5:return {{["x"] = 0, ["param2"] = 102, ["y"] = 0, ["param1"] = 158, ["z"] = 0, ["name"] = "bloc4builder:mesh_white_fuse1"}, {["x"] = 0, ["param2"] = 102, ["y"] = 0, ["param1"] = 142, ["z"] = 1, ["name"] = "bloc4builder:mesh_white_fuse1"}, {["x"] = 0, ["param2"] = 102, ["y"] = 0, ["param1"] = 142, ["z"] = 2, ["name"] = "bloc4builder:mesh_white_fuse1"}, {["x"] = 0, ["param2"] = 102, ["y"] = 0, ["param1"] = 158, ["z"] = 3, ["name"] = "bloc4builder:mesh_white_fuse1"}, {["x"] = 0, ["param2"] = 102, ["y"] = 0, ["param1"] = 174, ["z"] = 4, ["name"] = "bloc4builder:mesh_white_fuse1"}, {["x"] = 0, ["param2"] = 102, ["y"] = 0, ["param1"] = 157, ["z"] = 5, ["name"] = "bloc4builder:mesh_white_fuse1"}, {["x"] = 0, ["param2"] = 102, ["y"] = 0, ["param1"] = 142, ["z"] = 6, ["name"] = "bloc4builder:mesh_white_fuse1"}, {["x"] = 0, ["param2"] = 102, ["y"] = 0, ["param1"] = 125, ["z"] = 7, ["name"] = "bloc4builder:mesh_white_fuse1"}, {["x"] = 0, ["param2"] = 102, ["y"] = 0, ["param1"] = 142, ["z"] = 8, ["name"] = "bloc4builder:mesh_white_fuse1"}, {["x"] = 0, ["param2"] = 102, ["y"] = 0, ["param1"] = 158, ["z"] = 9, ["name"] = "bloc4builder:mesh_white_fuse1"}, {["x"] = 0, ["param2"] = 102, ["y"] = 0, ["param1"] = 141, ["z"] = 10, ["name"] = "bloc4builder:mesh_white_fuse1"}, {["x"] = 0, ["param2"] = 241, ["y"] = 1, ["param1"] = 142, ["z"] = 0, ["name"] = "bloc4builder:slope_white_half_raised"}, {["x"] = 0, ["param2"] = 241, ["y"] = 1, ["param1"] = 126, ["z"] = 1, ["name"] = "bloc4builder:slope_white_half_raised"}, {["x"] = 0, ["param2"] = 241, ["y"] = 1, ["param1"] = 126, ["z"] = 2, ["name"] = "bloc4builder:slope_white_half_raised"}, {["x"] = 0, ["param2"] = 241, ["y"] = 1, ["param1"] = 142, ["z"] = 3, ["name"] = "bloc4builder:slope_white_half_raised"}, {["x"] = 0, ["param2"] = 241, ["y"] = 1, ["param1"] = 158, ["z"] = 4, ["name"] = "bloc4builder:slope_white_half_raised"}, {["x"] = 0, ["param2"] = 241, ["y"] = 1, ["param1"] = 173, ["z"] = 5, ["name"] = "bloc4builder:slope_white_half_raised"}, {["x"] = 0, ["param2"] = 241, ["y"] = 1, ["param1"] = 158, ["z"] = 6, ["name"] = "bloc4builder:slope_white_half_raised"}, {["x"] = 0, ["param2"] = 241, ["y"] = 1, ["param1"] = 141, ["z"] = 7, ["name"] = "bloc4builder:slope_white_half_raised"}, {["x"] = 0, ["param2"] = 241, ["y"] = 1, ["param1"] = 158, ["z"] = 8, ["name"] = "bloc4builder:slope_white_half_raised"}, {["x"] = 0, ["param2"] = 241, ["y"] = 1, ["param1"] = 174, ["z"] = 9, ["name"] = "bloc4builder:slope_white_half_raised"}, {["x"] = 0, ["param2"] = 241, ["y"] = 1, ["param1"] = 157, ["z"] = 10, ["name"] = "bloc4builder:slope_white_half_raised"}, {["x"] = 0, ["param2"] = 161, ["y"] = 2, ["param1"] = 126, ["z"] = 0, ["name"] = "bloc4builder:slope_white_inner_cut"}, {["x"] = 0, ["param2"] = 2, ["y"] = 2, ["z"] = 1, ["name"] = "bloc4builder:white"}, {["x"] = 0, ["param2"] = 2, ["y"] = 2, ["z"] = 2, ["name"] = "bloc4builder:white"}, {["x"] = 0, ["param2"] = 2, ["y"] = 2, ["z"] = 3, ["name"] = "bloc4builder:white"}, {["x"] = 0, ["param2"] = 2, ["y"] = 2, ["z"] = 4, ["name"] = "bloc4builder:white"}, {["x"] = 0, ["param2"] = 2, ["y"] = 2, ["z"] = 5, ["name"] = "bloc4builder:white"}, {["x"] = 0, ["param2"] = 2, ["y"] = 2, ["z"] = 6, ["name"] = "bloc4builder:white"}, {["x"] = 0, ["param2"] = 2, ["y"] = 2, ["z"] = 7, ["name"] = "bloc4builder:white"}, {["x"] = 0, ["param2"] = 2, ["y"] = 2, ["z"] = 8, ["name"] = "bloc4builder:white"}, {["x"] = 0, ["param2"] = 2, ["y"] = 2, ["z"] = 9, ["name"] = "bloc4builder:white"}, {["x"] = 0, ["param2"] = 162, ["y"] = 2, ["param1"] = 141, ["z"] = 10, ["name"] = "bloc4builder:slope_white_inner_cut"}, {["x"] = 0, ["param2"] = 169, ["y"] = 3, ["param1"] = 110, ["z"] = 0, ["name"] = "bloc4builder:slope_white"}, {["x"] = 0, ["param2"] = 2, ["y"] = 3, ["z"] = 1, ["name"] = "bloc4builder:white"}, {["x"] = 0, ["param2"] = 2, ["y"] = 3, ["z"] = 2, ["name"] = "bloc4builder:white"}, {["x"] = 0, ["param2"] = 2, ["y"] = 3, ["z"] = 3, ["name"] = "bloc4builder:white"}, {["x"] = 0, ["param2"] = 2, ["y"] = 3, ["z"] = 4, ["name"] = "bloc4builder:white"}, {["x"] = 0, ["param2"] = 2, ["y"] = 3, ["z"] = 5, ["name"] = "bloc4builder:white"}, {["x"] = 0, ["param2"] = 2, ["y"] = 3, ["z"] = 6, ["name"] = "bloc4builder:white"}, {["x"] = 0, ["param2"] = 2, ["y"] = 3, ["z"] = 7, ["name"] = "bloc4builder:white"}, {["x"] = 0, ["param2"] = 2, ["y"] = 3, ["z"] = 8, ["name"] = "bloc4builder:white"}, {["x"] = 0, ["param2"] = 2, ["y"] = 3, ["z"] = 9, ["name"] = "bloc4builder:white"}, {["x"] = 0, ["param2"] = 178, ["y"] = 3, ["param1"] = 125, ["z"] = 10, ["name"] = "bloc4builder:slope_white"}, {["x"] = 0, ["param2"] = 169, ["y"] = 4, ["param1"] = 94, ["z"] = 0, ["name"] = "bloc4builder:slope_white"}, {["x"] = 0, ["param2"] = 2, ["y"] = 4, ["z"] = 1, ["name"] = "bloc4builder:white"}, {["x"] = 0, ["param2"] = 2, ["y"] = 4, ["z"] = 2, ["name"] = "bloc4builder:white"}, {["x"] = 0, ["param2"] = 2, ["y"] = 4, ["z"] = 3, ["name"] = "bloc4builder:white"}, {["x"] = 0, ["param2"] = 2, ["y"] = 4, ["z"] = 4, ["name"] = "bloc4builder:white"}, {["x"] = 0, ["param2"] = 3, ["y"] = 4, ["param1"] = 189, ["z"] = 5, ["name"] = "bloc4builder:hub"}, {["x"] = 0, ["param2"] = 2, ["y"] = 4, ["z"] = 6, ["name"] = "bloc4builder:white"}, {["x"] = 0, ["param2"] = 2, ["y"] = 4, ["z"] = 7, ["name"] = "bloc4builder:white"}, {["x"] = 0, ["param2"] = 2, ["y"] = 4, ["z"] = 8, ["name"] = "bloc4builder:white"}, {["x"] = 0, ["param2"] = 2, ["y"] = 4, ["z"] = 9, ["name"] = "bloc4builder:white"}, {["x"] = 0, ["param2"] = 178, ["y"] = 4, ["param1"] = 109, ["z"] = 10, ["name"] = "bloc4builder:slope_white"}, {["x"] = 0, ["param2"] = 169, ["y"] = 5, ["param1"] = 78, ["z"] = 0, ["name"] = "bloc4builder:slope_white"}, {["x"] = 0, ["param2"] = 2, ["y"] = 5, ["z"] = 1, ["name"] = "bloc4builder:white"}, {["x"] = 0, ["param2"] = 2, ["y"] = 5, ["z"] = 2, ["name"] = "bloc4builder:white"}, {["x"] = 0, ["param2"] = 2, ["y"] = 5, ["z"] = 3, ["name"] = "bloc4builder:white"}, {["x"] = 0, ["param2"] = 2, ["y"] = 5, ["z"] = 4, ["name"] = "bloc4builder:white"}, {["x"] = 0, ["meta"] = {["fields"] = {["owner"] = "singleplayer", ["channel"] = "neuf"}, ["inventory"] = {}}, ["param2"] = 3, ["y"] = 5, ["param1"] = 173, ["z"] = 5, ["name"] = "bloc4builder:sas2"}, {["x"] = 0, ["param2"] = 2, ["y"] = 5, ["z"] = 6, ["name"] = "bloc4builder:white"}, {["x"] = 0, ["param2"] = 2, ["y"] = 5, ["z"] = 7, ["name"] = "bloc4builder:white"}, {["x"] = 0, ["param2"] = 2, ["y"] = 5, ["z"] = 8, ["name"] = "bloc4builder:white"}, {["x"] = 0, ["param2"] = 2, ["y"] = 5, ["z"] = 9, ["name"] = "bloc4builder:white"}, {["x"] = 0, ["param2"] = 178, ["y"] = 5, ["param1"] = 125, ["z"] = 10, ["name"] = "bloc4builder:slope_white"}, {["x"] = 0, ["param2"] = 180, ["y"] = 6, ["param1"] = 62, ["z"] = 0, ["name"] = "bloc4builder:slope_white_inner_cut"}, {["x"] = 0, ["param2"] = 2, ["y"] = 6, ["z"] = 1, ["name"] = "bloc4builder:white"}, {["x"] = 0, ["param2"] = 2, ["y"] = 6, ["z"] = 2, ["name"] = "bloc4builder:white"}, {["x"] = 0, ["param2"] = 2, ["y"] = 6, ["z"] = 3, ["name"] = "bloc4builder:white"}, {["x"] = 0, ["param2"] = 2, ["y"] = 6, ["z"] = 4, ["name"] = "bloc4builder:white"}, {["x"] = 0, ["y"] = 6, ["param1"] = 157, ["z"] = 5, ["name"] = "bloc4builder:hidden"}, {["x"] = 0, ["param2"] = 2, ["y"] = 6, ["z"] = 6, ["name"] = "bloc4builder:white"}, {["x"] = 0, ["param2"] = 2, ["y"] = 6, ["z"] = 7, ["name"] = "bloc4builder:white"}, {["x"] = 0, ["param2"] = 2, ["y"] = 6, ["z"] = 8, ["name"] = "bloc4builder:white"}, {["x"] = 0, ["param2"] = 2, ["y"] = 6, ["z"] = 9, ["name"] = "bloc4builder:white"}, {["x"] = 0, ["param2"] = 183, ["y"] = 6, ["param1"] = 141, ["z"] = 10, ["name"] = "bloc4builder:slope_white_inner_cut"}, {["x"] = 0, ["param2"] = 243, ["y"] = 7, ["param1"] = 78, ["z"] = 0, ["name"] = "bloc4builder:slope_white_half_raised"}, {["x"] = 0, ["param2"] = 243, ["y"] = 7, ["param1"] = 94, ["z"] = 1, ["name"] = "bloc4builder:slope_white_half_raised"}, {["x"] = 0, ["param2"] = 243, ["y"] = 7, ["param1"] = 110, ["z"] = 2, ["name"] = "bloc4builder:slope_white_half_raised"}, {["x"] = 0, ["param2"] = 243, ["y"] = 7, ["param1"] = 126, ["z"] = 3, ["name"] = "bloc4builder:slope_white_half_raised"}, {["x"] = 0, ["param2"] = 243, ["y"] = 7, ["param1"] = 126, ["z"] = 4, ["name"] = "bloc4builder:slope_white_half_raised"}, {["x"] = 0, ["param2"] = 243, ["y"] = 7, ["param1"] = 141, ["z"] = 5, ["name"] = "bloc4builder:slope_white_half_raised"}, {["x"] = 0, ["param2"] = 243, ["y"] = 7, ["param1"] = 126, ["z"] = 6, ["name"] = "bloc4builder:slope_white_half_raised"}, {["x"] = 0, ["param2"] = 243, ["y"] = 7, ["param1"] = 109, ["z"] = 7, ["name"] = "bloc4builder:slope_white_half_raised"}, {["x"] = 0, ["param2"] = 243, ["y"] = 7, ["param1"] = 126, ["z"] = 8, ["name"] = "bloc4builder:slope_white_half_raised"}, {["x"] = 0, ["param2"] = 243, ["y"] = 7, ["param1"] = 142, ["z"] = 9, ["name"] = "bloc4builder:slope_white_half_raised"}, {["x"] = 0, ["param2"] = 243, ["y"] = 7, ["param1"] = 141, ["z"] = 10, ["name"] = "bloc4builder:slope_white_half_raised"}, {["x"] = 0, ["param2"] = 101, ["y"] = 8, ["param1"] = 78, ["z"] = 0, ["name"] = "bloc4builder:mesh_white_fuse1"}, {["x"] = 0, ["param2"] = 101, ["y"] = 8, ["param1"] = 94, ["z"] = 1, ["name"] = "bloc4builder:mesh_white_fuse1"}, {["x"] = 0, ["param2"] = 101, ["y"] = 8, ["param1"] = 110, ["z"] = 2, ["name"] = "bloc4builder:mesh_white_fuse1"}, {["x"] = 0, ["param2"] = 101, ["y"] = 8, ["param1"] = 110, ["z"] = 3, ["name"] = "bloc4builder:mesh_white_fuse1"}, {["x"] = 0, ["param2"] = 101, ["y"] = 8, ["param1"] = 110, ["z"] = 4, ["name"] = "bloc4builder:mesh_white_fuse1"}, {["x"] = 0, ["param2"] = 101, ["y"] = 8, ["param1"] = 126, ["z"] = 5, ["name"] = "bloc4builder:mesh_white_fuse1"}, {["x"] = 0, ["param2"] = 101, ["y"] = 8, ["param1"] = 110, ["z"] = 6, ["name"] = "bloc4builder:mesh_white_fuse1"}, {["x"] = 0, ["param2"] = 101, ["y"] = 8, ["param1"] = 110, ["z"] = 7, ["name"] = "bloc4builder:mesh_white_fuse1"}, {["x"] = 0, ["param2"] = 101, ["y"] = 8, ["param1"] = 110, ["z"] = 8, ["name"] = "bloc4builder:mesh_white_fuse1"}, {["x"] = 0, ["param2"] = 101, ["y"] = 8, ["param1"] = 126, ["z"] = 9, ["name"] = "bloc4builder:mesh_white_fuse1"}, {["x"] = 0, ["param2"] = 101, ["y"] = 8, ["param1"] = 126, ["z"] = 10, ["name"] = "bloc4builder:mesh_white_fuse1"}, {["x"] = 1, ["param2"] = 247, ["y"] = 0, ["param1"] = 142, ["z"] = 0, ["name"] = "bloc4builder:slope_white_half_raised"}, {["x"] = 1, ["param2"] = 247, ["y"] = 0, ["param1"] = 141, ["z"] = 1, ["name"] = "bloc4builder:slope_white_half_raised"}, {["x"] = 1, ["param2"] = 247, ["y"] = 0, ["param1"] = 157, ["z"] = 2, ["name"] = "bloc4builder:slope_white_half_raised"}, {["x"] = 1, ["param2"] = 247, ["y"] = 0, ["param1"] = 173, ["z"] = 3, ["name"] = "bloc4builder:slope_white_half_raised"}, {["x"] = 1, ["param2"] = 247, ["y"] = 0, ["param1"] = 189, ["z"] = 4, ["name"] = "bloc4builder:slope_white_half_raised"}, {["x"] = 1, ["param2"] = 247, ["y"] = 0, ["param1"] = 172, ["z"] = 5, ["name"] = "bloc4builder:slope_white_half_raised"}, {["x"] = 1, ["param2"] = 247, ["y"] = 0, ["param1"] = 157, ["z"] = 6, ["name"] = "bloc4builder:slope_white_half_raised"}, {["x"] = 1, ["param2"] = 247, ["y"] = 0, ["param1"] = 140, ["z"] = 7, ["name"] = "bloc4builder:slope_white_half_raised"}, {["x"] = 1, ["param2"] = 247, ["y"] = 0, ["param1"] = 157, ["z"] = 8, ["name"] = "bloc4builder:slope_white_half_raised"}, {["x"] = 1, ["param2"] = 247, ["y"] = 0, ["param1"] = 173, ["z"] = 9, ["name"] = "bloc4builder:slope_white_half_raised"}, {["x"] = 1, ["param2"] = 247, ["y"] = 0, ["param1"] = 158, ["z"] = 10, ["name"] = "bloc4builder:slope_white_half_raised"}, {["x"] = 1, ["param2"] = 227, ["y"] = 1, ["z"] = 0, ["name"] = "bloc4builder:white"}, {["x"] = 1, ["meta"] = {["fields"] = {["spacengine"] = "^B¨125¨0¨625¨2", ["channel"] = "neuf:singleplayer", ["infotext"] = "WatchDog", ["pos_cont"] = "(-4,-4,-6)"}, ["inventory"] = {}}, ["y"] = 1, ["z"] = 1, ["name"] = "spacengine:shield"}, {["x"] = 1, ["param2"] = 226, ["y"] = 1, ["z"] = 10, ["name"] = "bloc4builder:white"}, {["x"] = 1, ["param2"] = 227, ["y"] = 2, ["z"] = 0, ["name"] = "bloc4builder:white"}, {["x"] = 1, ["meta"] = {["fields"] = {["spacengine"] = "^B¨125¨0¨625¨2", ["channel"] = "neuf:singleplayer", ["infotext"] = "WatchDog", ["pos_cont"] = "(-4,-3,-6)"}, ["inventory"] = {}}, ["y"] = 2, ["z"] = 1, ["name"] = "spacengine:shield"}, {["x"] = 1, ["meta"] = {["fields"] = {["spacengine"] = "^i¨0¨0¨^iA0¨1¨^", ["channel"] = "neuf:singleplayer", ["infotext"] = "POWER ON/OFF", ["pos_cont"] = "(-4,-3,-4)"}, ["inventory"] = {}}, ["param2"] = 3, ["y"] = 2, ["param1"] = 172, ["z"] = 3, ["name"] = "spacengine:inter_0"}, {["x"] = 1, ["param2"] = 226, ["y"] = 2, ["z"] = 10, ["name"] = "bloc4builder:white"}, {["x"] = 1, ["param2"] = 227, ["y"] = 3, ["z"] = 0, ["name"] = "bloc4builder:white"}, {["x"] = 1, ["meta"] = {["fields"] = {["spacengine"] = "2¨150¨0¨500¨^spacengine:hydrogene_tank¨^battery¨15¨1¨10¨500", ["channel"] = "neuf:singleplayer", ["infotext"] = "Generateur Hydrogene", ["pos_cont"] = "(-4,-2,-6)"}, ["inventory"] = {}}, ["param2"] = 2, ["y"] = 3, ["param1"] = 154, ["z"] = 1, ["name"] = "spacengine:power"}, {["x"] = 1, ["param2"] = 12, ["y"] = 3, ["param1"] = 221, ["z"] = 5, ["name"] = "bloc4builder:light_on"}, {["x"] = 1, ["param2"] = 12, ["y"] = 3, ["param1"] = 221, ["z"] = 9, ["name"] = "bloc4builder:light_on"}, {["x"] = 1, ["param2"] = 226, ["y"] = 3, ["z"] = 10, ["name"] = "bloc4builder:white"}, {["x"] = 1, ["param2"] = 227, ["y"] = 4, ["z"] = 0, ["name"] = "bloc4builder:white"}, {["x"] = 1, ["param2"] = 3, ["y"] = 4, ["z"] = 1, ["name"] = "bloc4builder:white"}, {["x"] = 1, ["param2"] = 226, ["y"] = 4, ["z"] = 10, ["name"] = "bloc4builder:white"}, {["x"] = 1, ["param2"] = 227, ["y"] = 5, ["z"] = 0, ["name"] = "bloc4builder:white"}, {["x"] = 1, ["param2"] = 3, ["y"] = 5, ["param1"] = 123, ["z"] = 1, ["name"] = "bloc4builder:slab_grille_1"}, {["x"] = 1, ["y"] = 5, ["param1"] = 139, ["z"] = 2, ["name"] = "bloc4builder:slab_grille_1"}, {["x"] = 1, ["y"] = 5, ["param1"] = 155, ["z"] = 3, ["name"] = "bloc4builder:slab_grille_1"}, {["x"] = 1, ["y"] = 5, ["param1"] = 171, ["z"] = 4, ["name"] = "bloc4builder:slab_grille_1"}, {["x"] = 1, ["y"] = 5, ["param1"] = 188, ["z"] = 5, ["name"] = "bloc4builder:slab_grille_1"}, {["x"] = 1, ["y"] = 5, ["param1"] = 171, ["z"] = 6, ["name"] = "bloc4builder:slab_grille_1"}, {["x"] = 1, ["y"] = 5, ["param1"] = 155, ["z"] = 7, ["name"] = "bloc4builder:slab_grille_1"}, {["x"] = 1, ["y"] = 5, ["param1"] = 171, ["z"] = 8, ["name"] = "bloc4builder:slab_grille_1"}, {["x"] = 1, ["param2"] = 3, ["y"] = 5, ["param1"] = 187, ["z"] = 9, ["name"] = "bloc4builder:slab_grille_1"}, {["x"] = 1, ["param2"] = 226, ["y"] = 5, ["z"] = 10, ["name"] = "bloc4builder:white"}, {["x"] = 1, ["param2"] = 227, ["y"] = 6, ["z"] = 0, ["name"] = "bloc4builder:white"}, {["x"] = 1, ["meta"] = {["fields"] = {["owner"] = "singleplayer", ["channel"] = "neuf"}, ["inventory"] = {}}, ["param2"] = 3, ["y"] = 6, ["param1"] = 156, ["z"] = 6, ["name"] = "bloc4builder:keypad"}, {["x"] = 1, ["param2"] = 226, ["y"] = 6, ["z"] = 10, ["name"] = "bloc4builder:white"}, {["x"] = 1, ["param2"] = 227, ["y"] = 7, ["z"] = 0, ["name"] = "bloc4builder:white"}, {["x"] = 1, ["param2"] = 226, ["y"] = 7, ["z"] = 10, ["name"] = "bloc4builder:white"}, {["x"] = 1, ["param2"] = 225, ["y"] = 8, ["param1"] = 78, ["z"] = 0, ["name"] = "bloc4builder:slope_white_half_raised"}, {["x"] = 1, ["param2"] = 225, ["y"] = 8, ["param1"] = 94, ["z"] = 1, ["name"] = "bloc4builder:slope_white_half_raised"}, {["x"] = 1, ["param2"] = 225, ["y"] = 8, ["param1"] = 110, ["z"] = 2, ["name"] = "bloc4builder:slope_white_half_raised"}, {["x"] = 1, ["param2"] = 225, ["y"] = 8, ["param1"] = 126, ["z"] = 3, ["name"] = "bloc4builder:slope_white_half_raised"}, {["x"] = 1, ["param2"] = 225, ["y"] = 8, ["param1"] = 126, ["z"] = 4, ["name"] = "bloc4builder:slope_white_half_raised"}, {["x"] = 1, ["param2"] = 225, ["y"] = 8, ["param1"] = 141, ["z"] = 5, ["name"] = "bloc4builder:slope_white_half_raised"}, {["x"] = 1, ["param2"] = 225, ["y"] = 8, ["param1"] = 126, ["z"] = 6, ["name"] = "bloc4builder:slope_white_half_raised"}, {["x"] = 1, ["param2"] = 225, ["y"] = 8, ["param1"] = 110, ["z"] = 7, ["name"] = "bloc4builder:slope_white_half_raised"}, {["x"] = 1, ["param2"] = 225, ["y"] = 8, ["param1"] = 126, ["z"] = 8, ["name"] = "bloc4builder:slope_white_half_raised"}, {["x"] = 1, ["param2"] = 225, ["y"] = 8, ["param1"] = 142, ["z"] = 9, ["name"] = "bloc4builder:slope_white_half_raised"}, {["x"] = 1, ["param2"] = 225, ["y"] = 8, ["param1"] = 126, ["z"] = 10, ["name"] = "bloc4builder:slope_white_half_raised"}, {["x"] = 2, ["param2"] = 226, ["y"] = 0, ["z"] = 0, ["name"] = "bloc4builder:white"}, {["x"] = 2, ["param2"] = 226, ["y"] = 0, ["z"] = 1, ["name"] = "bloc4builder:white"}, {["x"] = 2, ["param2"] = 226, ["y"] = 0, ["z"] = 2, ["name"] = "bloc4builder:white"}, {["x"] = 2, ["param2"] = 226, ["y"] = 0, ["z"] = 3, ["name"] = "bloc4builder:white"}, {["x"] = 2, ["param2"] = 226, ["y"] = 0, ["z"] = 4, ["name"] = "bloc4builder:white"}, {["x"] = 2, ["param2"] = 226, ["y"] = 0, ["z"] = 5, ["name"] = "bloc4builder:white"}, {["x"] = 2, ["param2"] = 226, ["y"] = 0, ["z"] = 6, ["name"] = "bloc4builder:white"}, {["x"] = 2, ["param2"] = 226, ["y"] = 0, ["z"] = 7, ["name"] = "bloc4builder:white"}, {["x"] = 2, ["param2"] = 226, ["y"] = 0, ["z"] = 8, ["name"] = "bloc4builder:white"}, {["x"] = 2, ["param2"] = 226, ["y"] = 0, ["z"] = 9, ["name"] = "bloc4builder:white"}, {["x"] = 2, ["param2"] = 226, ["y"] = 0, ["z"] = 10, ["name"] = "bloc4builder:white"}, {["x"] = 2, ["y"] = 1, ["z"] = 0, ["name"] = "bloc4builder:yellow"}, {["x"] = 2, ["param2"] = 225, ["y"] = 1, ["z"] = 10, ["name"] = "bloc4builder:white"}, {["x"] = 2, ["param2"] = 3, ["y"] = 2, ["z"] = 0, ["name"] = "bloc4builder:white"}, {["x"] = 2, ["meta"] = {["fields"] = {["owner"] = "singleplayer", ["channel"] = "neuf"}, ["inventory"] = {}}, ["param2"] = 2, ["y"] = 2, ["param1"] = 122, ["z"] = 1, ["name"] = "bloc4builder:keypad"}, {["x"] = 2, ["param2"] = 225, ["y"] = 2, ["z"] = 10, ["name"] = "bloc4builder:white"}, {["x"] = 2, ["y"] = 3, ["z"] = 0, ["name"] = "bloc4builder:yellow"}, {["x"] = 2, ["param2"] = 225, ["y"] = 3, ["z"] = 10, ["name"] = "bloc4builder:white"}, {["x"] = 2, ["param2"] = 3, ["y"] = 4, ["z"] = 0, ["name"] = "bloc4builder:white"}, {["x"] = 2, ["param2"] = 225, ["y"] = 4, ["z"] = 10, ["name"] = "bloc4builder:white"}, {["x"] = 2, ["param2"] = 227, ["y"] = 5, ["z"] = 0, ["name"] = "bloc4builder:white"}, {["x"] = 2, ["param2"] = 3, ["y"] = 5, ["param1"] = 122, ["z"] = 1, ["name"] = "bloc4builder:slab_grille_1"}, {["x"] = 2, ["param2"] = 1, ["y"] = 5, ["param1"] = 138, ["z"] = 2, ["name"] = "bloc4builder:slab_grille_two_sides"}, {["x"] = 2, ["param2"] = 1, ["y"] = 5, ["param1"] = 154, ["z"] = 3, ["name"] = "bloc4builder:slab_grille_two_sides"}, {["x"] = 2, ["param2"] = 1, ["y"] = 5, ["param1"] = 154, ["z"] = 4, ["name"] = "bloc4builder:slab_grille_two_sides"}, {["x"] = 2, ["param2"] = 1, ["y"] = 5, ["param1"] = 171, ["z"] = 5, ["name"] = "bloc4builder:slab_grille_two_sides"}, {["x"] = 2, ["param2"] = 1, ["y"] = 5, ["param1"] = 154, ["z"] = 6, ["name"] = "bloc4builder:slab_grille_two_sides"}, {["x"] = 2, ["param2"] = 1, ["y"] = 5, ["param1"] = 138, ["z"] = 7, ["name"] = "bloc4builder:slab_grille_two_sides"}, {["x"] = 2, ["param2"] = 1, ["y"] = 5, ["param1"] = 154, ["z"] = 8, ["name"] = "bloc4builder:slab_grille_two_sides"}, {["x"] = 2, ["param2"] = 3, ["y"] = 5, ["param1"] = 170, ["z"] = 9, ["name"] = "bloc4builder:slab_grille_1"}, {["x"] = 2, ["param2"] = 225, ["y"] = 5, ["z"] = 10, ["name"] = "bloc4builder:white"}, {["x"] = 2, ["meta"] = {["fields"] = {["spacengine"] = "^A¨100¨0¨750¨20¨5¨2", ["channel"] = "neuf:singleplayer", ["infotext"] = "LASER", ["pos_cont"] = "(-3,0,6)"}, ["inventory"] = {}}, ["param2"] = 18, ["y"] = 5, ["param1"] = 94, ["z"] = 13, ["name"] = "spacengine:weapons"}, {["x"] = 2, ["meta"] = {["fields"] = {["spacengine"] = "^A¨75¨0¨10¨50¨50¨500", ["channel"] = "neuf:singleplayer", ["infotext"] = "Rocket", ["pos_cont"] = "(-3,1,-7)"}, ["inventory"] = {}}, ["y"] = 6, ["z"] = 0, ["name"] = "spacengine:engine"}, {["x"] = 2, ["param2"] = 225, ["y"] = 6, ["z"] = 10, ["name"] = "bloc4builder:white"}, {["x"] = 2, ["meta"] = {["fields"] = {["spacengine"] = "^A¨75¨0¨10¨50¨50¨500", ["channel"] = "neuf:singleplayer", ["infotext"] = "Rocket", ["pos_cont"] = "(-3,2,-7)"}, ["inventory"] = {}}, ["y"] = 7, ["z"] = 0, ["name"] = "spacengine:engine"}, {["x"] = 2, ["param2"] = 225, ["y"] = 7, ["z"] = 10, ["name"] = "bloc4builder:white"}, {["x"] = 2, ["param2"] = 225, ["y"] = 8, ["z"] = 0, ["name"] = "bloc4builder:white"}, {["x"] = 2, ["param2"] = 225, ["y"] = 8, ["z"] = 1, ["name"] = "bloc4builder:white"}, {["x"] = 2, ["param2"] = 161, ["y"] = 8, ["z"] = 2, ["name"] = "bloc4builder:white"}, {["x"] = 2, ["param2"] = 161, ["y"] = 8, ["z"] = 3, ["name"] = "bloc4builder:white"}, {["x"] = 2, ["param2"] = 161, ["y"] = 8, ["z"] = 4, ["name"] = "bloc4builder:white"}, {["x"] = 2, ["param2"] = 161, ["y"] = 8, ["z"] = 5, ["name"] = "bloc4builder:white"}, {["x"] = 2, ["param2"] = 161, ["y"] = 8, ["z"] = 6, ["name"] = "bloc4builder:white"}, {["x"] = 2, ["param2"] = 161, ["y"] = 8, ["z"] = 7, ["name"] = "bloc4builder:white"}, {["x"] = 2, ["param2"] = 225, ["y"] = 8, ["z"] = 8, ["name"] = "bloc4builder:white"}, {["x"] = 2, ["param2"] = 225, ["y"] = 8, ["z"] = 9, ["name"] = "bloc4builder:white"}, {["x"] = 2, ["param2"] = 225, ["y"] = 8, ["z"] = 10, ["name"] = "bloc4builder:white"}, {["x"] = 2, ["meta"] = {["fields"] = {["spacengine"] = "^A¨100¨0¨750¨20¨5¨2", ["channel"] = "neuf:singleplayer", ["infotext"] = "LASER", ["pos_cont"] = "(-3,4,-6)"}, ["inventory"] = {}}, ["param2"] = 1, ["y"] = 9, ["param1"] = 94, ["z"] = 1, ["name"] = "spacengine:weapons"}, {["x"] = 2, ["meta"] = {["fields"] = {["spacengine"] = "^A¨100¨0¨750¨20¨5¨2", ["channel"] = "neuf:singleplayer", ["infotext"] = "LASER", ["pos_cont"] = "(-3,4,2)"}, ["inventory"] = {}}, ["param2"] = 1, ["y"] = 9, ["param1"] = 110, ["z"] = 9, ["name"] = "spacengine:weapons"}, {["x"] = 3, ["param2"] = 225, ["y"] = 0, ["z"] = 0, ["name"] = "bloc4builder:white"}, {["x"] = 3, ["param2"] = 225, ["y"] = 0, ["z"] = 1, ["name"] = "bloc4builder:white"}, {["x"] = 3, ["param2"] = 225, ["y"] = 0, ["z"] = 2, ["name"] = "bloc4builder:white"}, {["x"] = 3, ["param2"] = 225, ["y"] = 0, ["z"] = 3, ["name"] = "bloc4builder:white"}, {["x"] = 3, ["param2"] = 225, ["y"] = 0, ["z"] = 4, ["name"] = "bloc4builder:white"}, {["x"] = 3, ["param2"] = 225, ["y"] = 0, ["z"] = 5, ["name"] = "bloc4builder:white"}, {["x"] = 3, ["param2"] = 225, ["y"] = 0, ["z"] = 6, ["name"] = "bloc4builder:white"}, {["x"] = 3, ["param2"] = 225, ["y"] = 0, ["z"] = 7, ["name"] = "bloc4builder:white"}, {["x"] = 3, ["param2"] = 1, ["y"] = 0, ["z"] = 8, ["name"] = "bloc4builder:white"}, {["x"] = 3, ["param2"] = 1, ["y"] = 0, ["z"] = 9, ["name"] = "bloc4builder:white"}, {["x"] = 3, ["param2"] = 225, ["y"] = 0, ["z"] = 10, ["name"] = "bloc4builder:white"}, {["x"] = 3, ["y"] = 1, ["z"] = 0, ["name"] = "bloc4builder:garage"}, {["x"] = 3, ["y"] = 1, ["param1"] = 155, ["z"] = 9, ["name"] = "bloc4builder:ladder"}, {["x"] = 3, ["param2"] = 224, ["y"] = 1, ["z"] = 10, ["name"] = "bloc4builder:white"}, {["x"] = 3, ["y"] = 2, ["z"] = 0, ["name"] = "bloc4builder:garage"}, {["x"] = 3, ["y"] = 2, ["param1"] = 170, ["z"] = 9, ["name"] = "bloc4builder:ladder"}, {["x"] = 3, ["param2"] = 224, ["y"] = 2, ["z"] = 10, ["name"] = "bloc4builder:white"}, {["x"] = 3, ["y"] = 3, ["z"] = 0, ["name"] = "bloc4builder:garage"}, {["x"] = 3, ["y"] = 3, ["param1"] = 187, ["z"] = 9, ["name"] = "bloc4builder:ladder"}, {["x"] = 3, ["param2"] = 224, ["y"] = 3, ["z"] = 10, ["name"] = "bloc4builder:white"}, {["x"] = 3, ["param2"] = 151, ["y"] = 3, ["param1"] = 78, ["z"] = 11, ["name"] = "bloc4builder:slope_white"}, {["x"] = 3, ["param2"] = 151, ["y"] = 3, ["param1"] = 94, ["z"] = 12, ["name"] = "bloc4builder:slope_white"}, {["x"] = 3, ["param2"] = 151, ["y"] = 3, ["param1"] = 109, ["z"] = 13, ["name"] = "bloc4builder:slope_white"}, {["x"] = 3, ["param2"] = 151, ["y"] = 3, ["param1"] = 94, ["z"] = 14, ["name"] = "bloc4builder:slope_white"}, {["x"] = 3, ["y"] = 4, ["z"] = 0, ["name"] = "bloc4builder:yellow"}, {["x"] = 3, ["y"] = 4, ["param1"] = 170, ["z"] = 9, ["name"] = "bloc4builder:ladder"}, {["x"] = 3, ["y"] = 4, ["z"] = 10, ["name"] = "bloc4builder:white"}, {["x"] = 3, ["param2"] = 129, ["y"] = 4, ["z"] = 11, ["name"] = "bloc4builder:white"}, {["x"] = 3, ["param2"] = 129, ["y"] = 4, ["z"] = 12, ["name"] = "bloc4builder:white"}, {["x"] = 3, ["param2"] = 129, ["y"] = 4, ["z"] = 13, ["name"] = "bloc4builder:white"}, {["x"] = 3, ["param2"] = 129, ["y"] = 4, ["z"] = 14, ["name"] = "bloc4builder:white"}, {["x"] = 3, ["param2"] = 227, ["y"] = 5, ["z"] = 0, ["name"] = "bloc4builder:white"}, {["x"] = 3, ["param2"] = 3, ["y"] = 5, ["param1"] = 137, ["z"] = 1, ["name"] = "bloc4builder:slab_grille_1"}, {["x"] = 3, ["param2"] = 7, ["y"] = 5, ["param1"] = 153, ["z"] = 2, ["name"] = "bloc4builder:slab_grille_1"}, {["x"] = 3, ["param2"] = 9, ["y"] = 5, ["param1"] = 137, ["z"] = 8, ["name"] = "bloc4builder:slab_grille_1"}, {["x"] = 3, ["meta"] = {["fields"] = {["spacengine"] = "^C¨150¨0¨50000", ["channel"] = "neuf:singleplayer", ["infotext"] = "BATTERY Mega5", ["pos_cont"] = "(-2,0,3)"}, ["inventory"] = {}}, ["param2"] = 3, ["y"] = 5, ["z"] = 10, ["name"] = "spacengine:battery"}, {["x"] = 3, ["param2"] = 129, ["y"] = 5, ["z"] = 11, ["name"] = "bloc4builder:white"}, {["x"] = 3, ["param2"] = 129, ["y"] = 5, ["z"] = 12, ["name"] = "bloc4builder:white"}, {["x"] = 3, ["param2"] = 129, ["y"] = 5, ["z"] = 13, ["name"] = "bloc4builder:white"}, {["x"] = 3, ["param2"] = 129, ["y"] = 5, ["z"] = 14, ["name"] = "bloc4builder:white"}, {["x"] = 3, ["param2"] = 3, ["y"] = 6, ["z"] = 0, ["name"] = "bloc4builder:white"}, {["x"] = 3, ["param2"] = 20, ["y"] = 6, ["param1"] = 187, ["z"] = 5, ["name"] = "bloc4builder:slab_white_1"}, {["x"] = 3, ["param2"] = 22, ["y"] = 6, ["param1"] = 170, ["z"] = 6, ["name"] = "bloc4builder:slab_white_1"}, {["x"] = 3, ["param2"] = 224, ["y"] = 6, ["z"] = 10, ["name"] = "bloc4builder:white"}, {["x"] = 3, ["param2"] = 129, ["y"] = 6, ["param1"] = 94, ["z"] = 11, ["name"] = "bloc4builder:slope_white"}, {["x"] = 3, ["param2"] = 129, ["y"] = 6, ["param1"] = 78, ["z"] = 12, ["name"] = "bloc4builder:slope_white"}, {["x"] = 3, ["param2"] = 129, ["y"] = 6, ["param1"] = 78, ["z"] = 13, ["name"] = "bloc4builder:slope_white"}, {["x"] = 3, ["param2"] = 129, ["y"] = 6, ["param1"] = 62, ["z"] = 14, ["name"] = "bloc4builder:slope_white"}, {["x"] = 3, ["y"] = 7, ["z"] = 0, ["name"] = "bloc4builder:white"}, {["x"] = 3, ["param2"] = 9, ["y"] = 7, ["param1"] = 171, ["z"] = 4, ["name"] = "bloc4builder:slab_white_1"}, {["x"] = 3, ["meta"] = {["fields"] = {["spacengine"] = "^A¨100¨0¨500", ["channel"] = "neuf:singleplayer", ["formspec"] = "size [9,10]bgcolor[#080808BB;true]list[current_name;storage;3,1.5;2,2;]list[current_player;main;0.5,6.5;8,4;]", ["infotext"] = "Container 500Kg", ["pos_cont"] = "(-2,2,-2)"}, ["inventory"] = {["main"] = {"", "", "", "", "", "", "", "", "", "", "", "", "", "", "", "", "", "", "", "", "", "", "", "", "", "", "", "", "", "", "", ""}, ["storage"] = {"", "", "", ""}}}, ["param2"] = 1, ["y"] = 7, ["z"] = 5, ["name"] = "spacengine:container3"}, {["x"] = 3, ["meta"] = {["fields"] = {["spacengine"] = "^A¨100¨0¨500", ["channel"] = "neuf:singleplayer", ["infotext"] = "Container 500Kg", ["pos_cont"] = "(-2,2,-1)"}, ["inventory"] = {}}, ["param2"] = 1, ["y"] = 7, ["z"] = 6, ["name"] = "spacengine:container"}, {["x"] = 3, ["param2"] = 7, ["y"] = 7, ["param1"] = 139, ["z"] = 7, ["name"] = "bloc4builder:slab_white_1"}, {["x"] = 3, ["param2"] = 225, ["y"] = 7, ["z"] = 10, ["name"] = "bloc4builder:white"}, {["x"] = 3, ["param2"] = 225, ["y"] = 8, ["z"] = 0, ["name"] = "bloc4builder:white"}, {["x"] = 3, ["param2"] = 226, ["y"] = 8, ["z"] = 1, ["name"] = "bloc4builder:rainbow"}, {["x"] = 3, ["param2"] = 226, ["y"] = 8, ["z"] = 2, ["name"] = "bloc4builder:rainbow"}, {["x"] = 3, ["param2"] = 227, ["y"] = 8, ["z"] = 3, ["name"] = "bloc4builder:rainbow"}, {["x"] = 3, ["param2"] = 227, ["y"] = 8, ["z"] = 4, ["name"] = "bloc4builder:rainbow"}, {["x"] = 3, ["param2"] = 227, ["y"] = 8, ["z"] = 5, ["name"] = "bloc4builder:rainbow"}, {["x"] = 3, ["param2"] = 224, ["y"] = 8, ["z"] = 6, ["name"] = "bloc4builder:rainbow"}, {["x"] = 3, ["param2"] = 224, ["y"] = 8, ["z"] = 7, ["name"] = "bloc4builder:rainbow"}, {["x"] = 3, ["param2"] = 161, ["y"] = 8, ["z"] = 8, ["name"] = "bloc4builder:white"}, {["x"] = 3, ["param2"] = 225, ["y"] = 8, ["z"] = 9, ["name"] = "bloc4builder:white"}, {["x"] = 3, ["param2"] = 225, ["y"] = 8, ["z"] = 10, ["name"] = "bloc4builder:white"}, {["x"] = 3, ["param2"] = 225, ["y"] = 9, ["param1"] = 94, ["z"] = 0, ["name"] = "bloc4builder:slope_white"}, {["x"] = 3, ["param2"] = 225, ["y"] = 9, ["param1"] = 110, ["z"] = 1, ["name"] = "bloc4builder:slope_white"}, {["x"] = 3, ["param2"] = 1, ["y"] = 9, ["param1"] = 95, ["z"] = 2, ["name"] = "moreblocks:slope_obsidian_glass"}, {["x"] = 3, ["param2"] = 1, ["y"] = 9, ["param1"] = 78, ["z"] = 3, ["name"] = "moreblocks:slope_obsidian_glass"}, {["x"] = 3, ["param2"] = 1, ["y"] = 9, ["param1"] = 79, ["z"] = 4, ["name"] = "moreblocks:slope_obsidian_glass"}, {["x"] = 3, ["param2"] = 1, ["y"] = 9, ["param1"] = 95, ["z"] = 5, ["name"] = "moreblocks:slope_obsidian_glass"}, {["x"] = 3, ["param2"] = 1, ["y"] = 9, ["param1"] = 79, ["z"] = 6, ["name"] = "moreblocks:slope_obsidian_glass"}, {["x"] = 3, ["param2"] = 2, ["y"] = 9, ["param1"] = 79, ["z"] = 7, ["name"] = "moreblocks:slope_obsidian_glass_outer"}, {["x"] = 4, ["param2"] = 225, ["y"] = 0, ["z"] = 0, ["name"] = "bloc4builder:white"}, {["x"] = 4, ["param2"] = 225, ["y"] = 0, ["z"] = 1, ["name"] = "bloc4builder:white"}, {["x"] = 4, ["param2"] = 225, ["y"] = 0, ["z"] = 2, ["name"] = "bloc4builder:white"}, {["x"] = 4, ["param2"] = 225, ["y"] = 0, ["z"] = 3, ["name"] = "bloc4builder:white"}, {["x"] = 4, ["param2"] = 225, ["y"] = 0, ["z"] = 4, ["name"] = "bloc4builder:white"}, {["x"] = 4, ["param2"] = 225, ["y"] = 0, ["z"] = 5, ["name"] = "bloc4builder:white"}, {["x"] = 4, ["param2"] = 225, ["y"] = 0, ["z"] = 6, ["name"] = "bloc4builder:white"}, {["x"] = 4, ["param2"] = 225, ["y"] = 0, ["z"] = 7, ["name"] = "bloc4builder:white"}, {["x"] = 4, ["param2"] = 225, ["y"] = 0, ["z"] = 8, ["name"] = "bloc4builder:white"}, {["x"] = 4, ["param2"] = 1, ["y"] = 0, ["z"] = 9, ["name"] = "bloc4builder:white"}, {["x"] = 4, ["param2"] = 225, ["y"] = 0, ["z"] = 10, ["name"] = "bloc4builder:white"}, {["x"] = 4, ["y"] = 1, ["z"] = 0, ["name"] = "bloc4builder:garage"}, {["x"] = 4, ["param2"] = 224, ["y"] = 1, ["z"] = 10, ["name"] = "bloc4builder:white"}, {["x"] = 4, ["y"] = 2, ["z"] = 0, ["name"] = "bloc4builder:garage"}, {["x"] = 4, ["param2"] = 224, ["y"] = 2, ["z"] = 10, ["name"] = "bloc4builder:white"}, {["x"] = 4, ["y"] = 3, ["z"] = 0, ["name"] = "bloc4builder:garage"}, {["x"] = 4, ["param2"] = 131, ["y"] = 3, ["z"] = 10, ["name"] = "bloc4builder:white"}, {["x"] = 4, ["param2"] = 128, ["y"] = 3, ["z"] = 11, ["name"] = "bloc4builder:white"}, {["x"] = 4, ["param2"] = 128, ["y"] = 3, ["z"] = 12, ["name"] = "bloc4builder:white"}, {["x"] = 4, ["param2"] = 128, ["y"] = 3, ["z"] = 13, ["name"] = "bloc4builder:white"}, {["x"] = 4, ["param2"] = 131, ["y"] = 3, ["z"] = 14, ["name"] = "bloc4builder:white"}, {["x"] = 4, ["param2"] = 2, ["y"] = 4, ["z"] = 0, ["name"] = "bloc4builder:white"}, {["x"] = 4, ["param2"] = 9, ["y"] = 4, ["param1"] = 154, ["z"] = 9, ["name"] = "bloc4builder:slab_grille_1"}, {["x"] = 4, ["param2"] = 18, ["y"] = 4, ["param1"] = 139, ["z"] = 10, ["name"] = "bloc4builder:slab_grille_1"}, {["x"] = 4, ["meta"] = {["fields"] = {["spacengine"] = "^b¨0¨0¨^bC0¨1¨^", ["channel"] = "neuf:singleplayer", ["infotext"] = "CONTROLER on/off", ["pos_cont"] = "(-1,-1,5)"}, ["inventory"] = {}}, ["param2"] = 3, ["y"] = 4, ["param1"] = 108, ["z"] = 12, ["name"] = "spacengine:switch_bp"}, {["x"] = 4, ["meta"] = {["fields"] = {["spacengine"] = "^S¨64¨0¨^aB2bM0¨1", ["channel"] = "neuf:singleplayer", ["pos_cont"] = "(-1,-1,6)", ["text"] = "(2(b(c1(b2_______)(cPUISSAN | (p(3?SHIELD@)(h (3?OFF@) | (n(1A)(h000% | (d(1`)00522 / (c02500 | (2(eRQ)002"}, ["inventory"] = {}}, ["param2"] = 3, ["y"] = 4, ["param1"] = 108, ["z"] = 13, ["name"] = "monitor:screen_down"}, {["x"] = 4, ["param2"] = 9, ["y"] = 4, ["param1"] = 93, ["z"] = 14, ["name"] = "moreblocks:slab_obsidian_glass_1"}, {["x"] = 4, ["param2"] = 225, ["y"] = 5, ["z"] = 0, ["name"] = "bloc4builder:white"}, {["x"] = 4, ["param2"] = 3, ["y"] = 5, ["param1"] = 154, ["z"] = 1, ["name"] = "bloc4builder:slab_grille_1"}, {["x"] = 4, ["param2"] = 7, ["y"] = 5, ["param1"] = 170, ["z"] = 2, ["name"] = "bloc4builder:slab_grille_1"}, {["x"] = 4, ["param2"] = 18, ["y"] = 5, ["param1"] = 153, ["z"] = 7, ["name"] = "bloc4builder:slab_grille_1"}, {["x"] = 4, ["param2"] = 18, ["y"] = 5, ["param1"] = 138, ["z"] = 8, ["name"] = "bloc4builder:slab_grille_1"}, {["x"] = 4, ["param2"] = 2, ["y"] = 5, ["param1"] = 139, ["z"] = 9, ["name"] = "bloc4builder:slab_grille_two_sides"}, {["x"] = 4, ["param2"] = 5, ["y"] = 5, ["param1"] = 124, ["z"] = 10, ["name"] = "bloc4builder:slab_grille_two_sides"}, {["x"] = 4, ["meta"] = {["fields"] = {["spacengine"] = "^i¨0¨0¨^iA0¨1¨^", ["channel"] = "neuf:singleplayer", ["infotext"] = "POWER ON/OFF", ["pos_cont"] = "(-1,0,4)"}, ["inventory"] = {}}, ["param2"] = 3, ["y"] = 5, ["param1"] = 109, ["z"] = 11, ["name"] = "spacengine:inter_0"}, {["x"] = 4, ["meta"] = {["fields"] = {["spacengine"] = "^a¨0¨0¨^aA0¨1¨^", ["channel"] = "neuf:singleplayer", ["infotext"] = "ENGINE PUISSANCE", ["pos_cont"] = "(-1,0,5)"}, ["inventory"] = {}}, ["param2"] = 3, ["y"] = 5, ["param1"] = 93, ["z"] = 12, ["name"] = "spacengine:analog00"}, {["x"] = 4, ["meta"] = {["fields"] = {["spacengine"] = "^P¨64¨0¨^bD0bP0bM0¨1", ["channel"] = "neuf:singleplayer", ["pos_cont"] = "(-1,0,6)", ["text"] = "(2(b(c1(b23______)(c ON/OFF | (p(3?POWER@)(f(3?ON=@) | (gGenerateur Hydro | (2(df(to(df)(f0000993 | (1(qt)00083(o/(e00100KU"}, ["inventory"] = {}}, ["param2"] = 3, ["y"] = 5, ["param1"] = 109, ["z"] = 13, ["name"] = "monitor:screen_wall"}, {["x"] = 4, ["param2"] = 9, ["y"] = 5, ["param1"] = 93, ["z"] = 14, ["name"] = "moreblocks:slab_obsidian_glass_1"}, {["x"] = 4, ["meta"] = {["fields"] = {["spacengine"] = "^A¨75¨0¨10¨50¨50¨500", ["channel"] = "neuf:singleplayer", ["infotext"] = "Rocket", ["pos_cont"] = "(-1,1,-7)"}, ["inventory"] = {}}, ["y"] = 6, ["z"] = 0, ["name"] = "spacengine:engine"}, {["x"] = 4, ["param2"] = 18, ["y"] = 6, ["param1"] = 170, ["z"] = 7, ["name"] = "bloc4builder:slab_grille_1"}, {["x"] = 4, ["param2"] = 149, ["y"] = 6, ["param1"] = 110, ["z"] = 11, ["name"] = "bloc4builder:slope_white"}, {["x"] = 4, ["param2"] = 149, ["y"] = 6, ["param1"] = 94, ["z"] = 12, ["name"] = "bloc4builder:slope_white"}, {["x"] = 4, ["param2"] = 149, ["y"] = 6, ["param1"] = 94, ["z"] = 13, ["name"] = "bloc4builder:slope_white"}, {["x"] = 4, ["param2"] = 129, ["y"] = 6, ["z"] = 14, ["name"] = "bloc4builder:white"}, {["x"] = 4, ["param2"] = 1, ["y"] = 7, ["z"] = 0, ["name"] = "bloc4builder:white"}, {["x"] = 4, ["param2"] = 2, ["y"] = 7, ["z"] = 1, ["name"] = "bloc4builder:white"}, {["x"] = 4, ["param2"] = 2, ["y"] = 7, ["z"] = 2, ["name"] = "bloc4builder:white"}, {["x"] = 4, ["param2"] = 3, ["y"] = 7, ["z"] = 3, ["name"] = "bloc4builder:white"}, {["x"] = 4, ["param2"] = 2, ["y"] = 7, ["z"] = 4, ["name"] = "bloc4builder:white"}, {["x"] = 4, ["param2"] = 3, ["y"] = 7, ["z"] = 5, ["name"] = "bloc4builder:white"}, {["x"] = 4, ["param2"] = 2, ["y"] = 7, ["z"] = 6, ["name"] = "bloc4builder:white"}, {["x"] = 4, ["param2"] = 18, ["y"] = 7, ["param1"] = 154, ["z"] = 7, ["name"] = "bloc4builder:slab_grille_1"}, {["x"] = 4, ["param2"] = 225, ["y"] = 7, ["z"] = 10, ["name"] = "bloc4builder:white"}, {["x"] = 4, ["param2"] = 225, ["y"] = 8, ["z"] = 0, ["name"] = "bloc4builder:white"}, {["x"] = 4, ["y"] = 8, ["param1"] = 126, ["z"] = 2, ["name"] = "monitor:console_base"}, {["x"] = 4, ["meta"] = {["fields"] = {["spacengine"] = "^t¨0¨0¨^bC0bC0bC0bC0¨1¨^", ["channel"] = "neuf:singleplayer", ["infotext"] = "CONTROLER on/off -- 1 --\
CONTROLER on/off -- 2 --\
CONTROLER on/off -- 3 --\
CONTROLER on/off -- 4 --", ["pos_cont"] = "(-1,3,-4)"}, ["inventory"] = {}}, ["param2"] = 3, ["y"] = 8, ["param1"] = 111, ["z"] = 3, ["name"] = "spacengine:switch_4bp3"}, {["x"] = 4, ["meta"] = {["fields"] = {["spacengine"] = "^t¨0¨0¨^bC0bC0bC0bC0¨1¨^", ["channel"] = "neuf:singleplayer", ["infotext"] = "CONTROLER on/off -- 1 --\
CONTROLER on/off -- 2 --\
CONTROLER on/off -- 3 --\
CONTROLER on/off -- 4 --", ["pos_cont"] = "(-1,3,-3)"}, ["inventory"] = {}}, ["param2"] = 3, ["y"] = 8, ["param1"] = 95, ["z"] = 4, ["name"] = "spacengine:switch_4bp1"}, {["x"] = 4, ["meta"] = {["fields"] = {["spacengine"] = "^C¨64¨0¨^bC0bJ0bM0aa0bi0¨1", ["channel"] = "neuf:singleplayer", ["pos_cont"] = "(-1,3,-2)", ["text"] = "(2(b(c1(b2345____)(c(1;)ON(1:)OFF | (P(3?CONTROLER@)(1(fs)(q084% | (2(df(to(df(h(1_'a_)(f(1%g_)(h(1`a_)(f (2:(1g) | (r(1x)(f000%(c(1_v)X11Y11Z15 | (1(kV)(h(2`)OVER(l(14$)0003657"}, ["inventory"] = {}}, ["param2"] = 3, ["y"] = 8, ["param1"] = 111, ["z"] = 5, ["name"] = "monitor:screen_down"}, {["x"] = 4, ["param2"] = 236, ["y"] = 8, ["param1"] = 94, ["z"] = 6, ["name"] = "bloc4builder:slope_rainbow"}, {["x"] = 4, ["param2"] = 225, ["y"] = 8, ["z"] = 7, ["name"] = "bloc4builder:rainbow"}, {["x"] = 4, ["param2"] = 161, ["y"] = 8, ["z"] = 8, ["name"] = "bloc4builder:white"}, {["x"] = 4, ["param2"] = 161, ["y"] = 8, ["z"] = 9, ["name"] = "bloc4builder:white"}, {["x"] = 4, ["param2"] = 225, ["y"] = 8, ["z"] = 10, ["name"] = "bloc4builder:white"}, {["x"] = 4, ["param2"] = 227, ["y"] = 9, ["z"] = 0, ["name"] = "bloc4builder:white"}, {["x"] = 4, ["meta"] = {["fields"] = {["spacengine"] = "^C¨64¨0¨^bC0bJ0bM0aa0bi0¨1", ["channel"] = "neuf:singleplayer", ["pos_cont"] = "(-1,4,-5)", ["text"] = "(2(b(c1(b2345____)(c(1;)ON(1:)OFF | (P(3?CONTROLER@)(1(fs)(q084% | (2(df(to(df(h(1_'a_)(f(1%g_)(h(1`a_)(f (2:(1g) | (r(1x)(f000%(c(1_v)X11Y11Z15 | (1(kV)(h(2`)OVER(l(14$)0003657"}, ["inventory"] = {}}, ["y"] = 9, ["param1"] = 110, ["z"] = 2, ["name"] = "monitor:screen_console"}, {["x"] = 4, ["param2"] = 2, ["y"] = 9, ["param1"] = 63, ["z"] = 7, ["name"] = "moreblocks:slope_obsidian_glass"}, {["x"] = 4, ["param2"] = 225, ["y"] = 10, ["param1"] = 94, ["z"] = 0, ["name"] = "bloc4builder:slope_white"}, {["x"] = 4, ["param2"] = 225, ["y"] = 10, ["param1"] = 110, ["z"] = 1, ["name"] = "bloc4builder:slope_white"}, {["x"] = 4, ["param2"] = 1, ["y"] = 10, ["param1"] = 94, ["z"] = 2, ["name"] = "moreblocks:slope_obsidian_glass"}, {["x"] = 4, ["param2"] = 1, ["y"] = 10, ["param1"] = 79, ["z"] = 3, ["name"] = "moreblocks:slope_obsidian_glass"}, {["x"] = 4, ["param2"] = 1, ["y"] = 10, ["param1"] = 63, ["z"] = 4, ["name"] = "moreblocks:slope_obsidian_glass"}, {["x"] = 4, ["param2"] = 1, ["y"] = 10, ["param1"] = 79, ["z"] = 5, ["name"] = "moreblocks:slope_obsidian_glass"}, {["x"] = 4, ["param2"] = 2, ["y"] = 10, ["param1"] = 63, ["z"] = 6, ["name"] = "moreblocks:slope_obsidian_glass_outer"}, {["x"] = 5, ["param2"] = 1, ["y"] = 0, ["z"] = 0, ["name"] = "bloc4builder:white"}, {["x"] = 5, ["param2"] = 1, ["y"] = 0, ["z"] = 1, ["name"] = "bloc4builder:white"}, {["x"] = 5, ["param2"] = 225, ["y"] = 0, ["z"] = 2, ["name"] = "bloc4builder:white"}, {["x"] = 5, ["param2"] = 1, ["y"] = 0, ["z"] = 3, ["name"] = "bloc4builder:white"}, {["x"] = 5, ["param2"] = 225, ["y"] = 0, ["z"] = 4, ["name"] = "bloc4builder:white"}, {["x"] = 5, ["param2"] = 1, ["y"] = 0, ["z"] = 5, ["name"] = "bloc4builder:white"}, {["x"] = 5, ["param2"] = 225, ["y"] = 0, ["z"] = 6, ["name"] = "bloc4builder:white"}, {["x"] = 5, ["param2"] = 1, ["y"] = 0, ["z"] = 7, ["name"] = "bloc4builder:white"}, {["x"] = 5, ["param2"] = 225, ["y"] = 0, ["z"] = 8, ["name"] = "bloc4builder:white"}, {["x"] = 5, ["param2"] = 1, ["y"] = 0, ["z"] = 9, ["name"] = "bloc4builder:white"}, {["x"] = 5, ["param2"] = 225, ["y"] = 0, ["z"] = 10, ["name"] = "bloc4builder:white"}, {["x"] = 5, ["y"] = 1, ["z"] = 0, ["name"] = "bloc4builder:garage"}, {["x"] = 5, ["param2"] = 225, ["y"] = 1, ["z"] = 10, ["name"] = "bloc4builder:white"}, {["x"] = 5, ["y"] = 2, ["z"] = 0, ["name"] = "bloc4builder:garage"}, {["x"] = 5, ["meta"] = {["fields"] = {["owner"] = "singleplayer", ["channel"] = "neuf"}, ["inventory"] = {}}, ["y"] = 2, ["param1"] = 136, ["z"] = 9, ["name"] = "bloc4builder:keypad"}, {["x"] = 5, ["param2"] = 225, ["y"] = 2, ["z"] = 10, ["name"] = "bloc4builder:white"}, {["x"] = 5, ["y"] = 3, ["z"] = 0, ["name"] = "bloc4builder:garage"}, {["x"] = 5, ["y"] = 3, ["param1"] = 137, ["z"] = 10, ["name"] = "bloc4builder:rail_signal"}, {["x"] = 5, ["param2"] = 128, ["y"] = 3, ["z"] = 11, ["name"] = "bloc4builder:white"}, {["x"] = 5, ["param2"] = 128, ["y"] = 3, ["z"] = 12, ["name"] = "bloc4builder:white"}, {["x"] = 5, ["param2"] = 128, ["y"] = 3, ["z"] = 13, ["name"] = "bloc4builder:white"}, {["x"] = 5, ["param2"] = 128, ["y"] = 3, ["z"] = 14, ["name"] = "bloc4builder:white"}, {["x"] = 5, ["y"] = 4, ["z"] = 0, ["name"] = "bloc4builder:yellow"}, {["x"] = 5, ["param2"] = 22, ["y"] = 4, ["param1"] = 154, ["z"] = 1, ["name"] = "bloc4builder:slab_grille_1"}, {["x"] = 5, ["param2"] = 9, ["y"] = 4, ["param1"] = 137, ["z"] = 9, ["name"] = "bloc4builder:slab_grille_1"}, {["x"] = 5, ["param2"] = 2, ["y"] = 4, ["param1"] = 122, ["z"] = 10, ["name"] = "bloc4builder:stair_grille_alt_1"}, {["x"] = 5, ["param2"] = 9, ["y"] = 4, ["param1"] = 78, ["z"] = 14, ["name"] = "moreblocks:slab_obsidian_glass_1"}, {["x"] = 5, ["param2"] = 225, ["y"] = 5, ["z"] = 0, ["name"] = "bloc4builder:white"}, {["x"] = 5, ["param2"] = 2, ["y"] = 5, ["param1"] = 171, ["z"] = 1, ["name"] = "bloc4builder:ladder"}, {["x"] = 5, ["param2"] = 7, ["y"] = 5, ["param1"] = 187, ["z"] = 2, ["name"] = "bloc4builder:slab_grille_1"}, {["x"] = 5, ["meta"] = {["fields"] = {["spacengine"] = "^L¨250¨0¨^x05y05z07v01815¨6", ["channel"] = "neuf:singleplayer", ["pos_cont"] = "(-20854,1980,-25024)", ["infotext"] = "CONTROLER beta5", ["captain"] = "singleplayer", ["stock_pos"] = "33333#0#0¨-4#-2#-6¨-1#-1#6¨-1#0#6¨-1#3#-2¨-1#4#-5¨0#3#-1¨1#-1#6¨1#0#6¨1#3#-2¨1#4#-5¨4#-2#-6"}, ["inventory"] = {["stock"] = {"spacengine:hydrogene_tank 95", "spacengine:oxygene_tank 98", "", "", "", ""}}}, ["y"] = 5, ["z"] = 7, ["name"] = "spacengine:controler"}, {["x"] = 5, ["param2"] = 2, ["y"] = 5, ["param1"] = 153, ["z"] = 8, ["name"] = "bloc4builder:slab_grille_1"}, {["x"] = 5, ["y"] = 5, ["param1"] = 138, ["z"] = 9, ["name"] = "bloc4builder:slab_grille_1"}, {["x"] = 5, ["param2"] = 9, ["y"] = 5, ["param1"] = 78, ["z"] = 14, ["name"] = "moreblocks:slab_obsidian_glass_1"}, {["x"] = 5, ["param2"] = 1, ["y"] = 6, ["z"] = 0, ["name"] = "bloc4builder:white"}, {["x"] = 5, ["param2"] = 2, ["y"] = 6, ["param1"] = 188, ["z"] = 1, ["name"] = "bloc4builder:ladder"}, {["x"] = 5, ["param2"] = 22, ["y"] = 6, ["param1"] = 221, ["z"] = 3, ["name"] = "bloc4builder:light_on"}, {["x"] = 5, ["param2"] = 22, ["y"] = 6, ["param1"] = 221, ["z"] = 4, ["name"] = "bloc4builder:light_on"}, {["x"] = 5, ["param2"] = 22, ["y"] = 6, ["param1"] = 221, ["z"] = 5, ["name"] = "bloc4builder:light_on"}, {["x"] = 5, ["meta"] = {["fields"] = {["spacengine"] = "^a¨0¨0¨^aA0¨1¨^", ["channel"] = "neuf:singleplayer", ["infotext"] = "ENGINE PUISSANCE", ["pos_cont"] = "(0,1,6)"}, ["inventory"] = {}}, ["param2"] = 8, ["y"] = 6, ["z"] = 13, ["name"] = "spacengine:levier0"}, {["x"] = 5, ["param2"] = 129, ["y"] = 6, ["z"] = 14, ["name"] = "bloc4builder:white"}, {["x"] = 5, ["param2"] = 2, ["y"] = 7, ["z"] = 0, ["name"] = "bloc4builder:white"}, {["x"] = 5, ["param2"] = 2, ["y"] = 7, ["param1"] = 173, ["z"] = 1, ["name"] = "bloc4builder:ladder"}, {["x"] = 5, ["param2"] = 2, ["y"] = 7, ["z"] = 2, ["name"] = "bloc4builder:white"}, {["x"] = 5, ["param2"] = 2, ["y"] = 7, ["z"] = 3, ["name"] = "bloc4builder:white"}, {["x"] = 5, ["param2"] = 2, ["y"] = 7, ["z"] = 4, ["name"] = "bloc4builder:white"}, {["x"] = 5, ["param2"] = 2, ["y"] = 7, ["z"] = 5, ["name"] = "bloc4builder:white"}, {["x"] = 5, ["param2"] = 2, ["y"] = 7, ["z"] = 6, ["name"] = "bloc4builder:white"}, {["x"] = 5, ["meta"] = {["fields"] = {["spacengine"] = "^A¨50¨0¨500", ["channel"] = "neuf:singleplayer", ["infotext"] = "Radio", ["pos_cont"] = "(0,2,0)"}, ["inventory"] = {}}, ["param2"] = 2, ["y"] = 7, ["z"] = 7, ["name"] = "spacengine:radio"}, {["x"] = 5, ["param2"] = 226, ["y"] = 7, ["z"] = 10, ["name"] = "bloc4builder:white"}, {["x"] = 5, ["param2"] = 130, ["y"] = 7, ["param1"] = 110, ["z"] = 11, ["name"] = "bloc4builder:slab_white_1"}, {["x"] = 5, ["param2"] = 130, ["y"] = 7, ["param1"] = 94, ["z"] = 12, ["name"] = "bloc4builder:slab_white_1"}, {["x"] = 5, ["param2"] = 129, ["y"] = 7, ["param1"] = 78, ["z"] = 13, ["name"] = "bloc4builder:slab_white_1"}, {["x"] = 5, ["param2"] = 227, ["y"] = 8, ["z"] = 0, ["name"] = "bloc4builder:white"}, {["x"] = 5, ["meta"] = {["fields"] = {["spacengine"] = "^C¨64¨0¨^bC0bJ0bM0aa0bi0¨1", ["channel"] = "neuf:singleplayer", ["pos_cont"] = "(0,3,-1)", ["text"] = "(2(b(c1(b2345____)(c(1;)ON(1:)OFF | (P(3?CONTROLER@)(1(fs)(q084% | (2(df(to(df(h(1_'a_)(f(1%g_)(h(1`a_)(f (2:(1g) | (r(1x)(f000%(c(1_v)X11Y11Z15 | (1(kV)(h(2`)OVER(l(14$)0003657"}, ["inventory"] = {}}, ["y"] = 8, ["param1"] = 111, ["z"] = 6, ["name"] = "monitor:screen_down"}, {["x"] = 5, ["param2"] = 224, ["y"] = 8, ["z"] = 7, ["name"] = "bloc4builder:rainbow"}, {["x"] = 5, ["param2"] = 163, ["y"] = 8, ["z"] = 8, ["name"] = "bloc4builder:white"}, {["x"] = 5, ["param2"] = 163, ["y"] = 8, ["z"] = 9, ["name"] = "bloc4builder:white"}, {["x"] = 5, ["param2"] = 163, ["y"] = 8, ["z"] = 10, ["name"] = "bloc4builder:white"}, {["x"] = 5, ["param2"] = 224, ["y"] = 9, ["z"] = 0, ["name"] = "bloc4builder:white"}, {["x"] = 5, ["param2"] = 2, ["y"] = 9, ["param1"] = 79, ["z"] = 7, ["name"] = "moreblocks:slope_obsidian_glass"}, {["x"] = 5, ["y"] = 10, ["z"] = 0, ["name"] = "bloc4builder:yellow"}, {["x"] = 5, ["y"] = 10, ["z"] = 1, ["name"] = "bloc4builder:yellow"}, {["x"] = 5, ["y"] = 10, ["param1"] = 111, ["z"] = 2, ["name"] = "default:obsidian_glass"}, {["x"] = 5, ["y"] = 10, ["param1"] = 95, ["z"] = 3, ["name"] = "default:obsidian_glass"}, {["x"] = 5, ["y"] = 10, ["param1"] = 79, ["z"] = 4, ["name"] = "default:obsidian_glass"}, {["x"] = 5, ["y"] = 10, ["param1"] = 63, ["z"] = 5, ["name"] = "default:obsidian_glass"}, {["x"] = 5, ["param2"] = 2, ["y"] = 10, ["param1"] = 79, ["z"] = 6, ["name"] = "moreblocks:slope_obsidian_glass"}, {["x"] = 6, ["param2"] = 225, ["y"] = 0, ["z"] = 0, ["name"] = "bloc4builder:white"}, {["x"] = 6, ["param2"] = 225, ["y"] = 0, ["z"] = 1, ["name"] = "bloc4builder:white"}, {["x"] = 6, ["param2"] = 225, ["y"] = 0, ["z"] = 2, ["name"] = "bloc4builder:white"}, {["x"] = 6, ["param2"] = 225, ["y"] = 0, ["z"] = 3, ["name"] = "bloc4builder:white"}, {["x"] = 6, ["param2"] = 225, ["y"] = 0, ["z"] = 4, ["name"] = "bloc4builder:white"}, {["x"] = 6, ["param2"] = 225, ["y"] = 0, ["z"] = 5, ["name"] = "bloc4builder:white"}, {["x"] = 6, ["param2"] = 225, ["y"] = 0, ["z"] = 6, ["name"] = "bloc4builder:white"}, {["x"] = 6, ["param2"] = 225, ["y"] = 0, ["z"] = 7, ["name"] = "bloc4builder:white"}, {["x"] = 6, ["param2"] = 225, ["y"] = 0, ["z"] = 8, ["name"] = "bloc4builder:white"}, {["x"] = 6, ["param2"] = 1, ["y"] = 0, ["z"] = 9, ["name"] = "bloc4builder:white"}, {["x"] = 6, ["param2"] = 225, ["y"] = 0, ["z"] = 10, ["name"] = "bloc4builder:white"}, {["x"] = 6, ["y"] = 1, ["z"] = 0, ["name"] = "bloc4builder:garage"}, {["x"] = 6, ["param2"] = 225, ["y"] = 1, ["z"] = 10, ["name"] = "bloc4builder:white"}, {["x"] = 6, ["y"] = 2, ["z"] = 0, ["name"] = "bloc4builder:garage"}, {["x"] = 6, ["param2"] = 225, ["y"] = 2, ["z"] = 10, ["name"] = "bloc4builder:white"}, {["x"] = 6, ["y"] = 3, ["z"] = 0, ["name"] = "bloc4builder:garage"}, {["x"] = 6, ["param2"] = 130, ["y"] = 3, ["z"] = 10, ["name"] = "bloc4builder:white"}, {["x"] = 6, ["param2"] = 129, ["y"] = 3, ["z"] = 11, ["name"] = "bloc4builder:white"}, {["x"] = 6, ["param2"] = 128, ["y"] = 3, ["z"] = 12, ["name"] = "bloc4builder:white"}, {["x"] = 6, ["param2"] = 128, ["y"] = 3, ["z"] = 13, ["name"] = "bloc4builder:white"}, {["x"] = 6, ["param2"] = 128, ["y"] = 3, ["z"] = 14, ["name"] = "bloc4builder:white"}, {["x"] = 6, ["param2"] = 1, ["y"] = 4, ["z"] = 0, ["name"] = "bloc4builder:white"}, {["x"] = 6, ["param2"] = 9, ["y"] = 4, ["param1"] = 154, ["z"] = 9, ["name"] = "bloc4builder:slab_grille_1"}, {["x"] = 6, ["param2"] = 12, ["y"] = 4, ["param1"] = 139, ["z"] = 10, ["name"] = "bloc4builder:slab_grille_1"}, {["x"] = 6, ["meta"] = {["fields"] = {["spacengine"] = "^b¨0¨0¨^bC0¨1¨^", ["channel"] = "neuf:singleplayer", ["infotext"] = "CONTROLER on/off", ["pos_cont"] = "(1,-1,5)"}, ["inventory"] = {}}, ["param2"] = 1, ["y"] = 4, ["param1"] = 108, ["z"] = 12, ["name"] = "spacengine:switch_bp"}, {["x"] = 6, ["meta"] = {["fields"] = {["spacengine"] = "^O¨64¨0¨^aG0bf0bM0¨1¨^A", ["channel"] = "neuf:singleplayer", ["pos_cont"] = "(1,-1,6)", ["text"] = "(2(b(c1(b23______)(cPUISSAN | (p(3?OXYGENE@(1_(iG(f(3?ON=@) | (2(fR(1(fRRRQP(2_(c:(1(fPP(kP(kP(hP | (1(j&(fPP(kP(kP(hP)(d1 | (oNb 1/(fS 50"}, ["inventory"] = {}}, ["param2"] = 1, ["y"] = 4, ["param1"] = 109, ["z"] = 13, ["name"] = "monitor:screen_down"}, {["x"] = 6, ["param2"] = 9, ["y"] = 4, ["param1"] = 94, ["z"] = 14, ["name"] = "moreblocks:slab_obsidian_glass_1"}, {["x"] = 6, ["param2"] = 225, ["y"] = 5, ["z"] = 0, ["name"] = "bloc4builder:white"}, {["x"] = 6, ["param2"] = 3, ["y"] = 5, ["param1"] = 154, ["z"] = 1, ["name"] = "bloc4builder:slab_grille_1"}, {["x"] = 6, ["param2"] = 7, ["y"] = 5, ["param1"] = 170, ["z"] = 2, ["name"] = "bloc4builder:slab_grille_1"}, {["x"] = 6, ["param2"] = 12, ["y"] = 5, ["param1"] = 153, ["z"] = 7, ["name"] = "bloc4builder:slab_grille_1"}, {["x"] = 6, ["param2"] = 12, ["y"] = 5, ["param1"] = 138, ["z"] = 8, ["name"] = "bloc4builder:slab_grille_1"}, {["x"] = 6, ["param2"] = 2, ["y"] = 5, ["param1"] = 139, ["z"] = 9, ["name"] = "bloc4builder:slab_grille_two_sides"}, {["x"] = 6, ["param2"] = 7, ["y"] = 5, ["param1"] = 124, ["z"] = 10, ["name"] = "bloc4builder:slab_grille_two_sides"}, {["x"] = 6, ["meta"] = {["fields"] = {["spacengine"] = "^i¨0¨0¨^iA0¨1¨^", ["channel"] = "neuf:singleplayer", ["infotext"] = "POWER ON/OFF", ["pos_cont"] = "(1,0,4)"}, ["inventory"] = {}}, ["param2"] = 1, ["y"] = 5, ["param1"] = 109, ["z"] = 11, ["name"] = "spacengine:inter_0"}, {["x"] = 6, ["meta"] = {["fields"] = {["spacengine"] = "^a¨0¨0¨^aA0¨1¨^", ["channel"] = "neuf:singleplayer", ["infotext"] = "ENGINE PUISSANCE", ["pos_cont"] = "(1,0,5)"}, ["inventory"] = {}}, ["param2"] = 1, ["y"] = 5, ["param1"] = 93, ["z"] = 12, ["name"] = "spacengine:analog00"}, {["x"] = 6, ["meta"] = {["fields"] = {["spacengine"] = "^W¨64¨0¨^bF0aC0aD0aI0bM0¨1", ["channel"] = "neuf:singleplayer", ["pos_cont"] = "(1,0,6)", ["text"] = "(2(b(c1(b2345____)(c(h(1!)FIRE (1!) | (p (3?WEAPONS@) (fREADY! | (1(hp)(q021%(l(1_%)006 (d(1v)002 | (1(g*G)04590U(1_(mwA)000 | (e(2_Q)0000/0005"}, ["inventory"] = {}}, ["param2"] = 1, ["y"] = 5, ["param1"] = 109, ["z"] = 13, ["name"] = "monitor:screen_wall"}, {["x"] = 6, ["param2"] = 9, ["y"] = 5, ["param1"] = 94, ["z"] = 14, ["name"] = "moreblocks:slab_obsidian_glass_1"}, {["x"] = 6, ["meta"] = {["fields"] = {["spacengine"] = "^A¨75¨0¨10¨50¨50¨500", ["channel"] = "neuf:singleplayer", ["infotext"] = "Rocket", ["pos_cont"] = "(1,1,-7)"}, ["inventory"] = {}}, ["y"] = 6, ["z"] = 0, ["name"] = "spacengine:engine"}, {["x"] = 6, ["param2"] = 12, ["y"] = 6, ["param1"] = 170, ["z"] = 7, ["name"] = "bloc4builder:slab_grille_1"}, {["x"] = 6, ["param2"] = 151, ["y"] = 6, ["param1"] = 110, ["z"] = 11, ["name"] = "bloc4builder:slope_white"}, {["x"] = 6, ["param2"] = 151, ["y"] = 6, ["param1"] = 94, ["z"] = 12, ["name"] = "bloc4builder:slope_white"}, {["x"] = 6, ["param2"] = 151, ["y"] = 6, ["param1"] = 94, ["z"] = 13, ["name"] = "bloc4builder:slope_white"}, {["x"] = 6, ["param2"] = 131, ["y"] = 6, ["z"] = 14, ["name"] = "bloc4builder:white"}, {["x"] = 6, ["param2"] = 2, ["y"] = 7, ["z"] = 0, ["name"] = "bloc4builder:white"}, {["x"] = 6, ["param2"] = 2, ["y"] = 7, ["z"] = 1, ["name"] = "bloc4builder:white"}, {["x"] = 6, ["param2"] = 2, ["y"] = 7, ["z"] = 2, ["name"] = "bloc4builder:white"}, {["x"] = 6, ["param2"] = 2, ["y"] = 7, ["z"] = 3, ["name"] = "bloc4builder:white"}, {["x"] = 6, ["param2"] = 2, ["y"] = 7, ["z"] = 4, ["name"] = "bloc4builder:white"}, {["x"] = 6, ["param2"] = 2, ["y"] = 7, ["z"] = 5, ["name"] = "bloc4builder:white"}, {["x"] = 6, ["param2"] = 2, ["y"] = 7, ["z"] = 6, ["name"] = "bloc4builder:white"}, {["x"] = 6, ["param2"] = 12, ["y"] = 7, ["param1"] = 154, ["z"] = 7, ["name"] = "bloc4builder:slab_grille_1"}, {["x"] = 6, ["param2"] = 226, ["y"] = 7, ["z"] = 10, ["name"] = "bloc4builder:white"}, {["x"] = 6, ["param2"] = 227, ["y"] = 8, ["z"] = 0, ["name"] = "bloc4builder:white"}, {["x"] = 6, ["y"] = 8, ["param1"] = 127, ["z"] = 2, ["name"] = "monitor:console_base"}, {["x"] = 6, ["meta"] = {["fields"] = {["spacengine"] = "^t¨0¨0¨^bC0bC0bC0bC0¨1¨^", ["channel"] = "neuf:singleplayer", ["infotext"] = "CONTROLER on/off -- 1 --\
CONTROLER on/off -- 2 --\
CONTROLER on/off -- 3 --\
CONTROLER on/off -- 4 --", ["pos_cont"] = "(1,3,-4)"}, ["inventory"] = {}}, ["param2"] = 1, ["y"] = 8, ["param1"] = 111, ["z"] = 3, ["name"] = "spacengine:switch_4bp3"}, {["x"] = 6, ["meta"] = {["fields"] = {["spacengine"] = "^t¨0¨0¨^bC0bC0bC0bC0¨1¨^", ["channel"] = "neuf:singleplayer", ["infotext"] = "CONTROLER on/off -- 1 --\
CONTROLER on/off -- 2 --\
CONTROLER on/off -- 3 --\
CONTROLER on/off -- 4 --", ["pos_cont"] = "(1,3,-3)"}, ["inventory"] = {}}, ["param2"] = 1, ["y"] = 8, ["param1"] = 95, ["z"] = 4, ["name"] = "spacengine:switch_4bp1"}, {["x"] = 6, ["meta"] = {["fields"] = {["spacengine"] = "^C¨64¨0¨^bC0bJ0bM0aa0bi0¨1", ["channel"] = "neuf:singleplayer", ["pos_cont"] = "(1,3,-2)", ["text"] = "(2(b(c1(b2345____)(c(1;)ON(1:)OFF | (P(3?CONTROLER@)(1(fs)(q084% | (2(df(to(df(h(1_'a_)(f(1%g_)(h(1`a_)(f (2:(1g) | (r(1x)(f000%(c(1_v)X11Y11Z15 | (1(kV)(h(2`)OVER(l(14$)0003657"}, ["inventory"] = {}}, ["param2"] = 1, ["y"] = 8, ["param1"] = 111, ["z"] = 5, ["name"] = "monitor:screen_down"}, {["x"] = 6, ["param2"] = 233, ["y"] = 8, ["param1"] = 94, ["z"] = 6, ["name"] = "bloc4builder:slope_rainbow"}, {["x"] = 6, ["param2"] = 227, ["y"] = 8, ["z"] = 7, ["name"] = "bloc4builder:rainbow"}, {["x"] = 6, ["param2"] = 163, ["y"] = 8, ["z"] = 8, ["name"] = "bloc4builder:white"}, {["x"] = 6, ["param2"] = 163, ["y"] = 8, ["z"] = 9, ["name"] = "bloc4builder:white"}, {["x"] = 6, ["param2"] = 227, ["y"] = 8, ["z"] = 10, ["name"] = "bloc4builder:white"}, {["x"] = 6, ["param2"] = 224, ["y"] = 9, ["z"] = 0, ["name"] = "bloc4builder:white"}, {["x"] = 6, ["meta"] = {["fields"] = {["spacengine"] = "^C¨64¨0¨^bC0bJ0bM0aa0bi0¨1", ["channel"] = "neuf:singleplayer", ["pos_cont"] = "(1,4,-5)", ["text"] = "(2(b(c1(b2345____)(c(1;)ON(1:)OFF | (P(3?CONTROLER@)(1(fs)(q084% | (2(df(to(df(h(1_'a_)(f(1%g_)(h(1`a_)(f (2:(1g) | (r(1x)(f000%(c(1_v)X11Y11Z15 | (1(kV)(h(2`)OVER(l(14$)0003657"}, ["inventory"] = {}}, ["y"] = 9, ["param1"] = 111, ["z"] = 2, ["name"] = "monitor:screen_console"}, {["x"] = 6, ["param2"] = 2, ["y"] = 9, ["param1"] = 63, ["z"] = 7, ["name"] = "moreblocks:slope_obsidian_glass"}, {["x"] = 6, ["param2"] = 227, ["y"] = 10, ["param1"] = 93, ["z"] = 0, ["name"] = "bloc4builder:slope_white"}, {["x"] = 6, ["param2"] = 227, ["y"] = 10, ["param1"] = 110, ["z"] = 1, ["name"] = "bloc4builder:slope_white"}, {["x"] = 6, ["param2"] = 3, ["y"] = 10, ["param1"] = 95, ["z"] = 2, ["name"] = "moreblocks:slope_obsidian_glass"}, {["x"] = 6, ["param2"] = 3, ["y"] = 10, ["param1"] = 79, ["z"] = 3, ["name"] = "moreblocks:slope_obsidian_glass"}, {["x"] = 6, ["param2"] = 3, ["y"] = 10, ["param1"] = 63, ["z"] = 4, ["name"] = "moreblocks:slope_obsidian_glass"}, {["x"] = 6, ["param2"] = 3, ["y"] = 10, ["param1"] = 79, ["z"] = 5, ["name"] = "moreblocks:slope_obsidian_glass"}, {["x"] = 6, ["param2"] = 3, ["y"] = 10, ["param1"] = 63, ["z"] = 6, ["name"] = "moreblocks:slope_obsidian_glass_outer"}, {["x"] = 7, ["param2"] = 225, ["y"] = 0, ["z"] = 0, ["name"] = "bloc4builder:white"}, {["x"] = 7, ["param2"] = 225, ["y"] = 0, ["z"] = 1, ["name"] = "bloc4builder:white"}, {["x"] = 7, ["param2"] = 225, ["y"] = 0, ["z"] = 2, ["name"] = "bloc4builder:white"}, {["x"] = 7, ["param2"] = 225, ["y"] = 0, ["z"] = 3, ["name"] = "bloc4builder:white"}, {["x"] = 7, ["param2"] = 225, ["y"] = 0, ["z"] = 4, ["name"] = "bloc4builder:white"}, {["x"] = 7, ["param2"] = 225, ["y"] = 0, ["z"] = 5, ["name"] = "bloc4builder:white"}, {["x"] = 7, ["param2"] = 225, ["y"] = 0, ["z"] = 6, ["name"] = "bloc4builder:white"}, {["x"] = 7, ["param2"] = 225, ["y"] = 0, ["z"] = 7, ["name"] = "bloc4builder:white"}, {["x"] = 7, ["param2"] = 1, ["y"] = 0, ["z"] = 8, ["name"] = "bloc4builder:white"}, {["x"] = 7, ["param2"] = 1, ["y"] = 0, ["z"] = 9, ["name"] = "bloc4builder:white"}, {["x"] = 7, ["param2"] = 225, ["y"] = 0, ["z"] = 10, ["name"] = "bloc4builder:white"}, {["x"] = 7, ["y"] = 1, ["z"] = 0, ["name"] = "bloc4builder:garage"}, {["x"] = 7, ["y"] = 1, ["param1"] = 155, ["z"] = 9, ["name"] = "bloc4builder:ladder"}, {["x"] = 7, ["param2"] = 225, ["y"] = 1, ["z"] = 10, ["name"] = "bloc4builder:white"}, {["x"] = 7, ["y"] = 2, ["z"] = 0, ["name"] = "bloc4builder:garage"}, {["x"] = 7, ["y"] = 2, ["param1"] = 170, ["z"] = 9, ["name"] = "bloc4builder:ladder"}, {["x"] = 7, ["param2"] = 225, ["y"] = 2, ["z"] = 10, ["name"] = "bloc4builder:white"}, {["x"] = 7, ["y"] = 3, ["z"] = 0, ["name"] = "bloc4builder:garage"}, {["x"] = 7, ["y"] = 3, ["param1"] = 187, ["z"] = 9, ["name"] = "bloc4builder:ladder"}, {["x"] = 7, ["param2"] = 224, ["y"] = 3, ["z"] = 10, ["name"] = "bloc4builder:white"}, {["x"] = 7, ["param2"] = 149, ["y"] = 3, ["param1"] = 62, ["z"] = 11, ["name"] = "bloc4builder:slope_white"}, {["x"] = 7, ["param2"] = 149, ["y"] = 3, ["param1"] = 62, ["z"] = 12, ["name"] = "bloc4builder:slope_white"}, {["x"] = 7, ["param2"] = 149, ["y"] = 3, ["param1"] = 77, ["z"] = 13, ["name"] = "bloc4builder:slope_white"}, {["x"] = 7, ["param2"] = 149, ["y"] = 3, ["param1"] = 62, ["z"] = 14, ["name"] = "bloc4builder:slope_white"}, {["x"] = 7, ["y"] = 4, ["z"] = 0, ["name"] = "bloc4builder:yellow"}, {["x"] = 7, ["y"] = 4, ["param1"] = 170, ["z"] = 9, ["name"] = "bloc4builder:ladder"}, {["x"] = 7, ["param2"] = 1, ["y"] = 4, ["z"] = 10, ["name"] = "bloc4builder:white"}, {["x"] = 7, ["param2"] = 131, ["y"] = 4, ["z"] = 11, ["name"] = "bloc4builder:white"}, {["x"] = 7, ["param2"] = 131, ["y"] = 4, ["z"] = 12, ["name"] = "bloc4builder:white"}, {["x"] = 7, ["param2"] = 131, ["y"] = 4, ["z"] = 13, ["name"] = "bloc4builder:white"}, {["x"] = 7, ["param2"] = 131, ["y"] = 4, ["z"] = 14, ["name"] = "bloc4builder:white"}, {["x"] = 7, ["param2"] = 225, ["y"] = 5, ["z"] = 0, ["name"] = "bloc4builder:white"}, {["x"] = 7, ["param2"] = 3, ["y"] = 5, ["param1"] = 137, ["z"] = 1, ["name"] = "bloc4builder:slab_grille_1"}, {["x"] = 7, ["param2"] = 7, ["y"] = 5, ["param1"] = 153, ["z"] = 2, ["name"] = "bloc4builder:slab_grille_1"}, {["x"] = 7, ["param2"] = 9, ["y"] = 5, ["param1"] = 137, ["z"] = 8, ["name"] = "bloc4builder:slab_grille_1"}, {["x"] = 7, ["meta"] = {["fields"] = {["spacengine"] = "^C¨150¨0¨50000", ["channel"] = "neuf:singleplayer", ["infotext"] = "BATTERY Mega5", ["pos_cont"] = "(2,0,3)"}, ["inventory"] = {}}, ["param2"] = 1, ["y"] = 5, ["z"] = 10, ["name"] = "spacengine:battery"}, {["x"] = 7, ["param2"] = 131, ["y"] = 5, ["z"] = 11, ["name"] = "bloc4builder:white"}, {["x"] = 7, ["param2"] = 131, ["y"] = 5, ["z"] = 12, ["name"] = "bloc4builder:white"}, {["x"] = 7, ["param2"] = 131, ["y"] = 5, ["z"] = 13, ["name"] = "bloc4builder:white"}, {["x"] = 7, ["param2"] = 131, ["y"] = 5, ["z"] = 14, ["name"] = "bloc4builder:white"}, {["x"] = 7, ["param2"] = 2, ["y"] = 6, ["z"] = 0, ["name"] = "bloc4builder:white"}, {["x"] = 7, ["param2"] = 21, ["y"] = 6, ["param1"] = 187, ["z"] = 5, ["name"] = "bloc4builder:slab_white_1"}, {["x"] = 7, ["param2"] = 20, ["y"] = 6, ["param1"] = 170, ["z"] = 6, ["name"] = "bloc4builder:slab_white_1"}, {["x"] = 7, ["param2"] = 225, ["y"] = 6, ["z"] = 10, ["name"] = "bloc4builder:white"}, {["x"] = 7, ["param2"] = 131, ["y"] = 6, ["param1"] = 94, ["z"] = 11, ["name"] = "bloc4builder:slope_white"}, {["x"] = 7, ["param2"] = 131, ["y"] = 6, ["param1"] = 78, ["z"] = 12, ["name"] = "bloc4builder:slope_white"}, {["x"] = 7, ["param2"] = 131, ["y"] = 6, ["param1"] = 78, ["z"] = 13, ["name"] = "bloc4builder:slope_white"}, {["x"] = 7, ["param2"] = 131, ["y"] = 6, ["param1"] = 94, ["z"] = 14, ["name"] = "bloc4builder:slope_white"}, {["x"] = 7, ["param2"] = 2, ["y"] = 7, ["z"] = 0, ["name"] = "bloc4builder:white"}, {["x"] = 7, ["param2"] = 9, ["y"] = 7, ["param1"] = 171, ["z"] = 4, ["name"] = "bloc4builder:slab_white_1"}, {["x"] = 7, ["meta"] = {["fields"] = {["spacengine"] = "^A¨100¨0¨4", ["channel"] = "neuf:singleplayer", ["infotext"] = "Gforce MOON", ["pos_cont"] = "(2,2,-2)"}, ["inventory"] = {}}, ["param2"] = 3, ["y"] = 7, ["z"] = 5, ["name"] = "spacengine:gravitation"}, {["x"] = 7, ["meta"] = {["fields"] = {["spacengine"] = "^A¨150¨0¨1¨50", ["channel"] = "neuf:singleplayer", ["infotext"] = "Oxygene", ["pos_cont"] = "(2,2,-1)"}, ["inventory"] = {}}, ["param2"] = 3, ["y"] = 7, ["z"] = 6, ["name"] = "spacengine:oxygene"}, {["x"] = 7, ["param2"] = 4, ["y"] = 7, ["param1"] = 139, ["z"] = 7, ["name"] = "bloc4builder:slab_white_1"}, {["x"] = 7, ["param2"] = 226, ["y"] = 7, ["z"] = 10, ["name"] = "bloc4builder:white"}, {["x"] = 7, ["param2"] = 227, ["y"] = 8, ["z"] = 0, ["name"] = "bloc4builder:white"}, {["x"] = 7, ["param2"] = 226, ["y"] = 8, ["z"] = 1, ["name"] = "bloc4builder:rainbow"}, {["x"] = 7, ["param2"] = 226, ["y"] = 8, ["z"] = 2, ["name"] = "bloc4builder:rainbow"}, {["x"] = 7, ["param2"] = 226, ["y"] = 8, ["z"] = 3, ["name"] = "bloc4builder:rainbow"}, {["x"] = 7, ["param2"] = 225, ["y"] = 8, ["z"] = 4, ["name"] = "bloc4builder:rainbow"}, {["x"] = 7, ["param2"] = 225, ["y"] = 8, ["z"] = 5, ["name"] = "bloc4builder:rainbow"}, {["x"] = 7, ["param2"] = 224, ["y"] = 8, ["z"] = 6, ["name"] = "bloc4builder:rainbow"}, {["x"] = 7, ["param2"] = 224, ["y"] = 8, ["z"] = 7, ["name"] = "bloc4builder:rainbow"}, {["x"] = 7, ["param2"] = 163, ["y"] = 8, ["z"] = 8, ["name"] = "bloc4builder:white"}, {["x"] = 7, ["param2"] = 227, ["y"] = 8, ["z"] = 9, ["name"] = "bloc4builder:white"}, {["x"] = 7, ["param2"] = 227, ["y"] = 8, ["z"] = 10, ["name"] = "bloc4builder:white"}, {["x"] = 7, ["param2"] = 227, ["y"] = 9, ["param1"] = 93, ["z"] = 0, ["name"] = "bloc4builder:slope_white"}, {["x"] = 7, ["param2"] = 227, ["y"] = 9, ["param1"] = 110, ["z"] = 1, ["name"] = "bloc4builder:slope_white"}, {["x"] = 7, ["param2"] = 3, ["y"] = 9, ["param1"] = 95, ["z"] = 2, ["name"] = "moreblocks:slope_obsidian_glass"}, {["x"] = 7, ["param2"] = 3, ["y"] = 9, ["param1"] = 79, ["z"] = 3, ["name"] = "moreblocks:slope_obsidian_glass"}, {["x"] = 7, ["param2"] = 3, ["y"] = 9, ["param1"] = 79, ["z"] = 4, ["name"] = "moreblocks:slope_obsidian_glass"}, {["x"] = 7, ["param2"] = 3, ["y"] = 9, ["param1"] = 95, ["z"] = 5, ["name"] = "moreblocks:slope_obsidian_glass"}, {["x"] = 7, ["param2"] = 3, ["y"] = 9, ["param1"] = 79, ["z"] = 6, ["name"] = "moreblocks:slope_obsidian_glass"}, {["x"] = 7, ["param2"] = 3, ["y"] = 9, ["param1"] = 63, ["z"] = 7, ["name"] = "moreblocks:slope_obsidian_glass_outer"}, {["x"] = 8, ["param2"] = 225, ["y"] = 0, ["z"] = 0, ["name"] = "bloc4builder:white"}, {["x"] = 8, ["param2"] = 225, ["y"] = 0, ["z"] = 1, ["name"] = "bloc4builder:white"}, {["x"] = 8, ["param2"] = 225, ["y"] = 0, ["z"] = 2, ["name"] = "bloc4builder:white"}, {["x"] = 8, ["param2"] = 225, ["y"] = 0, ["z"] = 3, ["name"] = "bloc4builder:white"}, {["x"] = 8, ["param2"] = 225, ["y"] = 0, ["z"] = 4, ["name"] = "bloc4builder:white"}, {["x"] = 8, ["param2"] = 225, ["y"] = 0, ["z"] = 5, ["name"] = "bloc4builder:white"}, {["x"] = 8, ["param2"] = 225, ["y"] = 0, ["z"] = 6, ["name"] = "bloc4builder:white"}, {["x"] = 8, ["param2"] = 225, ["y"] = 0, ["z"] = 7, ["name"] = "bloc4builder:white"}, {["x"] = 8, ["param2"] = 225, ["y"] = 0, ["z"] = 8, ["name"] = "bloc4builder:white"}, {["x"] = 8, ["param2"] = 225, ["y"] = 0, ["z"] = 9, ["name"] = "bloc4builder:white"}, {["x"] = 8, ["param2"] = 225, ["y"] = 0, ["z"] = 10, ["name"] = "bloc4builder:white"}, {["x"] = 8, ["y"] = 1, ["z"] = 0, ["name"] = "bloc4builder:yellow"}, {["x"] = 8, ["param2"] = 226, ["y"] = 1, ["z"] = 10, ["name"] = "bloc4builder:white"}, {["x"] = 8, ["param2"] = 1, ["y"] = 2, ["z"] = 0, ["name"] = "bloc4builder:white"}, {["x"] = 8, ["param2"] = 225, ["y"] = 2, ["z"] = 10, ["name"] = "bloc4builder:white"}, {["x"] = 8, ["y"] = 3, ["z"] = 0, ["name"] = "bloc4builder:yellow"}, {["x"] = 8, ["param2"] = 225, ["y"] = 3, ["z"] = 10, ["name"] = "bloc4builder:white"}, {["x"] = 8, ["param2"] = 1, ["y"] = 4, ["z"] = 0, ["name"] = "bloc4builder:white"}, {["x"] = 8, ["param2"] = 225, ["y"] = 4, ["z"] = 10, ["name"] = "bloc4builder:white"}, {["x"] = 8, ["param2"] = 226, ["y"] = 5, ["z"] = 0, ["name"] = "bloc4builder:white"}, {["x"] = 8, ["param2"] = 2, ["y"] = 5, ["param1"] = 122, ["z"] = 1, ["name"] = "bloc4builder:slab_grille_1"}, {["x"] = 8, ["param2"] = 3, ["y"] = 5, ["param1"] = 138, ["z"] = 2, ["name"] = "bloc4builder:slab_grille_two_sides"}, {["x"] = 8, ["param2"] = 3, ["y"] = 5, ["param1"] = 154, ["z"] = 3, ["name"] = "bloc4builder:slab_grille_two_sides"}, {["x"] = 8, ["param2"] = 3, ["y"] = 5, ["param1"] = 154, ["z"] = 4, ["name"] = "bloc4builder:slab_grille_two_sides"}, {["x"] = 8, ["param2"] = 3, ["y"] = 5, ["param1"] = 170, ["z"] = 5, ["name"] = "bloc4builder:slab_grille_two_sides"}, {["x"] = 8, ["param2"] = 3, ["y"] = 5, ["param1"] = 154, ["z"] = 6, ["name"] = "bloc4builder:slab_grille_two_sides"}, {["x"] = 8, ["param2"] = 3, ["y"] = 5, ["param1"] = 138, ["z"] = 7, ["name"] = "bloc4builder:slab_grille_two_sides"}, {["x"] = 8, ["param2"] = 3, ["y"] = 5, ["param1"] = 154, ["z"] = 8, ["name"] = "bloc4builder:slab_grille_two_sides"}, {["x"] = 8, ["param2"] = 1, ["y"] = 5, ["param1"] = 170, ["z"] = 9, ["name"] = "bloc4builder:slab_grille_1"}, {["x"] = 8, ["param2"] = 225, ["y"] = 5, ["z"] = 10, ["name"] = "bloc4builder:white"}, {["x"] = 8, ["meta"] = {["fields"] = {["spacengine"] = "^A¨100¨0¨750¨20¨5¨2", ["channel"] = "neuf:singleplayer", ["infotext"] = "LASER", ["pos_cont"] = "(3,0,6)"}, ["inventory"] = {}}, ["param2"] = 14, ["y"] = 5, ["param1"] = 78, ["z"] = 13, ["name"] = "spacengine:weapons"}, {["x"] = 8, ["meta"] = {["fields"] = {["spacengine"] = "^A¨75¨0¨10¨50¨50¨500", ["channel"] = "neuf:singleplayer", ["infotext"] = "Rocket", ["pos_cont"] = "(3,1,-7)"}, ["inventory"] = {}}, ["y"] = 6, ["z"] = 0, ["name"] = "spacengine:engine"}, {["x"] = 8, ["param2"] = 225, ["y"] = 6, ["z"] = 10, ["name"] = "bloc4builder:white"}, {["x"] = 8, ["meta"] = {["fields"] = {["spacengine"] = "^A¨75¨0¨10¨50¨50¨500", ["channel"] = "neuf:singleplayer", ["infotext"] = "Rocket", ["pos_cont"] = "(3,2,-7)"}, ["inventory"] = {}}, ["y"] = 7, ["z"] = 0, ["name"] = "spacengine:engine"}, {["x"] = 8, ["param2"] = 224, ["y"] = 7, ["z"] = 10, ["name"] = "bloc4builder:white"}, {["x"] = 8, ["param2"] = 227, ["y"] = 8, ["z"] = 0, ["name"] = "bloc4builder:white"}, {["x"] = 8, ["param2"] = 227, ["y"] = 8, ["z"] = 1, ["name"] = "bloc4builder:white"}, {["x"] = 8, ["param2"] = 163, ["y"] = 8, ["z"] = 2, ["name"] = "bloc4builder:white"}, {["x"] = 8, ["param2"] = 163, ["y"] = 8, ["z"] = 3, ["name"] = "bloc4builder:white"}, {["x"] = 8, ["param2"] = 163, ["y"] = 8, ["z"] = 4, ["name"] = "bloc4builder:white"}, {["x"] = 8, ["param2"] = 163, ["y"] = 8, ["z"] = 5, ["name"] = "bloc4builder:white"}, {["x"] = 8, ["param2"] = 163, ["y"] = 8, ["z"] = 6, ["name"] = "bloc4builder:white"}, {["x"] = 8, ["param2"] = 163, ["y"] = 8, ["z"] = 7, ["name"] = "bloc4builder:white"}, {["x"] = 8, ["param2"] = 227, ["y"] = 8, ["z"] = 8, ["name"] = "bloc4builder:white"}, {["x"] = 8, ["param2"] = 227, ["y"] = 8, ["z"] = 9, ["name"] = "bloc4builder:white"}, {["x"] = 8, ["param2"] = 227, ["y"] = 8, ["z"] = 10, ["name"] = "bloc4builder:white"}, {["x"] = 8, ["meta"] = {["fields"] = {["spacengine"] = "^A¨100¨0¨750¨20¨5¨2", ["channel"] = "neuf:singleplayer", ["infotext"] = "LASER", ["pos_cont"] = "(3,4,-6)"}, ["inventory"] = {}}, ["param2"] = 3, ["y"] = 9, ["param1"] = 94, ["z"] = 1, ["name"] = "spacengine:weapons"}, {["x"] = 8, ["meta"] = {["fields"] = {["spacengine"] = "^A¨100¨0¨750¨20¨5¨2", ["channel"] = "neuf:singleplayer", ["infotext"] = "LASER", ["pos_cont"] = "(3,4,2)"}, ["inventory"] = {}}, ["param2"] = 3, ["y"] = 9, ["param1"] = 110, ["z"] = 9, ["name"] = "spacengine:weapons"}, {["x"] = 9, ["param2"] = 245, ["y"] = 0, ["param1"] = 126, ["z"] = 0, ["name"] = "bloc4builder:slope_white_half_raised"}, {["x"] = 9, ["param2"] = 245, ["y"] = 0, ["param1"] = 109, ["z"] = 1, ["name"] = "bloc4builder:slope_white_half_raised"}, {["x"] = 9, ["param2"] = 245, ["y"] = 0, ["param1"] = 125, ["z"] = 2, ["name"] = "bloc4builder:slope_white_half_raised"}, {["x"] = 9, ["param2"] = 245, ["y"] = 0, ["param1"] = 141, ["z"] = 3, ["name"] = "bloc4builder:slope_white_half_raised"}, {["x"] = 9, ["param2"] = 245, ["y"] = 0, ["param1"] = 157, ["z"] = 4, ["name"] = "bloc4builder:slope_white_half_raised"}, {["x"] = 9, ["param2"] = 245, ["y"] = 0, ["param1"] = 172, ["z"] = 5, ["name"] = "bloc4builder:slope_white_half_raised"}, {["x"] = 9, ["param2"] = 245, ["y"] = 0, ["param1"] = 157, ["z"] = 6, ["name"] = "bloc4builder:slope_white_half_raised"}, {["x"] = 9, ["param2"] = 245, ["y"] = 0, ["param1"] = 141, ["z"] = 7, ["name"] = "bloc4builder:slope_white_half_raised"}, {["x"] = 9, ["param2"] = 245, ["y"] = 0, ["param1"] = 157, ["z"] = 8, ["name"] = "bloc4builder:slope_white_half_raised"}, {["x"] = 9, ["param2"] = 245, ["y"] = 0, ["param1"] = 173, ["z"] = 9, ["name"] = "bloc4builder:slope_white_half_raised"}, {["x"] = 9, ["param2"] = 245, ["y"] = 0, ["param1"] = 158, ["z"] = 10, ["name"] = "bloc4builder:slope_white_half_raised"}, {["x"] = 9, ["param2"] = 225, ["y"] = 1, ["z"] = 0, ["name"] = "bloc4builder:white"}, {["x"] = 9, ["meta"] = {["fields"] = {["spacengine"] = "^B¨125¨0¨625¨2", ["channel"] = "neuf:singleplayer", ["infotext"] = "WatchDog", ["pos_cont"] = "(4,-4,-6)"}, ["inventory"] = {}}, ["y"] = 1, ["z"] = 1, ["name"] = "spacengine:shield"}, {["x"] = 9, ["param2"] = 226, ["y"] = 1, ["z"] = 10, ["name"] = "bloc4builder:white"}, {["x"] = 9, ["param2"] = 225, ["y"] = 2, ["z"] = 0, ["name"] = "bloc4builder:white"}, {["x"] = 9, ["meta"] = {["fields"] = {["spacengine"] = "^B¨125¨0¨625¨2", ["channel"] = "neuf:singleplayer", ["infotext"] = "WatchDog", ["pos_cont"] = "(4,-3,-6)"}, ["inventory"] = {}}, ["y"] = 2, ["z"] = 1, ["name"] = "spacengine:shield"}, {["x"] = 9, ["meta"] = {["fields"] = {["spacengine"] = "^i¨0¨0¨^iA0¨1¨^", ["channel"] = "neuf:singleplayer", ["infotext"] = "POWER ON/OFF", ["pos_cont"] = "(4,-3,-4)"}, ["inventory"] = {}}, ["param2"] = 1, ["y"] = 2, ["param1"] = 172, ["z"] = 3, ["name"] = "spacengine:inter_0"}, {["x"] = 9, ["param2"] = 225, ["y"] = 2, ["z"] = 10, ["name"] = "bloc4builder:white"}, {["x"] = 9, ["param2"] = 225, ["y"] = 3, ["z"] = 0, ["name"] = "bloc4builder:white"}, {["x"] = 9, ["meta"] = {["fields"] = {["spacengine"] = "2¨150¨0¨500¨^spacengine:hydrogene_tank¨^battery¨15¨1¨11¨500", ["channel"] = "neuf:singleplayer", ["infotext"] = "Generateur Hydrogene", ["pos_cont"] = "(4,-2,-6)"}, ["inventory"] = {}}, ["param2"] = 2, ["y"] = 3, ["param1"] = 154, ["z"] = 1, ["name"] = "spacengine:power"}, {["x"] = 9, ["param2"] = 18, ["y"] = 3, ["param1"] = 221, ["z"] = 5, ["name"] = "bloc4builder:light_on"}, {["x"] = 9, ["param2"] = 18, ["y"] = 3, ["param1"] = 221, ["z"] = 9, ["name"] = "bloc4builder:light_on"}, {["x"] = 9, ["param2"] = 225, ["y"] = 3, ["z"] = 10, ["name"] = "bloc4builder:white"}, {["x"] = 9, ["param2"] = 225, ["y"] = 4, ["z"] = 0, ["name"] = "bloc4builder:white"}, {["x"] = 9, ["param2"] = 2, ["y"] = 4, ["z"] = 1, ["name"] = "bloc4builder:white"}, {["x"] = 9, ["param2"] = 225, ["y"] = 4, ["z"] = 10, ["name"] = "bloc4builder:white"}, {["x"] = 9, ["param2"] = 225, ["y"] = 5, ["z"] = 0, ["name"] = "bloc4builder:white"}, {["x"] = 9, ["param2"] = 2, ["y"] = 5, ["param1"] = 123, ["z"] = 1, ["name"] = "bloc4builder:slab_grille_1"}, {["x"] = 9, ["param2"] = 2, ["y"] = 5, ["param1"] = 139, ["z"] = 2, ["name"] = "bloc4builder:slab_grille_1"}, {["x"] = 9, ["param2"] = 2, ["y"] = 5, ["param1"] = 155, ["z"] = 3, ["name"] = "bloc4builder:slab_grille_1"}, {["x"] = 9, ["param2"] = 2, ["y"] = 5, ["param1"] = 171, ["z"] = 4, ["name"] = "bloc4builder:slab_grille_1"}, {["x"] = 9, ["param2"] = 2, ["y"] = 5, ["param1"] = 187, ["z"] = 5, ["name"] = "bloc4builder:slab_grille_1"}, {["x"] = 9, ["y"] = 5, ["param1"] = 171, ["z"] = 6, ["name"] = "bloc4builder:slab_grille_1"}, {["x"] = 9, ["y"] = 5, ["param1"] = 155, ["z"] = 7, ["name"] = "bloc4builder:slab_grille_1"}, {["x"] = 9, ["y"] = 5, ["param1"] = 171, ["z"] = 8, ["name"] = "bloc4builder:slab_grille_1"}, {["x"] = 9, ["param2"] = 1, ["y"] = 5, ["param1"] = 187, ["z"] = 9, ["name"] = "bloc4builder:slab_grille_1"}, {["x"] = 9, ["param2"] = 225, ["y"] = 5, ["z"] = 10, ["name"] = "bloc4builder:white"}, {["x"] = 9, ["param2"] = 225, ["y"] = 6, ["z"] = 0, ["name"] = "bloc4builder:white"}, {["x"] = 9, ["param2"] = 225, ["y"] = 6, ["z"] = 10, ["name"] = "bloc4builder:white"}, {["x"] = 9, ["param2"] = 225, ["y"] = 7, ["z"] = 0, ["name"] = "bloc4builder:white"}, {["x"] = 9, ["param2"] = 225, ["y"] = 7, ["z"] = 10, ["name"] = "bloc4builder:white"}, {["x"] = 9, ["param2"] = 227, ["y"] = 8, ["param1"] = 78, ["z"] = 0, ["name"] = "bloc4builder:slope_white_half_raised"}, {["x"] = 9, ["param2"] = 227, ["y"] = 8, ["param1"] = 93, ["z"] = 1, ["name"] = "bloc4builder:slope_white_half_raised"}, {["x"] = 9, ["param2"] = 227, ["y"] = 8, ["param1"] = 110, ["z"] = 2, ["name"] = "bloc4builder:slope_white_half_raised"}, {["x"] = 9, ["param2"] = 227, ["y"] = 8, ["param1"] = 125, ["z"] = 3, ["name"] = "bloc4builder:slope_white_half_raised"}, {["x"] = 9, ["param2"] = 227, ["y"] = 8, ["param1"] = 126, ["z"] = 4, ["name"] = "bloc4builder:slope_white_half_raised"}, {["x"] = 9, ["param2"] = 227, ["y"] = 8, ["param1"] = 142, ["z"] = 5, ["name"] = "bloc4builder:slope_white_half_raised"}, {["x"] = 9, ["param2"] = 227, ["y"] = 8, ["param1"] = 126, ["z"] = 6, ["name"] = "bloc4builder:slope_white_half_raised"}, {["x"] = 9, ["param2"] = 227, ["y"] = 8, ["param1"] = 110, ["z"] = 7, ["name"] = "bloc4builder:slope_white_half_raised"}, {["x"] = 9, ["param2"] = 227, ["y"] = 8, ["param1"] = 126, ["z"] = 8, ["name"] = "bloc4builder:slope_white_half_raised"}, {["x"] = 9, ["param2"] = 227, ["y"] = 8, ["param1"] = 142, ["z"] = 9, ["name"] = "bloc4builder:slope_white_half_raised"}, {["x"] = 9, ["param2"] = 227, ["y"] = 8, ["param1"] = 126, ["z"] = 10, ["name"] = "bloc4builder:slope_white_half_raised"}, {["x"] = 10, ["param2"] = 103, ["y"] = 0, ["param1"] = 110, ["z"] = 0, ["name"] = "bloc4builder:mesh_white_fuse1"}, {["x"] = 10, ["param2"] = 103, ["y"] = 0, ["param1"] = 126, ["z"] = 1, ["name"] = "bloc4builder:mesh_white_fuse1"}, {["x"] = 10, ["param2"] = 103, ["y"] = 0, ["param1"] = 142, ["z"] = 2, ["name"] = "bloc4builder:mesh_white_fuse1"}, {["x"] = 10, ["param2"] = 103, ["y"] = 0, ["param1"] = 158, ["z"] = 3, ["name"] = "bloc4builder:mesh_white_fuse1"}, {["x"] = 10, ["param2"] = 103, ["y"] = 0, ["param1"] = 174, ["z"] = 4, ["name"] = "bloc4builder:mesh_white_fuse1"}, {["x"] = 10, ["param2"] = 103, ["y"] = 0, ["param1"] = 157, ["z"] = 5, ["name"] = "bloc4builder:mesh_white_fuse1"}, {["x"] = 10, ["param2"] = 103, ["y"] = 0, ["param1"] = 142, ["z"] = 6, ["name"] = "bloc4builder:mesh_white_fuse1"}, {["x"] = 10, ["param2"] = 103, ["y"] = 0, ["param1"] = 126, ["z"] = 7, ["name"] = "bloc4builder:mesh_white_fuse1"}, {["x"] = 10, ["param2"] = 103, ["y"] = 0, ["param1"] = 142, ["z"] = 8, ["name"] = "bloc4builder:mesh_white_fuse1"}, {["x"] = 10, ["param2"] = 103, ["y"] = 0, ["param1"] = 158, ["z"] = 9, ["name"] = "bloc4builder:mesh_white_fuse1"}, {["x"] = 10, ["param2"] = 103, ["y"] = 0, ["param1"] = 142, ["z"] = 10, ["name"] = "bloc4builder:mesh_white_fuse1"}, {["x"] = 10, ["param2"] = 239, ["y"] = 1, ["param1"] = 94, ["z"] = 0, ["name"] = "bloc4builder:slope_white_half_raised"}, {["x"] = 10, ["param2"] = 239, ["y"] = 1, ["param1"] = 110, ["z"] = 1, ["name"] = "bloc4builder:slope_white_half_raised"}, {["x"] = 10, ["param2"] = 239, ["y"] = 1, ["param1"] = 126, ["z"] = 2, ["name"] = "bloc4builder:slope_white_half_raised"}, {["x"] = 10, ["param2"] = 239, ["y"] = 1, ["param1"] = 142, ["z"] = 3, ["name"] = "bloc4builder:slope_white_half_raised"}, {["x"] = 10, ["param2"] = 239, ["y"] = 1, ["param1"] = 158, ["z"] = 4, ["name"] = "bloc4builder:slope_white_half_raised"}, {["x"] = 10, ["param2"] = 239, ["y"] = 1, ["param1"] = 173, ["z"] = 5, ["name"] = "bloc4builder:slope_white_half_raised"}, {["x"] = 10, ["param2"] = 239, ["y"] = 1, ["param1"] = 158, ["z"] = 6, ["name"] = "bloc4builder:slope_white_half_raised"}, {["x"] = 10, ["param2"] = 239, ["y"] = 1, ["param1"] = 142, ["z"] = 7, ["name"] = "bloc4builder:slope_white_half_raised"}, {["x"] = 10, ["param2"] = 239, ["y"] = 1, ["param1"] = 158, ["z"] = 8, ["name"] = "bloc4builder:slope_white_half_raised"}, {["x"] = 10, ["param2"] = 239, ["y"] = 1, ["param1"] = 174, ["z"] = 9, ["name"] = "bloc4builder:slope_white_half_raised"}, {["x"] = 10, ["param2"] = 239, ["y"] = 1, ["param1"] = 158, ["z"] = 10, ["name"] = "bloc4builder:slope_white_half_raised"}, {["x"] = 10, ["param2"] = 160, ["y"] = 2, ["param1"] = 78, ["z"] = 0, ["name"] = "bloc4builder:slope_white_inner_cut"}, {["x"] = 10, ["param2"] = 1, ["y"] = 2, ["z"] = 1, ["name"] = "bloc4builder:white"}, {["x"] = 10, ["param2"] = 1, ["y"] = 2, ["z"] = 2, ["name"] = "bloc4builder:white"}, {["x"] = 10, ["param2"] = 1, ["y"] = 2, ["z"] = 3, ["name"] = "bloc4builder:white"}, {["x"] = 10, ["param2"] = 1, ["y"] = 2, ["z"] = 4, ["name"] = "bloc4builder:white"}, {["x"] = 10, ["param2"] = 1, ["y"] = 2, ["z"] = 5, ["name"] = "bloc4builder:white"}, {["x"] = 10, ["param2"] = 1, ["y"] = 2, ["z"] = 6, ["name"] = "bloc4builder:white"}, {["x"] = 10, ["param2"] = 1, ["y"] = 2, ["z"] = 7, ["name"] = "bloc4builder:white"}, {["x"] = 10, ["param2"] = 1, ["y"] = 2, ["z"] = 8, ["name"] = "bloc4builder:white"}, {["x"] = 10, ["param2"] = 1, ["y"] = 2, ["z"] = 9, ["name"] = "bloc4builder:white"}, {["x"] = 10, ["param2"] = 163, ["y"] = 2, ["param1"] = 142, ["z"] = 10, ["name"] = "bloc4builder:slope_white_inner_cut"}, {["x"] = 10, ["param2"] = 172, ["y"] = 3, ["param1"] = 62, ["z"] = 0, ["name"] = "bloc4builder:slope_white"}, {["x"] = 10, ["param2"] = 1, ["y"] = 3, ["z"] = 1, ["name"] = "bloc4builder:white"}, {["x"] = 10, ["param2"] = 1, ["y"] = 3, ["z"] = 2, ["name"] = "bloc4builder:white"}, {["x"] = 10, ["param2"] = 1, ["y"] = 3, ["z"] = 3, ["name"] = "bloc4builder:white"}, {["x"] = 10, ["param2"] = 1, ["y"] = 3, ["z"] = 4, ["name"] = "bloc4builder:white"}, {["x"] = 10, ["param2"] = 1, ["y"] = 3, ["z"] = 5, ["name"] = "bloc4builder:white"}, {["x"] = 10, ["param2"] = 1, ["y"] = 3, ["z"] = 6, ["name"] = "bloc4builder:white"}, {["x"] = 10, ["param2"] = 1, ["y"] = 3, ["z"] = 7, ["name"] = "bloc4builder:white"}, {["x"] = 10, ["param2"] = 1, ["y"] = 3, ["z"] = 8, ["name"] = "bloc4builder:white"}, {["x"] = 10, ["param2"] = 1, ["y"] = 3, ["z"] = 9, ["name"] = "bloc4builder:white"}, {["x"] = 10, ["param2"] = 167, ["y"] = 3, ["param1"] = 126, ["z"] = 10, ["name"] = "bloc4builder:slope_white"}, {["x"] = 10, ["param2"] = 172, ["y"] = 4, ["param1"] = 46, ["z"] = 0, ["name"] = "bloc4builder:slope_white"}, {["x"] = 10, ["param2"] = 1, ["y"] = 4, ["z"] = 1, ["name"] = "bloc4builder:white"}, {["x"] = 10, ["param2"] = 1, ["y"] = 4, ["z"] = 2, ["name"] = "bloc4builder:white"}, {["x"] = 10, ["param2"] = 1, ["y"] = 4, ["z"] = 3, ["name"] = "bloc4builder:white"}, {["x"] = 10, ["param2"] = 1, ["y"] = 4, ["z"] = 4, ["name"] = "bloc4builder:white"}, {["x"] = 10, ["param2"] = 1, ["y"] = 4, ["z"] = 5, ["name"] = "bloc4builder:white"}, {["x"] = 10, ["param2"] = 1, ["y"] = 4, ["z"] = 6, ["name"] = "bloc4builder:white"}, {["x"] = 10, ["param2"] = 1, ["y"] = 4, ["z"] = 7, ["name"] = "bloc4builder:white"}, {["x"] = 10, ["param2"] = 1, ["y"] = 4, ["z"] = 8, ["name"] = "bloc4builder:white"}, {["x"] = 10, ["param2"] = 1, ["y"] = 4, ["z"] = 9, ["name"] = "bloc4builder:white"}, {["x"] = 10, ["param2"] = 167, ["y"] = 4, ["param1"] = 110, ["z"] = 10, ["name"] = "bloc4builder:slope_white"}, {["x"] = 10, ["param2"] = 172, ["y"] = 5, ["param1"] = 46, ["z"] = 0, ["name"] = "bloc4builder:slope_white"}, {["x"] = 10, ["param2"] = 1, ["y"] = 5, ["z"] = 1, ["name"] = "bloc4builder:white"}, {["x"] = 10, ["param2"] = 1, ["y"] = 5, ["z"] = 2, ["name"] = "bloc4builder:white"}, {["x"] = 10, ["param2"] = 1, ["y"] = 5, ["z"] = 3, ["name"] = "bloc4builder:white"}, {["x"] = 10, ["param2"] = 1, ["y"] = 5, ["z"] = 4, ["name"] = "bloc4builder:white"}, {["x"] = 10, ["param2"] = 1, ["y"] = 5, ["z"] = 5, ["name"] = "bloc4builder:white"}, {["x"] = 10, ["param2"] = 1, ["y"] = 5, ["z"] = 6, ["name"] = "bloc4builder:white"}, {["x"] = 10, ["param2"] = 1, ["y"] = 5, ["z"] = 7, ["name"] = "bloc4builder:white"}, {["x"] = 10, ["param2"] = 1, ["y"] = 5, ["z"] = 8, ["name"] = "bloc4builder:white"}, {["x"] = 10, ["param2"] = 1, ["y"] = 5, ["z"] = 9, ["name"] = "bloc4builder:white"}, {["x"] = 10, ["param2"] = 167, ["y"] = 5, ["param1"] = 94, ["z"] = 10, ["name"] = "bloc4builder:slope_white"}, {["x"] = 10, ["param2"] = 181, ["y"] = 6, ["param1"] = 62, ["z"] = 0, ["name"] = "bloc4builder:slope_white_inner_cut"}, {["x"] = 10, ["param2"] = 1, ["y"] = 6, ["z"] = 1, ["name"] = "bloc4builder:white"}, {["x"] = 10, ["param2"] = 1, ["y"] = 6, ["z"] = 2, ["name"] = "bloc4builder:white"}, {["x"] = 10, ["param2"] = 1, ["y"] = 6, ["z"] = 3, ["name"] = "bloc4builder:white"}, {["x"] = 10, ["param2"] = 1, ["y"] = 6, ["z"] = 4, ["name"] = "bloc4builder:white"}, {["x"] = 10, ["param2"] = 1, ["y"] = 6, ["z"] = 5, ["name"] = "bloc4builder:white"}, {["x"] = 10, ["param2"] = 1, ["y"] = 6, ["z"] = 6, ["name"] = "bloc4builder:white"}, {["x"] = 10, ["param2"] = 1, ["y"] = 6, ["z"] = 7, ["name"] = "bloc4builder:white"}, {["x"] = 10, ["param2"] = 1, ["y"] = 6, ["z"] = 8, ["name"] = "bloc4builder:white"}, {["x"] = 10, ["param2"] = 1, ["y"] = 6, ["z"] = 9, ["name"] = "bloc4builder:white"}, {["x"] = 10, ["param2"] = 182, ["y"] = 6, ["param1"] = 110, ["z"] = 10, ["name"] = "bloc4builder:slope_white_inner_cut"}, {["x"] = 10, ["param2"] = 237, ["y"] = 7, ["param1"] = 78, ["z"] = 0, ["name"] = "bloc4builder:slope_white_half_raised"}, {["x"] = 10, ["param2"] = 237, ["y"] = 7, ["param1"] = 94, ["z"] = 1, ["name"] = "bloc4builder:slope_white_half_raised"}, {["x"] = 10, ["param2"] = 237, ["y"] = 7, ["param1"] = 110, ["z"] = 2, ["name"] = "bloc4builder:slope_white_half_raised"}, {["x"] = 10, ["param2"] = 237, ["y"] = 7, ["param1"] = 126, ["z"] = 3, ["name"] = "bloc4builder:slope_white_half_raised"}, {["x"] = 10, ["param2"] = 237, ["y"] = 7, ["param1"] = 126, ["z"] = 4, ["name"] = "bloc4builder:slope_white_half_raised"}, {["x"] = 10, ["param2"] = 237, ["y"] = 7, ["param1"] = 141, ["z"] = 5, ["name"] = "bloc4builder:slope_white_half_raised"}, {["x"] = 10, ["param2"] = 237, ["y"] = 7, ["param1"] = 126, ["z"] = 6, ["name"] = "bloc4builder:slope_white_half_raised"}, {["x"] = 10, ["param2"] = 237, ["y"] = 7, ["param1"] = 110, ["z"] = 7, ["name"] = "bloc4builder:slope_white_half_raised"}, {["x"] = 10, ["param2"] = 237, ["y"] = 7, ["param1"] = 126, ["z"] = 8, ["name"] = "bloc4builder:slope_white_half_raised"}, {["x"] = 10, ["param2"] = 237, ["y"] = 7, ["param1"] = 142, ["z"] = 9, ["name"] = "bloc4builder:slope_white_half_raised"}, {["x"] = 10, ["param2"] = 237, ["y"] = 7, ["param1"] = 126, ["z"] = 10, ["name"] = "bloc4builder:slope_white_half_raised"}, {["x"] = 10, ["param2"] = 100, ["y"] = 8, ["param1"] = 62, ["z"] = 0, ["name"] = "bloc4builder:mesh_white_fuse1"}, {["x"] = 10, ["param2"] = 100, ["y"] = 8, ["param1"] = 78, ["z"] = 1, ["name"] = "bloc4builder:mesh_white_fuse1"}, {["x"] = 10, ["param2"] = 100, ["y"] = 8, ["param1"] = 94, ["z"] = 2, ["name"] = "bloc4builder:mesh_white_fuse1"}, {["x"] = 10, ["param2"] = 100, ["y"] = 8, ["param1"] = 110, ["z"] = 3, ["name"] = "bloc4builder:mesh_white_fuse1"}, {["x"] = 10, ["param2"] = 100, ["y"] = 8, ["param1"] = 110, ["z"] = 4, ["name"] = "bloc4builder:mesh_white_fuse1"}, {["x"] = 10, ["param2"] = 100, ["y"] = 8, ["param1"] = 126, ["z"] = 5, ["name"] = "bloc4builder:mesh_white_fuse1"}, {["x"] = 10, ["param2"] = 100, ["y"] = 8, ["param1"] = 110, ["z"] = 6, ["name"] = "bloc4builder:mesh_white_fuse1"}, {["x"] = 10, ["param2"] = 100, ["y"] = 8, ["param1"] = 94, ["z"] = 7, ["name"] = "bloc4builder:mesh_white_fuse1"}, {["x"] = 10, ["param2"] = 100, ["y"] = 8, ["param1"] = 110, ["z"] = 8, ["name"] = "bloc4builder:mesh_white_fuse1"}, {["x"] = 10, ["param2"] = 100, ["y"] = 8, ["param1"] = 126, ["z"] = 9, ["name"] = "bloc4builder:mesh_white_fuse1"}, {["x"] = 10, ["param2"] = 100, ["y"] = 8, ["param1"] = 110, ["z"] = 10, ["name"] = "bloc4builder:mesh_white_fuse1"}}