5:return {{["x"] = 0, ["param2"] = 41, ["y"] = 5, ["param1"] = 110, ["z"] = 0, ["name"] = "bloc4builder:slope_rainbow"}, {["x"] = 0, ["param2"] = 32, ["y"] = 5, ["z"] = 1, ["name"] = "bloc4builder:rainbow"}, {["x"] = 0, ["param2"] = 32, ["y"] = 5, ["z"] = 2, ["name"] = "bloc4builder:rainbow"}, {["x"] = 0, ["param2"] = 32, ["y"] = 5, ["z"] = 3, ["name"] = "bloc4builder:rainbow"}, {["x"] = 0, ["param2"] = 32, ["y"] = 5, ["z"] = 4, ["name"] = "bloc4builder:rainbow"}, {["x"] = 0, ["param2"] = 3, ["y"] = 5, ["param1"] = 142, ["z"] = 5, ["name"] = "bloc4builder:hub"}, {["x"] = 0, ["param2"] = 32, ["y"] = 5, ["z"] = 6, ["name"] = "bloc4builder:rainbow"}, {["x"] = 0, ["param2"] = 50, ["y"] = 5, ["param1"] = 158, ["z"] = 7, ["name"] = "bloc4builder:slope_rainbow_half_raised"}, {["x"] = 0, ["param2"] = 50, ["y"] = 5, ["param1"] = 174, ["z"] = 8, ["name"] = "bloc4builder:slope_rainbow_half"}, {["x"] = 0, ["param2"] = 233, ["y"] = 6, ["param1"] = 126, ["z"] = 0, ["name"] = "bloc4builder:slope_rainbow"}, {["x"] = 0, ["param2"] = 35, ["y"] = 6, ["z"] = 1, ["name"] = "bloc4builder:rainbow"}, {["x"] = 0, ["param2"] = 35, ["y"] = 6, ["z"] = 2, ["name"] = "bloc4builder:rainbow"}, {["x"] = 0, ["param2"] = 32, ["y"] = 6, ["z"] = 3, ["name"] = "bloc4builder:rainbow"}, {["x"] = 0, ["param2"] = 32, ["y"] = 6, ["z"] = 4, ["name"] = "bloc4builder:rainbow"}, {["x"] = 0, ["param2"] = 3, ["y"] = 6, ["param1"] = 158, ["z"] = 5, ["name"] = "bloc4builder:door"}, {["x"] = 0, ["param2"] = 35, ["y"] = 6, ["z"] = 6, ["name"] = "bloc4builder:rainbow"}, {["x"] = 0, ["param2"] = 50, ["y"] = 6, ["param1"] = 174, ["z"] = 7, ["name"] = "bloc4builder:slope_rainbow_half_raised"}, {["x"] = 0, ["param2"] = 50, ["y"] = 6, ["param1"] = 190, ["z"] = 8, ["name"] = "bloc4builder:slope_rainbow_half"}, {["x"] = 0, ["param2"] = 233, ["y"] = 7, ["param1"] = 142, ["z"] = 0, ["name"] = "bloc4builder:slope_rainbow"}, {["x"] = 0, ["param2"] = 35, ["y"] = 7, ["z"] = 1, ["name"] = "bloc4builder:rainbow"}, {["x"] = 0, ["y"] = 7, ["param1"] = 174, ["z"] = 2, ["name"] = "bloc4builder:building_glass"}, {["x"] = 0, ["y"] = 7, ["param1"] = 158, ["z"] = 3, ["name"] = "bloc4builder:building_glass"}, {["x"] = 0, ["param2"] = 35, ["y"] = 7, ["z"] = 4, ["name"] = "bloc4builder:rainbow"}, {["x"] = 0, ["param2"] = 35, ["y"] = 7, ["z"] = 6, ["name"] = "bloc4builder:rainbow"}, {["x"] = 0, ["param2"] = 50, ["y"] = 7, ["param1"] = 174, ["z"] = 7, ["name"] = "bloc4builder:slope_rainbow_half_raised"}, {["x"] = 0, ["param2"] = 50, ["y"] = 7, ["param1"] = 190, ["z"] = 8, ["name"] = "bloc4builder:slope_rainbow_half"}, {["x"] = 0, ["param2"] = 41, ["y"] = 8, ["param1"] = 158, ["z"] = 0, ["name"] = "bloc4builder:slope_rainbow"}, {["x"] = 0, ["param2"] = 35, ["y"] = 8, ["z"] = 1, ["name"] = "bloc4builder:rainbow"}, {["x"] = 0, ["param2"] = 35, ["y"] = 8, ["z"] = 2, ["name"] = "bloc4builder:rainbow"}, {["x"] = 0, ["param2"] = 32, ["y"] = 8, ["z"] = 3, ["name"] = "bloc4builder:rainbow"}, {["x"] = 0, ["param2"] = 32, ["y"] = 8, ["z"] = 4, ["name"] = "bloc4builder:rainbow"}, {["x"] = 0, ["param2"] = 32, ["y"] = 8, ["z"] = 5, ["name"] = "bloc4builder:rainbow"}, {["x"] = 0, ["param2"] = 35, ["y"] = 8, ["z"] = 6, ["name"] = "bloc4builder:rainbow"}, {["x"] = 0, ["param2"] = 50, ["y"] = 8, ["param1"] = 158, ["z"] = 7, ["name"] = "bloc4builder:slope_rainbow_half_raised"}, {["x"] = 0, ["param2"] = 50, ["y"] = 8, ["param1"] = 174, ["z"] = 8, ["name"] = "bloc4builder:slope_rainbow_half"}, {["x"] = 1, ["param2"] = 35, ["y"] = 5, ["z"] = 0, ["name"] = "bloc4builder:rainbow"}, {["x"] = 1, ["param2"] = 35, ["y"] = 5, ["z"] = 1, ["name"] = "bloc4builder:rainbow"}, {["x"] = 1, ["param2"] = 35, ["y"] = 5, ["z"] = 2, ["name"] = "bloc4builder:rainbow"}, {["x"] = 1, ["param2"] = 35, ["y"] = 5, ["z"] = 3, ["name"] = "bloc4builder:rainbow"}, {["x"] = 1, ["param2"] = 35, ["y"] = 5, ["z"] = 4, ["name"] = "bloc4builder:rainbow"}, {["x"] = 1, ["param2"] = 35, ["y"] = 5, ["z"] = 5, ["name"] = "bloc4builder:rainbow"}, {["x"] = 1, ["param2"] = 35, ["y"] = 5, ["z"] = 6, ["name"] = "bloc4builder:rainbow"}, {["x"] = 1, ["param2"] = 33, ["y"] = 5, ["z"] = 7, ["name"] = "bloc4builder:rainbow"}, {["x"] = 1, ["param2"] = 33, ["y"] = 5, ["z"] = 8, ["name"] = "bloc4builder:rainbow"}, {["x"] = 1, ["param2"] = 50, ["y"] = 5, ["param1"] = 206, ["z"] = 9, ["name"] = "bloc4builder:slope_rainbow"}, {["x"] = 1, ["param2"] = 224, ["y"] = 6, ["z"] = 0, ["name"] = "bloc4builder:rainbow"}, {["x"] = 1, ["meta"] = {["fields"] = {["infotext"] = "Container 500Kg", ["channel"] = "linxx:singleplayer", ["spacengine"] = "^A¨100¨0¨500", ["pos_cont"] = "(-8,-1,0)"}, ["inventory"] = {}}, ["y"] = 6, ["z"] = 7, ["name"] = "spacengine:container"}, {["x"] = 1, ["param2"] = 227, ["y"] = 6, ["z"] = 8, ["name"] = "bloc4builder:rainbow"}, {["x"] = 1, ["param2"] = 18, ["y"] = 6, ["param1"] = 222, ["z"] = 9, ["name"] = "moreblocks:slope_meselamp"}, {["x"] = 1, ["param2"] = 227, ["y"] = 7, ["z"] = 0, ["name"] = "bloc4builder:rainbow"}, {["x"] = 1, ["meta"] = {["fields"] = {["owner"] = "singleplayer", ["channel"] = "linxx"}, ["inventory"] = {}}, ["param2"] = 3, ["y"] = 7, ["param1"] = 204, ["z"] = 6, ["name"] = "bloc4builder:keypad"}, {["x"] = 1, ["meta"] = {["fields"] = {["infotext"] = "Container 500Kg", ["channel"] = "linxx:singleplayer", ["spacengine"] = "^A¨100¨0¨500", ["pos_cont"] = "(-8,0,0)"}, ["inventory"] = {}}, ["y"] = 7, ["z"] = 7, ["name"] = "spacengine:container"}, {["x"] = 1, ["param2"] = 227, ["y"] = 7, ["z"] = 8, ["name"] = "bloc4builder:rainbow"}, {["x"] = 1, ["param2"] = 18, ["y"] = 7, ["param1"] = 222, ["z"] = 9, ["name"] = "moreblocks:slope_meselamp"}, {["x"] = 1, ["param2"] = 35, ["y"] = 8, ["z"] = 0, ["name"] = "bloc4builder:rainbow"}, {["x"] = 1, ["param2"] = 7, ["y"] = 8, ["param1"] = 221, ["z"] = 1, ["name"] = "bloc4builder:light_on"}, {["x"] = 1, ["param2"] = 9, ["y"] = 8, ["param1"] = 221, ["z"] = 6, ["name"] = "bloc4builder:light_on"}, {["x"] = 1, ["param2"] = 34, ["y"] = 8, ["z"] = 7, ["name"] = "bloc4builder:rainbow"}, {["x"] = 1, ["param2"] = 35, ["y"] = 8, ["z"] = 8, ["name"] = "bloc4builder:rainbow"}, {["x"] = 1, ["param2"] = 50, ["y"] = 8, ["param1"] = 206, ["z"] = 9, ["name"] = "bloc4builder:slope_rainbow"}, {["x"] = 1, ["param2"] = 34, ["y"] = 9, ["param1"] = 206, ["z"] = 1, ["name"] = "bloc4builder:slab_rainbow_1"}, {["x"] = 1, ["param2"] = 35, ["y"] = 9, ["param1"] = 190, ["z"] = 2, ["name"] = "bloc4builder:slab_rainbow_1"}, {["x"] = 1, ["param2"] = 35, ["y"] = 9, ["param1"] = 174, ["z"] = 3, ["name"] = "bloc4builder:slab_rainbow_1"}, {["x"] = 1, ["param2"] = 35, ["y"] = 9, ["param1"] = 174, ["z"] = 4, ["name"] = "bloc4builder:slab_rainbow_1"}, {["x"] = 1, ["param2"] = 32, ["y"] = 9, ["param1"] = 190, ["z"] = 5, ["name"] = "bloc4builder:slab_rainbow_1"}, {["x"] = 1, ["param2"] = 32, ["y"] = 9, ["param1"] = 206, ["z"] = 6, ["name"] = "bloc4builder:slab_rainbow_1"}, {["x"] = 2, ["param2"] = 247, ["y"] = 4, ["param1"] = 93, ["z"] = 0, ["name"] = "bloc4builder:slope_rainbow_half"}, {["x"] = 2, ["param2"] = 247, ["y"] = 4, ["param1"] = 108, ["z"] = 1, ["name"] = "bloc4builder:slope_rainbow_half"}, {["x"] = 2, ["param2"] = 247, ["y"] = 4, ["param1"] = 108, ["z"] = 2, ["name"] = "bloc4builder:slope_rainbow_half"}, {["x"] = 2, ["param2"] = 247, ["y"] = 4, ["param1"] = 124, ["z"] = 3, ["name"] = "bloc4builder:slope_rainbow_half"}, {["x"] = 2, ["param2"] = 247, ["y"] = 4, ["param1"] = 124, ["z"] = 4, ["name"] = "bloc4builder:slope_rainbow_half"}, {["x"] = 2, ["param2"] = 247, ["y"] = 4, ["param1"] = 108, ["z"] = 5, ["name"] = "bloc4builder:slope_rainbow_half"}, {["x"] = 2, ["param2"] = 247, ["y"] = 4, ["param1"] = 124, ["z"] = 6, ["name"] = "bloc4builder:slope_rainbow_half"}, {["x"] = 2, ["param2"] = 247, ["y"] = 4, ["param1"] = 140, ["z"] = 7, ["name"] = "bloc4builder:slope_rainbow_half"}, {["x"] = 2, ["param2"] = 247, ["y"] = 4, ["param1"] = 156, ["z"] = 8, ["name"] = "bloc4builder:slope_rainbow_half"}, {["x"] = 2, ["param2"] = 247, ["y"] = 4, ["param1"] = 173, ["z"] = 9, ["name"] = "bloc4builder:slope_rainbow_half"}, {["x"] = 2, ["param2"] = 35, ["y"] = 5, ["z"] = 0, ["name"] = "bloc4builder:rainbow"}, {["x"] = 2, ["param2"] = 35, ["y"] = 5, ["z"] = 1, ["name"] = "bloc4builder:rainbow"}, {["x"] = 2, ["param2"] = 35, ["y"] = 5, ["z"] = 2, ["name"] = "bloc4builder:rainbow"}, {["x"] = 2, ["param2"] = 35, ["y"] = 5, ["z"] = 3, ["name"] = "bloc4builder:rainbow"}, {["x"] = 2, ["param2"] = 35, ["y"] = 5, ["z"] = 4, ["name"] = "bloc4builder:rainbow"}, {["x"] = 2, ["param2"] = 35, ["y"] = 5, ["z"] = 5, ["name"] = "bloc4builder:rainbow"}, {["x"] = 2, ["param2"] = 35, ["y"] = 5, ["z"] = 6, ["name"] = "bloc4builder:rainbow"}, {["x"] = 2, ["param2"] = 3, ["y"] = 5, ["z"] = 7, ["name"] = "bloc4builder:rainbow"}, {["x"] = 2, ["param2"] = 3, ["y"] = 5, ["z"] = 8, ["name"] = "bloc4builder:rainbow"}, {["x"] = 2, ["param2"] = 1, ["y"] = 5, ["z"] = 9, ["name"] = "bloc4builder:rainbow"}, {["x"] = 2, ["param2"] = 37, ["y"] = 5, ["param1"] = 174, ["z"] = 10, ["name"] = "bloc4builder:slope_rainbow"}, {["x"] = 2, ["param2"] = 226, ["y"] = 6, ["z"] = 0, ["name"] = "bloc4builder:rainbow"}, {["x"] = 2, ["param2"] = 231, ["y"] = 6, ["param1"] = 188, ["z"] = 8, ["name"] = "bloc4builder:slab_rainbow_1"}, {["x"] = 2, ["param2"] = 50, ["y"] = 6, ["param1"] = 190, ["z"] = 10, ["name"] = "bloc4builder:slope_rainbow"}, {["x"] = 2, ["param2"] = 224, ["y"] = 7, ["z"] = 0, ["name"] = "bloc4builder:rainbow"}, {["x"] = 2, ["param2"] = 231, ["y"] = 7, ["param1"] = 188, ["z"] = 8, ["name"] = "bloc4builder:slab_rainbow_1"}, {["x"] = 2, ["param2"] = 50, ["y"] = 7, ["param1"] = 190, ["z"] = 10, ["name"] = "bloc4builder:slope_rainbow"}, {["x"] = 2, ["param2"] = 32, ["y"] = 8, ["z"] = 0, ["name"] = "bloc4builder:rainbow"}, {["x"] = 2, ["param2"] = 35, ["y"] = 8, ["z"] = 7, ["name"] = "bloc4builder:rainbow"}, {["x"] = 2, ["param2"] = 35, ["y"] = 8, ["z"] = 8, ["name"] = "bloc4builder:rainbow"}, {["x"] = 2, ["param2"] = 35, ["y"] = 8, ["z"] = 9, ["name"] = "bloc4builder:rainbow"}, {["x"] = 2, ["param2"] = 50, ["y"] = 8, ["param1"] = 174, ["z"] = 10, ["name"] = "bloc4builder:slope_rainbow"}, {["x"] = 2, ["param2"] = 34, ["y"] = 9, ["param1"] = 190, ["z"] = 1, ["name"] = "bloc4builder:slab_rainbow_1"}, {["x"] = 2, ["param2"] = 35, ["y"] = 9, ["param1"] = 174, ["z"] = 2, ["name"] = "bloc4builder:slab_rainbow_1"}, {["x"] = 2, ["param2"] = 35, ["y"] = 9, ["param1"] = 174, ["z"] = 3, ["name"] = "bloc4builder:slab_rainbow_1"}, {["x"] = 2, ["param2"] = 32, ["y"] = 9, ["param1"] = 174, ["z"] = 4, ["name"] = "bloc4builder:slab_rainbow_1"}, {["x"] = 2, ["param2"] = 32, ["y"] = 9, ["param1"] = 174, ["z"] = 5, ["name"] = "bloc4builder:slab_rainbow_1"}, {["x"] = 2, ["param2"] = 32, ["y"] = 9, ["param1"] = 190, ["z"] = 6, ["name"] = "bloc4builder:slab_rainbow_1"}, {["x"] = 3, ["param2"] = 247, ["y"] = 4, ["param1"] = 110, ["z"] = 0, ["name"] = "bloc4builder:slope_rainbow_half_raised"}, {["x"] = 3, ["param2"] = 247, ["y"] = 4, ["param1"] = 125, ["z"] = 1, ["name"] = "bloc4builder:slope_rainbow_half_raised"}, {["x"] = 3, ["param2"] = 247, ["y"] = 4, ["param1"] = 124, ["z"] = 2, ["name"] = "bloc4builder:slope_rainbow_half_raised"}, {["x"] = 3, ["param2"] = 247, ["y"] = 4, ["param1"] = 139, ["z"] = 3, ["name"] = "bloc4builder:slope_rainbow_half_raised"}, {["x"] = 3, ["param2"] = 247, ["y"] = 4, ["param1"] = 139, ["z"] = 4, ["name"] = "bloc4builder:slope_rainbow_half_raised"}, {["x"] = 3, ["param2"] = 247, ["y"] = 4, ["param1"] = 123, ["z"] = 5, ["name"] = "bloc4builder:slope_rainbow_half_raised"}, {["x"] = 3, ["param2"] = 247, ["y"] = 4, ["param1"] = 123, ["z"] = 6, ["name"] = "bloc4builder:slope_rainbow_half_raised"}, {["x"] = 3, ["param2"] = 247, ["y"] = 4, ["param1"] = 123, ["z"] = 7, ["name"] = "bloc4builder:slope_rainbow_half_raised"}, {["x"] = 3, ["param2"] = 247, ["y"] = 4, ["param1"] = 139, ["z"] = 8, ["name"] = "bloc4builder:slope_rainbow_half_raised"}, {["x"] = 3, ["param2"] = 247, ["y"] = 4, ["param1"] = 156, ["z"] = 9, ["name"] = "bloc4builder:slope_rainbow_half_raised"}, {["x"] = 3, ["param2"] = 35, ["y"] = 5, ["z"] = 0, ["name"] = "bloc4builder:rainbow"}, {["x"] = 3, ["param2"] = 227, ["y"] = 5, ["param1"] = 140, ["z"] = 1, ["name"] = "bloc4builder:stair_rainbow_alt_1"}, {["x"] = 3, ["param2"] = 22, ["y"] = 5, ["param1"] = 139, ["z"] = 2, ["name"] = "bloc4builder:slab_rainbow_two_sides"}, {["x"] = 3, ["param2"] = 21, ["y"] = 5, ["param1"] = 154, ["z"] = 3, ["name"] = "bloc4builder:slab_rainbow_1"}, {["x"] = 3, ["param2"] = 21, ["y"] = 5, ["param1"] = 154, ["z"] = 4, ["name"] = "bloc4builder:slab_rainbow_1"}, {["x"] = 3, ["param2"] = 21, ["y"] = 5, ["param1"] = 138, ["z"] = 5, ["name"] = "bloc4builder:slab_rainbow_1"}, {["x"] = 3, ["param2"] = 21, ["y"] = 5, ["param1"] = 138, ["z"] = 6, ["name"] = "bloc4builder:slab_rainbow_1"}, {["x"] = 3, ["param2"] = 21, ["y"] = 5, ["param1"] = 138, ["z"] = 7, ["name"] = "bloc4builder:slab_rainbow_1"}, {["x"] = 3, ["param2"] = 3, ["y"] = 5, ["z"] = 8, ["name"] = "bloc4builder:rainbow"}, {["x"] = 3, ["param2"] = 1, ["y"] = 5, ["z"] = 9, ["name"] = "bloc4builder:rainbow"}, {["x"] = 3, ["param2"] = 34, ["y"] = 5, ["z"] = 10, ["name"] = "bloc4builder:rainbow"}, {["x"] = 3, ["param2"] = 37, ["y"] = 5, ["param1"] = 141, ["z"] = 11, ["name"] = "bloc4builder:slope_rainbow_half"}, {["x"] = 3, ["param2"] = 224, ["y"] = 6, ["z"] = 0, ["name"] = "bloc4builder:rainbow"}, {["x"] = 3, ["param2"] = 7, ["y"] = 6, ["param1"] = 155, ["z"] = 2, ["name"] = "bloc4builder:slab_rainbow_two_sides"}, {["x"] = 3, ["param2"] = 12, ["y"] = 6, ["param1"] = 171, ["z"] = 3, ["name"] = "bloc4builder:slab_rainbow_1"}, {["x"] = 3, ["param2"] = 12, ["y"] = 6, ["param1"] = 171, ["z"] = 4, ["name"] = "bloc4builder:slab_rainbow_1"}, {["x"] = 3, ["param2"] = 12, ["y"] = 6, ["param1"] = 155, ["z"] = 5, ["name"] = "bloc4builder:slab_rainbow_two_sides"}, {["x"] = 3, ["param2"] = 231, ["y"] = 6, ["param1"] = 171, ["z"] = 8, ["name"] = "bloc4builder:slab_rainbow_1"}, {["x"] = 3, ["param2"] = 37, ["y"] = 6, ["param1"] = 157, ["z"] = 11, ["name"] = "bloc4builder:slope_rainbow_half"}, {["x"] = 3, ["param2"] = 224, ["y"] = 7, ["z"] = 0, ["name"] = "bloc4builder:rainbow"}, {["x"] = 3, ["param2"] = 7, ["y"] = 7, ["param1"] = 172, ["z"] = 2, ["name"] = "bloc4builder:slab_rainbow_two_sides"}, {["x"] = 3, ["param2"] = 12, ["y"] = 7, ["param1"] = 188, ["z"] = 3, ["name"] = "bloc4builder:slab_rainbow_1"}, {["x"] = 3, ["param2"] = 12, ["y"] = 7, ["param1"] = 188, ["z"] = 4, ["name"] = "bloc4builder:slab_rainbow_1"}, {["x"] = 3, ["param2"] = 12, ["y"] = 7, ["param1"] = 172, ["z"] = 5, ["name"] = "bloc4builder:slab_rainbow_two_sides"}, {["x"] = 3, ["param2"] = 231, ["y"] = 7, ["param1"] = 171, ["z"] = 8, ["name"] = "bloc4builder:slab_rainbow_1"}, {["x"] = 3, ["param2"] = 37, ["y"] = 7, ["param1"] = 157, ["z"] = 11, ["name"] = "bloc4builder:slope_rainbow_half"}, {["x"] = 3, ["param2"] = 32, ["y"] = 8, ["z"] = 0, ["name"] = "bloc4builder:rainbow"}, {["x"] = 3, ["param2"] = 7, ["y"] = 8, ["param1"] = 189, ["z"] = 2, ["name"] = "bloc4builder:slab_rainbow_two_sides"}, {["x"] = 3, ["param2"] = 12, ["y"] = 8, ["param1"] = 205, ["z"] = 3, ["name"] = "bloc4builder:slab_rainbow_1"}, {["x"] = 3, ["param2"] = 12, ["y"] = 8, ["param1"] = 205, ["z"] = 4, ["name"] = "bloc4builder:slab_rainbow_1"}, {["x"] = 3, ["param2"] = 12, ["y"] = 8, ["param1"] = 189, ["z"] = 5, ["name"] = "bloc4builder:slab_rainbow_two_sides"}, {["x"] = 3, ["param2"] = 35, ["y"] = 8, ["z"] = 7, ["name"] = "bloc4builder:rainbow"}, {["x"] = 3, ["param2"] = 35, ["y"] = 8, ["z"] = 8, ["name"] = "bloc4builder:rainbow"}, {["x"] = 3, ["param2"] = 35, ["y"] = 8, ["z"] = 9, ["name"] = "bloc4builder:rainbow"}, {["x"] = 3, ["param2"] = 32, ["y"] = 8, ["z"] = 10, ["name"] = "bloc4builder:rainbow"}, {["x"] = 3, ["param2"] = 37, ["y"] = 8, ["param1"] = 142, ["z"] = 11, ["name"] = "bloc4builder:slope_rainbow_half"}, {["x"] = 3, ["param2"] = 33, ["y"] = 9, ["param1"] = 158, ["z"] = 0, ["name"] = "bloc4builder:slope_rainbow_half"}, {["x"] = 3, ["param2"] = 33, ["y"] = 9, ["param1"] = 174, ["z"] = 1, ["name"] = "bloc4builder:slope_rainbow_half"}, {["x"] = 3, ["param2"] = 33, ["y"] = 9, ["param1"] = 174, ["z"] = 2, ["name"] = "bloc4builder:slope_rainbow_half"}, {["x"] = 3, ["param2"] = 33, ["y"] = 9, ["param1"] = 190, ["z"] = 3, ["name"] = "bloc4builder:slope_rainbow_half"}, {["x"] = 3, ["param2"] = 33, ["y"] = 9, ["param1"] = 190, ["z"] = 4, ["name"] = "bloc4builder:slope_rainbow_half"}, {["x"] = 3, ["param2"] = 33, ["y"] = 9, ["param1"] = 174, ["z"] = 5, ["name"] = "bloc4builder:slope_rainbow_half"}, {["x"] = 3, ["param2"] = 33, ["y"] = 9, ["param1"] = 174, ["z"] = 6, ["name"] = "bloc4builder:slope_rainbow_half"}, {["x"] = 3, ["meta"] = {["fields"] = {["infotext"] = "LASER", ["channel"] = "linxx:singleplayer", ["spacengine"] = "^A¨100¨0¨750¨20¨5¨2", ["pos_cont"] = "(-6,2,1)"}, ["inventory"] = {}}, ["param2"] = 2, ["y"] = 9, ["param1"] = 142, ["z"] = 8, ["name"] = "spacengine:weapons"}, {["x"] = 4, ["param2"] = 215, ["y"] = 3, ["param1"] = 141, ["z"] = 0, ["name"] = "bloc4builder:slope_rainbow_half"}, {["x"] = 4, ["param2"] = 215, ["y"] = 3, ["param1"] = 124, ["z"] = 1, ["name"] = "bloc4builder:slope_rainbow_half"}, {["x"] = 4, ["param2"] = 215, ["y"] = 3, ["param1"] = 107, ["z"] = 2, ["name"] = "bloc4builder:slope_rainbow_half"}, {["x"] = 4, ["param2"] = 215, ["y"] = 3, ["param1"] = 106, ["z"] = 3, ["name"] = "bloc4builder:slope_rainbow_half"}, {["x"] = 4, ["param2"] = 215, ["y"] = 3, ["param1"] = 106, ["z"] = 4, ["name"] = "bloc4builder:slope_rainbow_half"}, {["x"] = 4, ["param2"] = 215, ["y"] = 3, ["param1"] = 106, ["z"] = 5, ["name"] = "bloc4builder:slope_rainbow_half"}, {["x"] = 4, ["param2"] = 215, ["y"] = 3, ["param1"] = 122, ["z"] = 6, ["name"] = "bloc4builder:slope_rainbow_half"}, {["x"] = 4, ["param2"] = 215, ["y"] = 3, ["param1"] = 138, ["z"] = 7, ["name"] = "bloc4builder:slope_rainbow_half"}, {["x"] = 4, ["param2"] = 215, ["y"] = 3, ["param1"] = 155, ["z"] = 8, ["name"] = "bloc4builder:slope_rainbow_half"}, {["x"] = 4, ["param2"] = 215, ["y"] = 3, ["param1"] = 140, ["z"] = 9, ["name"] = "bloc4builder:slope_rainbow_half"}, {["x"] = 4, ["param2"] = 225, ["y"] = 4, ["z"] = 0, ["name"] = "bloc4builder:rainbow"}, {["x"] = 4, ["param2"] = 226, ["y"] = 4, ["z"] = 1, ["name"] = "bloc4builder:rainbow"}, {["x"] = 4, ["param2"] = 2, ["y"] = 4, ["z"] = 2, ["name"] = "bloc4builder:rainbow"}, {["x"] = 4, ["param2"] = 1, ["y"] = 4, ["z"] = 3, ["name"] = "bloc4builder:rainbow"}, {["x"] = 4, ["y"] = 4, ["z"] = 4, ["name"] = "bloc4builder:rainbow"}, {["x"] = 4, ["y"] = 4, ["z"] = 5, ["name"] = "bloc4builder:rainbow"}, {["x"] = 4, ["y"] = 4, ["z"] = 6, ["name"] = "bloc4builder:rainbow"}, {["x"] = 4, ["y"] = 4, ["z"] = 7, ["name"] = "bloc4builder:rainbow"}, {["x"] = 4, ["param2"] = 2, ["y"] = 4, ["z"] = 8, ["name"] = "bloc4builder:rainbow"}, {["x"] = 4, ["param2"] = 225, ["y"] = 4, ["z"] = 9, ["name"] = "bloc4builder:rainbow"}, {["x"] = 4, ["param2"] = 35, ["y"] = 5, ["z"] = 0, ["name"] = "bloc4builder:rainbow"}, {["x"] = 4, ["param2"] = 22, ["y"] = 5, ["param1"] = 154, ["z"] = 2, ["name"] = "bloc4builder:slab_rainbow_two_sides"}, {["x"] = 4, ["param2"] = 21, ["y"] = 5, ["param1"] = 170, ["z"] = 3, ["name"] = "bloc4builder:slab_rainbow_1"}, {["x"] = 4, ["param2"] = 21, ["y"] = 5, ["param1"] = 170, ["z"] = 4, ["name"] = "bloc4builder:slab_rainbow_1"}, {["x"] = 4, ["param2"] = 21, ["y"] = 5, ["param1"] = 154, ["z"] = 5, ["name"] = "bloc4builder:slab_rainbow_1"}, {["x"] = 4, ["param2"] = 21, ["y"] = 5, ["param1"] = 138, ["z"] = 6, ["name"] = "bloc4builder:slab_rainbow_1"}, {["x"] = 4, ["param2"] = 21, ["y"] = 5, ["param1"] = 121, ["z"] = 7, ["name"] = "bloc4builder:slab_rainbow_1"}, {["x"] = 4, ["param2"] = 3, ["y"] = 5, ["z"] = 8, ["name"] = "bloc4builder:rainbow"}, {["x"] = 4, ["y"] = 5, ["z"] = 9, ["name"] = "bloc4builder:rainbow"}, {["x"] = 4, ["param2"] = 33, ["y"] = 5, ["z"] = 10, ["name"] = "bloc4builder:rainbow"}, {["x"] = 4, ["param2"] = 37, ["y"] = 5, ["param1"] = 126, ["z"] = 11, ["name"] = "bloc4builder:slope_rainbow_half_raised"}, {["x"] = 4, ["param2"] = 225, ["y"] = 6, ["z"] = 0, ["name"] = "bloc4builder:rainbow"}, {["x"] = 4, ["param2"] = 7, ["y"] = 6, ["param1"] = 171, ["z"] = 2, ["name"] = "bloc4builder:slab_rainbow_1"}, {["x"] = 4, ["param2"] = 226, ["y"] = 6, ["z"] = 7, ["name"] = "bloc4builder:rainbow"}, {["x"] = 4, ["param2"] = 231, ["y"] = 6, ["param1"] = 155, ["z"] = 8, ["name"] = "bloc4builder:slab_rainbow_1"}, {["x"] = 4, ["param2"] = 37, ["y"] = 6, ["param1"] = 142, ["z"] = 11, ["name"] = "bloc4builder:slope_rainbow_half_raised"}, {["x"] = 4, ["param2"] = 224, ["y"] = 7, ["z"] = 0, ["name"] = "bloc4builder:rainbow"}, {["x"] = 4, ["param2"] = 7, ["y"] = 7, ["param1"] = 188, ["z"] = 2, ["name"] = "bloc4builder:slab_rainbow_1"}, {["x"] = 4, ["param2"] = 226, ["y"] = 7, ["z"] = 7, ["name"] = "bloc4builder:rainbow"}, {["x"] = 4, ["param2"] = 231, ["y"] = 7, ["param1"] = 155, ["z"] = 8, ["name"] = "bloc4builder:slab_rainbow_1"}, {["x"] = 4, ["param2"] = 37, ["y"] = 7, ["param1"] = 142, ["z"] = 11, ["name"] = "bloc4builder:slope_rainbow_half_raised"}, {["x"] = 4, ["param2"] = 32, ["y"] = 8, ["z"] = 0, ["name"] = "bloc4builder:rainbow"}, {["x"] = 4, ["param2"] = 7, ["y"] = 8, ["param1"] = 205, ["z"] = 2, ["name"] = "bloc4builder:slab_rainbow_1"}, {["x"] = 4, ["param2"] = 22, ["y"] = 8, ["param1"] = 221, ["z"] = 3, ["name"] = "bloc4builder:light_on"}, {["x"] = 4, ["param2"] = 22, ["y"] = 8, ["param1"] = 221, ["z"] = 4, ["name"] = "bloc4builder:light_on"}, {["x"] = 4, ["param2"] = 9, ["y"] = 8, ["param1"] = 205, ["z"] = 5, ["name"] = "bloc4builder:slab_rainbow_1"}, {["x"] = 4, ["param2"] = 35, ["y"] = 8, ["z"] = 7, ["name"] = "bloc4builder:rainbow"}, {["x"] = 4, ["param2"] = 35, ["y"] = 8, ["z"] = 8, ["name"] = "bloc4builder:rainbow"}, {["x"] = 4, ["param2"] = 35, ["y"] = 8, ["z"] = 9, ["name"] = "bloc4builder:rainbow"}, {["x"] = 4, ["param2"] = 32, ["y"] = 8, ["z"] = 10, ["name"] = "bloc4builder:rainbow"}, {["x"] = 4, ["param2"] = 37, ["y"] = 8, ["param1"] = 126, ["z"] = 11, ["name"] = "bloc4builder:slope_rainbow_half_raised"}, {["x"] = 4, ["param2"] = 33, ["y"] = 9, ["param1"] = 158, ["z"] = 0, ["name"] = "bloc4builder:slope_rainbow_half_raised"}, {["x"] = 4, ["param2"] = 33, ["y"] = 9, ["param1"] = 174, ["z"] = 1, ["name"] = "bloc4builder:slope_rainbow_half_raised"}, {["x"] = 4, ["param2"] = 33, ["y"] = 9, ["param1"] = 190, ["z"] = 2, ["name"] = "bloc4builder:slope_rainbow_half_raised"}, {["x"] = 4, ["param2"] = 33, ["y"] = 9, ["param1"] = 206, ["z"] = 3, ["name"] = "bloc4builder:slope_rainbow_half_raised"}, {["x"] = 4, ["param2"] = 33, ["y"] = 9, ["param1"] = 206, ["z"] = 4, ["name"] = "bloc4builder:slope_rainbow_half_raised"}, {["x"] = 4, ["param2"] = 33, ["y"] = 9, ["param1"] = 190, ["z"] = 5, ["name"] = "bloc4builder:slope_rainbow_half_raised"}, {["x"] = 4, ["param2"] = 33, ["y"] = 9, ["param1"] = 174, ["z"] = 6, ["name"] = "bloc4builder:slope_rainbow_half_raised"}, {["x"] = 5, ["param2"] = 215, ["y"] = 3, ["param1"] = 126, ["z"] = 0, ["name"] = "bloc4builder:slope_rainbow_half_raised"}, {["x"] = 5, ["param2"] = 215, ["y"] = 3, ["param1"] = 109, ["z"] = 1, ["name"] = "bloc4builder:slope_rainbow_half_raised"}, {["x"] = 5, ["param2"] = 215, ["y"] = 3, ["param1"] = 92, ["z"] = 2, ["name"] = "bloc4builder:slope_rainbow_half_raised"}, {["x"] = 5, ["param2"] = 215, ["y"] = 3, ["param1"] = 91, ["z"] = 3, ["name"] = "bloc4builder:slope_rainbow_half_raised"}, {["x"] = 5, ["param2"] = 215, ["y"] = 3, ["param1"] = 106, ["z"] = 4, ["name"] = "bloc4builder:slope_rainbow_half_raised"}, {["x"] = 5, ["param2"] = 215, ["y"] = 3, ["param1"] = 121, ["z"] = 5, ["name"] = "bloc4builder:slope_rainbow_half_raised"}, {["x"] = 5, ["param2"] = 215, ["y"] = 3, ["param1"] = 137, ["z"] = 6, ["name"] = "bloc4builder:slope_rainbow_half_raised"}, {["x"] = 5, ["param2"] = 215, ["y"] = 3, ["param1"] = 153, ["z"] = 7, ["name"] = "bloc4builder:slope_rainbow_half_raised"}, {["x"] = 5, ["param2"] = 215, ["y"] = 3, ["param1"] = 170, ["z"] = 8, ["name"] = "bloc4builder:slope_rainbow_half_raised"}, {["x"] = 5, ["param2"] = 215, ["y"] = 3, ["param1"] = 155, ["z"] = 9, ["name"] = "bloc4builder:slope_rainbow_half_raised"}, {["x"] = 5, ["param2"] = 227, ["y"] = 4, ["z"] = 0, ["name"] = "bloc4builder:rainbow"}, {["x"] = 5, ["param2"] = 227, ["y"] = 4, ["param1"] = 108, ["z"] = 1, ["name"] = "bloc4builder:stair_rainbow_alt_1"}, {["x"] = 5, ["param2"] = 7, ["y"] = 4, ["param1"] = 91, ["z"] = 2, ["name"] = "bloc4builder:slab_rainbow_1"}, {["x"] = 5, ["param2"] = 226, ["y"] = 4, ["z"] = 9, ["name"] = "bloc4builder:rainbow"}, {["x"] = 5, ["meta"] = {["fields"] = {["infotext"] = "LASER", ["channel"] = "linxx:singleplayer", ["spacengine"] = "^A¨100¨0¨750¨20¨5¨2", ["pos_cont"] = "(-4,-3,4)"}, ["inventory"] = {}}, ["param2"] = 22, ["y"] = 4, ["param1"] = 109, ["z"] = 11, ["name"] = "spacengine:weapons"}, {["x"] = 5, ["param2"] = 35, ["y"] = 5, ["z"] = 0, ["name"] = "bloc4builder:rainbow"}, {["x"] = 5, ["param2"] = 2, ["y"] = 5, ["z"] = 2, ["name"] = "bloc4builder:rainbow"}, {["x"] = 5, ["param2"] = 2, ["y"] = 5, ["z"] = 3, ["name"] = "bloc4builder:rainbow"}, {["x"] = 5, ["param2"] = 2, ["y"] = 5, ["z"] = 4, ["name"] = "bloc4builder:rainbow"}, {["x"] = 5, ["param2"] = 3, ["y"] = 5, ["z"] = 5, ["name"] = "bloc4builder:rainbow"}, {["x"] = 5, ["param2"] = 3, ["y"] = 5, ["z"] = 6, ["name"] = "bloc4builder:rainbow"}, {["x"] = 5, ["param2"] = 3, ["y"] = 5, ["z"] = 7, ["name"] = "bloc4builder:rainbow"}, {["x"] = 5, ["param2"] = 3, ["y"] = 5, ["z"] = 8, ["name"] = "bloc4builder:rainbow"}, {["x"] = 5, ["y"] = 5, ["z"] = 9, ["name"] = "bloc4builder:rainbow"}, {["x"] = 5, ["param2"] = 33, ["y"] = 5, ["z"] = 10, ["name"] = "bloc4builder:rainbow"}, {["x"] = 5, ["param2"] = 33, ["y"] = 5, ["z"] = 11, ["name"] = "bloc4builder:rainbow"}, {["x"] = 5, ["param2"] = 50, ["y"] = 5, ["param1"] = 142, ["z"] = 12, ["name"] = "bloc4builder:slope_rainbow"}, {["x"] = 5, ["meta"] = {["fields"] = {["infotext"] = "Rocket", ["channel"] = "linxx:singleplayer", ["spacengine"] = "^A¨75¨0¨10¨50¨50¨500", ["pos_cont"] = "(-4,-1,-7)"}, ["inventory"] = {}}, ["y"] = 6, ["z"] = 0, ["name"] = "spacengine:engine"}, {["x"] = 5, ["param2"] = 7, ["y"] = 6, ["param1"] = 154, ["z"] = 2, ["name"] = "bloc4builder:slab_rainbow_1"}, {["x"] = 5, ["param2"] = 9, ["y"] = 6, ["param1"] = 154, ["z"] = 5, ["name"] = "bloc4builder:slab_rainbow_1"}, {["x"] = 5, ["meta"] = {["fields"] = {["channel"] = "No channel"}, ["inventory"] = {}}, ["param2"] = 2, ["y"] = 6, ["param1"] = 137, ["z"] = 7, ["name"] = "bloc4builder:door_shop"}, {["x"] = 5, ["meta"] = {["fields"] = {["infotext"] = "Radio", ["channel"] = "linxx:singleplayer", ["spacengine"] = "^A¨50¨0¨500", ["pos_cont"] = "(-4,-1,3)"}, ["inventory"] = {}}, ["param2"] = 3, ["y"] = 6, ["z"] = 10, ["name"] = "spacengine:radio"}, {["x"] = 5, ["param2"] = 32, ["y"] = 6, ["z"] = 11, ["name"] = "bloc4builder:rainbow"}, {["x"] = 5, ["param2"] = 50, ["y"] = 6, ["param1"] = 158, ["z"] = 12, ["name"] = "bloc4builder:slope_rainbow"}, {["x"] = 5, ["meta"] = {["fields"] = {["infotext"] = "Rocket", ["channel"] = "linxx:singleplayer", ["spacengine"] = "^A¨75¨0¨10¨50¨50¨500", ["pos_cont"] = "(-4,0,-7)"}, ["inventory"] = {}}, ["y"] = 7, ["z"] = 0, ["name"] = "spacengine:engine"}, {["x"] = 5, ["param2"] = 7, ["y"] = 7, ["param1"] = 171, ["z"] = 2, ["name"] = "bloc4builder:slab_rainbow_1"}, {["x"] = 5, ["param2"] = 9, ["y"] = 7, ["param1"] = 171, ["z"] = 5, ["name"] = "bloc4builder:slab_rainbow_1"}, {["x"] = 5, ["y"] = 7, ["param1"] = 138, ["z"] = 7, ["name"] = "bloc4builder:hidden"}, {["x"] = 5, ["param2"] = 32, ["y"] = 7, ["z"] = 10, ["name"] = "bloc4builder:rainbow"}, {["x"] = 5, ["param2"] = 32, ["y"] = 7, ["z"] = 11, ["name"] = "bloc4builder:rainbow"}, {["x"] = 5, ["param2"] = 50, ["y"] = 7, ["param1"] = 158, ["z"] = 12, ["name"] = "bloc4builder:slope_rainbow"}, {["x"] = 5, ["param2"] = 32, ["y"] = 8, ["z"] = 0, ["name"] = "bloc4builder:rainbow"}, {["x"] = 5, ["param2"] = 7, ["y"] = 8, ["param1"] = 188, ["z"] = 2, ["name"] = "bloc4builder:slab_rainbow_1"}, {["x"] = 5, ["param2"] = 9, ["y"] = 8, ["param1"] = 188, ["z"] = 5, ["name"] = "bloc4builder:slab_rainbow_1"}, {["x"] = 5, ["param2"] = 35, ["y"] = 8, ["z"] = 7, ["name"] = "bloc4builder:rainbow"}, {["x"] = 5, ["param2"] = 34, ["y"] = 8, ["z"] = 8, ["name"] = "bloc4builder:rainbow"}, {["x"] = 5, ["param2"] = 34, ["y"] = 8, ["z"] = 9, ["name"] = "bloc4builder:rainbow"}, {["x"] = 5, ["param2"] = 34, ["y"] = 8, ["z"] = 10, ["name"] = "bloc4builder:rainbow"}, {["x"] = 5, ["param2"] = 34, ["y"] = 8, ["z"] = 11, ["name"] = "bloc4builder:rainbow"}, {["x"] = 5, ["param2"] = 50, ["y"] = 8, ["param1"] = 142, ["z"] = 12, ["name"] = "bloc4builder:slope_rainbow"}, {["x"] = 5, ["param2"] = 35, ["y"] = 9, ["z"] = 0, ["name"] = "bloc4builder:rainbow"}, {["x"] = 5, ["param2"] = 3, ["y"] = 9, ["z"] = 1, ["name"] = "bloc4builder:rainbow"}, {["x"] = 5, ["param2"] = 3, ["y"] = 9, ["z"] = 2, ["name"] = "bloc4builder:rainbow"}, {["x"] = 5, ["param2"] = 3, ["y"] = 9, ["z"] = 3, ["name"] = "bloc4builder:rainbow"}, {["x"] = 5, ["param2"] = 3, ["y"] = 9, ["z"] = 4, ["name"] = "bloc4builder:rainbow"}, {["x"] = 5, ["y"] = 9, ["z"] = 5, ["name"] = "bloc4builder:rainbow"}, {["x"] = 5, ["y"] = 9, ["z"] = 6, ["name"] = "bloc4builder:rainbow"}, {["x"] = 5, ["param2"] = 114, ["y"] = 9, ["param1"] = 142, ["z"] = 7, ["name"] = "bloc4builder:slope_rainbow"}, {["x"] = 5, ["param2"] = 225, ["y"] = 10, ["param1"] = 126, ["z"] = 0, ["name"] = "bloc4builder:slope_rainbow"}, {["x"] = 5, ["param2"] = 225, ["y"] = 10, ["param1"] = 142, ["z"] = 1, ["name"] = "bloc4builder:slope_rainbow"}, {["x"] = 5, ["param2"] = 225, ["y"] = 10, ["param1"] = 158, ["z"] = 2, ["name"] = "bloc4builder:slope_rainbow"}, {["x"] = 5, ["param2"] = 225, ["y"] = 10, ["param1"] = 174, ["z"] = 3, ["name"] = "bloc4builder:slope_rainbow"}, {["x"] = 5, ["param2"] = 225, ["y"] = 10, ["param1"] = 174, ["z"] = 4, ["name"] = "bloc4builder:slope_rainbow"}, {["x"] = 5, ["param2"] = 225, ["y"] = 10, ["param1"] = 158, ["z"] = 5, ["name"] = "bloc4builder:slope_rainbow"}, {["x"] = 5, ["param2"] = 225, ["y"] = 10, ["param1"] = 142, ["z"] = 6, ["name"] = "bloc4builder:slope_rainbow"}, {["x"] = 5, ["param2"] = 226, ["y"] = 10, ["param1"] = 126, ["z"] = 7, ["name"] = "bloc4builder:slope_rainbow_outer_cut"}, {["x"] = 6, ["param2"] = 49, ["y"] = 2, ["param1"] = 126, ["z"] = 0, ["name"] = "bloc4builder:slope_rainbow"}, {["x"] = 6, ["param2"] = 49, ["y"] = 2, ["param1"] = 109, ["z"] = 1, ["name"] = "bloc4builder:slope_rainbow"}, {["x"] = 6, ["param2"] = 49, ["y"] = 2, ["param1"] = 92, ["z"] = 2, ["name"] = "bloc4builder:slope_rainbow"}, {["x"] = 6, ["param2"] = 49, ["y"] = 2, ["param1"] = 91, ["z"] = 3, ["name"] = "bloc4builder:slope_rainbow"}, {["x"] = 6, ["param2"] = 49, ["y"] = 2, ["param1"] = 106, ["z"] = 4, ["name"] = "bloc4builder:slope_rainbow"}, {["x"] = 6, ["param2"] = 49, ["y"] = 2, ["param1"] = 121, ["z"] = 5, ["name"] = "bloc4builder:slope_rainbow"}, {["x"] = 6, ["param2"] = 49, ["y"] = 2, ["param1"] = 136, ["z"] = 6, ["name"] = "bloc4builder:slope_rainbow"}, {["x"] = 6, ["param2"] = 55, ["y"] = 2, ["param1"] = 153, ["z"] = 7, ["name"] = "bloc4builder:slope_rainbow"}, {["x"] = 6, ["param2"] = 55, ["y"] = 2, ["param1"] = 170, ["z"] = 8, ["name"] = "bloc4builder:slope_rainbow"}, {["x"] = 6, ["param2"] = 55, ["y"] = 2, ["param1"] = 154, ["z"] = 9, ["name"] = "bloc4builder:slope_rainbow_outer_cut"}, {["x"] = 6, ["param2"] = 195, ["y"] = 3, ["z"] = 0, ["name"] = "bloc4builder:rainbow"}, {["x"] = 6, ["param2"] = 227, ["y"] = 3, ["param1"] = 92, ["z"] = 1, ["name"] = "bloc4builder:stair_rainbow_alt_1"}, {["x"] = 6, ["param2"] = 2, ["y"] = 3, ["param1"] = 91, ["z"] = 2, ["name"] = "bloc4builder:slab_rainbow_two_sides"}, {["x"] = 6, ["param2"] = 2, ["y"] = 3, ["param1"] = 106, ["z"] = 3, ["name"] = "bloc4builder:slab_rainbow_1"}, {["x"] = 6, ["param2"] = 2, ["y"] = 3, ["param1"] = 121, ["z"] = 4, ["name"] = "bloc4builder:slab_rainbow_1"}, {["x"] = 6, ["param2"] = 3, ["y"] = 3, ["param1"] = 136, ["z"] = 5, ["name"] = "bloc4builder:slab_rainbow_1"}, {["x"] = 6, ["param2"] = 3, ["y"] = 3, ["param1"] = 153, ["z"] = 6, ["name"] = "bloc4builder:slab_rainbow_1"}, {["x"] = 6, ["y"] = 3, ["param1"] = 170, ["z"] = 7, ["name"] = "bloc4builder:slab_rainbow_1"}, {["x"] = 6, ["y"] = 3, ["param1"] = 187, ["z"] = 8, ["name"] = "bloc4builder:slab_rainbow_1"}, {["x"] = 6, ["param2"] = 194, ["y"] = 3, ["z"] = 9, ["name"] = "bloc4builder:rainbow"}, {["x"] = 6, ["param2"] = 210, ["y"] = 3, ["param1"] = 123, ["z"] = 10, ["name"] = "bloc4builder:slope_rainbow"}, {["x"] = 6, ["param2"] = 227, ["y"] = 4, ["z"] = 0, ["name"] = "bloc4builder:rainbow"}, {["x"] = 6, ["param2"] = 7, ["y"] = 4, ["param1"] = 106, ["z"] = 2, ["name"] = "bloc4builder:slab_rainbow_1"}, {["x"] = 6, ["param2"] = 32, ["y"] = 4, ["z"] = 9, ["name"] = "bloc4builder:rainbow"}, {["x"] = 6, ["param2"] = 242, ["y"] = 4, ["param1"] = 107, ["z"] = 10, ["name"] = "bloc4builder:slope_rainbow"}, {["x"] = 6, ["param2"] = 35, ["y"] = 5, ["z"] = 0, ["name"] = "bloc4builder:rainbow"}, {["x"] = 6, ["param2"] = 22, ["y"] = 5, ["param1"] = 121, ["z"] = 2, ["name"] = "bloc4builder:slab_rainbow_two_sides"}, {["x"] = 6, ["param2"] = 21, ["y"] = 5, ["param1"] = 136, ["z"] = 3, ["name"] = "bloc4builder:slab_rainbow_1"}, {["x"] = 6, ["param2"] = 21, ["y"] = 5, ["param1"] = 136, ["z"] = 4, ["name"] = "bloc4builder:slab_rainbow_1"}, {["x"] = 6, ["param2"] = 21, ["y"] = 5, ["param1"] = 136, ["z"] = 5, ["name"] = "bloc4builder:slab_rainbow_1"}, {["x"] = 6, ["param2"] = 21, ["y"] = 5, ["param1"] = 153, ["z"] = 6, ["name"] = "bloc4builder:slab_rainbow_1"}, {["x"] = 6, ["param2"] = 21, ["y"] = 5, ["param1"] = 170, ["z"] = 7, ["name"] = "bloc4builder:slab_rainbow_1"}, {["x"] = 6, ["param2"] = 3, ["y"] = 5, ["z"] = 8, ["name"] = "bloc4builder:rainbow"}, {["x"] = 6, ["y"] = 5, ["z"] = 9, ["name"] = "bloc4builder:rainbow"}, {["x"] = 6, ["param2"] = 32, ["y"] = 5, ["z"] = 10, ["name"] = "bloc4builder:rainbow"}, {["x"] = 6, ["param2"] = 32, ["y"] = 5, ["z"] = 11, ["name"] = "bloc4builder:rainbow"}, {["x"] = 6, ["param2"] = 33, ["y"] = 5, ["z"] = 12, ["name"] = "bloc4builder:rainbow"}, {["x"] = 6, ["param2"] = 50, ["y"] = 5, ["param1"] = 174, ["z"] = 13, ["name"] = "bloc4builder:slope_rainbow_half_raised"}, {["x"] = 6, ["param2"] = 50, ["y"] = 5, ["param1"] = 190, ["z"] = 14, ["name"] = "bloc4builder:slope_rainbow_half"}, {["x"] = 6, ["meta"] = {["fields"] = {["infotext"] = "Rocket", ["channel"] = "linxx:singleplayer", ["spacengine"] = "^A¨75¨0¨10¨50¨50¨500", ["pos_cont"] = "(-3,-1,-7)"}, ["inventory"] = {}}, ["param2"] = 2, ["y"] = 6, ["z"] = 0, ["name"] = "spacengine:engine"}, {["x"] = 6, ["param2"] = 18, ["y"] = 6, ["param1"] = 121, ["z"] = 1, ["name"] = "bloc4builder:slab_rainbow_1"}, {["x"] = 6, ["param2"] = 7, ["y"] = 6, ["param1"] = 137, ["z"] = 2, ["name"] = "bloc4builder:slab_rainbow_1"}, {["x"] = 6, ["param2"] = 9, ["y"] = 6, ["param1"] = 137, ["z"] = 5, ["name"] = "bloc4builder:slab_rainbow_1"}, {["x"] = 6, ["meta"] = {["fields"] = {["channel"] = "No channel"}, ["inventory"] = {}}, ["y"] = 6, ["param1"] = 153, ["z"] = 7, ["name"] = "bloc4builder:door_shop"}, {["x"] = 6, ["param2"] = 50, ["y"] = 6, ["param1"] = 190, ["z"] = 13, ["name"] = "bloc4builder:slope_rainbow_half_raised"}, {["x"] = 6, ["param2"] = 50, ["y"] = 6, ["param1"] = 206, ["z"] = 14, ["name"] = "bloc4builder:slope_rainbow_half"}, {["x"] = 6, ["meta"] = {["fields"] = {["infotext"] = "Rocket", ["channel"] = "linxx:singleplayer", ["spacengine"] = "^A¨75¨0¨10¨50¨50¨500", ["pos_cont"] = "(-3,0,-7)"}, ["inventory"] = {}}, ["param2"] = 2, ["y"] = 7, ["z"] = 0, ["name"] = "spacengine:engine"}, {["x"] = 6, ["param2"] = 18, ["y"] = 7, ["param1"] = 138, ["z"] = 1, ["name"] = "bloc4builder:slab_rainbow_1"}, {["x"] = 6, ["param2"] = 7, ["y"] = 7, ["param1"] = 154, ["z"] = 2, ["name"] = "bloc4builder:slab_rainbow_1"}, {["x"] = 6, ["param2"] = 9, ["y"] = 7, ["param1"] = 154, ["z"] = 5, ["name"] = "bloc4builder:slab_rainbow_1"}, {["x"] = 6, ["y"] = 7, ["param1"] = 137, ["z"] = 7, ["name"] = "bloc4builder:hidden"}, {["x"] = 6, ["meta"] = {["fields"] = {["infotext"] = "POWER ON/OFF", ["channel"] = "linxx:singleplayer", ["spacengine"] = "^i¨0¨0¨^iA0¨1¨^", ["pos_cont"] = "(-3,0,3)"}, ["inventory"] = {}}, ["param2"] = 3, ["y"] = 7, ["param1"] = 140, ["z"] = 10, ["name"] = "spacengine:inter_0"}, {["x"] = 6, ["meta"] = {["fields"] = {["infotext"] = "POWER ON/OFF", ["channel"] = "linxx:singleplayer", ["spacengine"] = "^i¨0¨0¨^iA0¨1¨^", ["pos_cont"] = "(-3,0,4)"}, ["inventory"] = {}}, ["param2"] = 3, ["y"] = 7, ["param1"] = 157, ["z"] = 11, ["name"] = "spacengine:inter_0"}, {["x"] = 6, ["meta"] = {["fields"] = {["infotext"] = "POWER ON/OFF", ["channel"] = "linxx:singleplayer", ["spacengine"] = "^i¨0¨0¨^iA0¨1¨^", ["pos_cont"] = "(-3,0,5)"}, ["inventory"] = {}}, ["param2"] = 3, ["y"] = 7, ["param1"] = 173, ["z"] = 12, ["name"] = "spacengine:inter_0"}, {["x"] = 6, ["param2"] = 50, ["y"] = 7, ["param1"] = 190, ["z"] = 13, ["name"] = "bloc4builder:slope_rainbow_half_raised"}, {["x"] = 6, ["param2"] = 50, ["y"] = 7, ["param1"] = 206, ["z"] = 14, ["name"] = "bloc4builder:slope_rainbow_half"}, {["x"] = 6, ["param2"] = 32, ["y"] = 8, ["z"] = 0, ["name"] = "bloc4builder:rainbow"}, {["x"] = 6, ["param2"] = 23, ["y"] = 8, ["param1"] = 155, ["z"] = 1, ["name"] = "bloc4builder:slab_rainbow_two_sides"}, {["x"] = 6, ["param2"] = 22, ["y"] = 8, ["param1"] = 171, ["z"] = 2, ["name"] = "bloc4builder:slab_rainbow_two_sides"}, {["x"] = 6, ["param2"] = 21, ["y"] = 8, ["param1"] = 187, ["z"] = 3, ["name"] = "bloc4builder:slab_rainbow_1"}, {["x"] = 6, ["param2"] = 20, ["y"] = 8, ["param1"] = 187, ["z"] = 4, ["name"] = "bloc4builder:slab_rainbow_1"}, {["x"] = 6, ["param2"] = 20, ["y"] = 8, ["param1"] = 171, ["z"] = 5, ["name"] = "bloc4builder:slab_rainbow_two_sides"}, {["x"] = 6, ["param2"] = 20, ["y"] = 8, ["param1"] = 155, ["z"] = 6, ["name"] = "bloc4builder:slab_rainbow_1"}, {["x"] = 6, ["param2"] = 32, ["y"] = 8, ["z"] = 7, ["name"] = "bloc4builder:rainbow"}, {["x"] = 6, ["param2"] = 32, ["y"] = 8, ["z"] = 8, ["name"] = "bloc4builder:rainbow"}, {["x"] = 6, ["param2"] = 33, ["y"] = 8, ["z"] = 9, ["name"] = "bloc4builder:rainbow"}, {["x"] = 6, ["param2"] = 32, ["y"] = 8, ["z"] = 10, ["name"] = "bloc4builder:rainbow"}, {["x"] = 6, ["param2"] = 32, ["y"] = 8, ["z"] = 11, ["name"] = "bloc4builder:rainbow"}, {["x"] = 6, ["param2"] = 32, ["y"] = 8, ["z"] = 12, ["name"] = "bloc4builder:rainbow"}, {["x"] = 6, ["param2"] = 50, ["y"] = 8, ["param1"] = 174, ["z"] = 13, ["name"] = "bloc4builder:slope_rainbow_half_raised"}, {["x"] = 6, ["param2"] = 50, ["y"] = 8, ["param1"] = 190, ["z"] = 14, ["name"] = "bloc4builder:slope_rainbow_half"}, {["x"] = 6, ["param2"] = 34, ["y"] = 9, ["z"] = 0, ["name"] = "bloc4builder:rainbow"}, {["x"] = 6, ["param2"] = 3, ["y"] = 9, ["z"] = 7, ["name"] = "bloc4builder:rainbow"}, {["x"] = 6, ["param2"] = 114, ["y"] = 9, ["param1"] = 109, ["z"] = 8, ["name"] = "bloc4builder:slope_rainbow"}, {["x"] = 6, ["param2"] = 226, ["y"] = 10, ["z"] = 0, ["name"] = "bloc4builder:rainbow"}, {["x"] = 6, ["param2"] = 226, ["y"] = 10, ["param1"] = 125, ["z"] = 7, ["name"] = "bloc4builder:slope_rainbow_inner_cut"}, {["x"] = 6, ["param2"] = 226, ["y"] = 10, ["param1"] = 110, ["z"] = 8, ["name"] = "bloc4builder:slope_rainbow_outer_cut"}, {["x"] = 6, ["param2"] = 243, ["y"] = 11, ["param1"] = 158, ["z"] = 0, ["name"] = "bloc4builder:slope_rainbow_half_raised"}, {["x"] = 6, ["param2"] = 243, ["y"] = 11, ["param1"] = 174, ["z"] = 1, ["name"] = "bloc4builder:slope_rainbow_half_raised"}, {["x"] = 6, ["param2"] = 243, ["y"] = 11, ["param1"] = 189, ["z"] = 2, ["name"] = "bloc4builder:slope_rainbow_half_raised"}, {["x"] = 6, ["param2"] = 243, ["y"] = 11, ["param1"] = 190, ["z"] = 3, ["name"] = "bloc4builder:slope_rainbow_half_raised"}, {["x"] = 6, ["param2"] = 243, ["y"] = 11, ["param1"] = 190, ["z"] = 4, ["name"] = "bloc4builder:slope_rainbow_half_raised"}, {["x"] = 6, ["param2"] = 243, ["y"] = 11, ["param1"] = 174, ["z"] = 5, ["name"] = "bloc4builder:slope_rainbow_half_raised"}, {["x"] = 6, ["param2"] = 243, ["y"] = 11, ["param1"] = 158, ["z"] = 6, ["name"] = "bloc4builder:slope_rainbow_half_raised"}, {["x"] = 6, ["param2"] = 98, ["y"] = 11, ["param1"] = 142, ["z"] = 7, ["name"] = "bloc4builder:mesh_rainbow_fuse1"}, {["x"] = 6, ["param2"] = 37, ["y"] = 12, ["param1"] = 158, ["z"] = 0, ["name"] = "bloc4builder:mesh_rainbow_fuse1"}, {["x"] = 6, ["param2"] = 37, ["y"] = 12, ["param1"] = 158, ["z"] = 1, ["name"] = "bloc4builder:mesh_rainbow_fuse1"}, {["x"] = 6, ["param2"] = 37, ["y"] = 12, ["param1"] = 174, ["z"] = 2, ["name"] = "bloc4builder:mesh_rainbow_fuse1"}, {["x"] = 6, ["param2"] = 37, ["y"] = 12, ["param1"] = 174, ["z"] = 3, ["name"] = "bloc4builder:mesh_rainbow_fuse1"}, {["x"] = 6, ["param2"] = 37, ["y"] = 12, ["param1"] = 174, ["z"] = 4, ["name"] = "bloc4builder:mesh_rainbow_fuse1"}, {["x"] = 6, ["param2"] = 37, ["y"] = 12, ["param1"] = 158, ["z"] = 5, ["name"] = "bloc4builder:mesh_rainbow_fuse1"}, {["x"] = 6, ["param2"] = 37, ["y"] = 12, ["param1"] = 142, ["z"] = 6, ["name"] = "bloc4builder:mesh_rainbow_fuse1"}, {["x"] = 7, ["param2"] = 49, ["y"] = 0, ["param1"] = 142, ["z"] = 0, ["name"] = "bloc4builder:slope_rainbow_half"}, {["x"] = 7, ["param2"] = 49, ["y"] = 0, ["param1"] = 125, ["z"] = 1, ["name"] = "bloc4builder:slope_rainbow_half"}, {["x"] = 7, ["param2"] = 49, ["y"] = 0, ["param1"] = 108, ["z"] = 2, ["name"] = "bloc4builder:slope_rainbow_half"}, {["x"] = 7, ["param2"] = 49, ["y"] = 0, ["param1"] = 123, ["z"] = 3, ["name"] = "bloc4builder:slope_rainbow_half"}, {["x"] = 7, ["param2"] = 49, ["y"] = 0, ["param1"] = 138, ["z"] = 4, ["name"] = "bloc4builder:slope_rainbow_half"}, {["x"] = 7, ["param2"] = 49, ["y"] = 0, ["param1"] = 153, ["z"] = 5, ["name"] = "bloc4builder:slope_rainbow_half"}, {["x"] = 7, ["param2"] = 49, ["y"] = 0, ["param1"] = 153, ["z"] = 6, ["name"] = "bloc4builder:slope_rainbow_half"}, {["x"] = 7, ["param2"] = 49, ["y"] = 0, ["param1"] = 170, ["z"] = 7, ["name"] = "bloc4builder:slope_rainbow_half"}, {["x"] = 7, ["param2"] = 49, ["y"] = 0, ["param1"] = 187, ["z"] = 8, ["name"] = "bloc4builder:slope_rainbow_half"}, {["x"] = 7, ["param2"] = 55, ["y"] = 0, ["param1"] = 170, ["z"] = 9, ["name"] = "bloc4builder:mesh_rainbow_fuse6"}, {["x"] = 7, ["param2"] = 49, ["y"] = 1, ["param1"] = 126, ["z"] = 0, ["name"] = "bloc4builder:slope_rainbow_half_raised"}, {["x"] = 7, ["param2"] = 49, ["y"] = 1, ["param1"] = 109, ["z"] = 1, ["name"] = "bloc4builder:slope_rainbow_half_raised"}, {["x"] = 7, ["param2"] = 49, ["y"] = 1, ["param1"] = 108, ["z"] = 2, ["name"] = "bloc4builder:slope_rainbow_half_raised"}, {["x"] = 7, ["param2"] = 49, ["y"] = 1, ["param1"] = 123, ["z"] = 3, ["name"] = "bloc4builder:slope_rainbow_half_raised"}, {["x"] = 7, ["param2"] = 49, ["y"] = 1, ["param1"] = 138, ["z"] = 4, ["name"] = "bloc4builder:slope_rainbow_half_raised"}, {["x"] = 7, ["param2"] = 49, ["y"] = 1, ["param1"] = 153, ["z"] = 5, ["name"] = "bloc4builder:slope_rainbow_half_raised"}, {["x"] = 7, ["param2"] = 49, ["y"] = 1, ["param1"] = 170, ["z"] = 6, ["name"] = "bloc4builder:slope_rainbow_half_raised"}, {["x"] = 7, ["param2"] = 49, ["y"] = 1, ["param1"] = 187, ["z"] = 7, ["name"] = "bloc4builder:slope_rainbow_half_raised"}, {["x"] = 7, ["param2"] = 49, ["y"] = 1, ["param1"] = 204, ["z"] = 8, ["name"] = "bloc4builder:slope_rainbow_half_raised"}, {["x"] = 7, ["param2"] = 55, ["y"] = 1, ["param1"] = 187, ["z"] = 9, ["name"] = "bloc4builder:mesh_rainbow_fuse5"}, {["x"] = 7, ["param2"] = 32, ["y"] = 2, ["z"] = 0, ["name"] = "bloc4builder:rainbow"}, {["x"] = 7, ["param2"] = 227, ["y"] = 2, ["param1"] = 92, ["z"] = 1, ["name"] = "bloc4builder:stair_rainbow_alt_1"}, {["x"] = 7, ["param2"] = 34, ["y"] = 2, ["z"] = 2, ["name"] = "bloc4builder:rainbow"}, {["x"] = 7, ["meta"] = {["fields"] = {["infotext"] = "BATTERY Mega5", ["channel"] = "linxx:singleplayer", ["spacengine"] = "^C¨150¨0¨50000", ["pos_cont"] = "(-2,-5,-4)"}, ["inventory"] = {}}, ["param2"] = 3, ["y"] = 2, ["z"] = 3, ["name"] = "spacengine:battery"}, {["x"] = 7, ["meta"] = {["fields"] = {["infotext"] = "Gforce MOON", ["channel"] = "linxx:singleplayer", ["spacengine"] = "^A¨100¨0¨4", ["pos_cont"] = "(-2,-5,-3)"}, ["inventory"] = {}}, ["param2"] = 3, ["y"] = 2, ["z"] = 4, ["name"] = "spacengine:gravitation"}, {["x"] = 7, ["meta"] = {["fields"] = {["spacengine"] = "^C¨64¨0¨^bC0bJ0bM0aa0bi0¨1", ["channel"] = "linxx:singleplayer", ["text"] = "(2(b(c1(b2345____)(c(1;)ON(1:)OFF | (P(3?CONTROLER@)(1(kq)(q029% | (2(df(to(df(h(1_'a_)(h(1%a_)(h(1`a_)(f (2:(1g) | (r(1x)(f000%(c(1_v)X19Y15Z15 | (1(kV)(h(2`)OVER(l(14$)0004381", ["pos_cont"] = "(-2,-5,-1)"}, ["inventory"] = {}}, ["param2"] = 3, ["y"] = 2, ["param1"] = 153, ["z"] = 6, ["name"] = "monitor:screen_console"}, {["x"] = 7, ["meta"] = {["fields"] = {["infotext"] = "BATTERY 100", ["channel"] = "linxx:singleplayer", ["spacengine"] = "^B¨100¨0¨10000", ["pos_cont"] = "(-2,-5,1)"}, ["inventory"] = {}}, ["param2"] = 3, ["y"] = 2, ["z"] = 8, ["name"] = "spacengine:battery"}, {["x"] = 7, ["param2"] = 55, ["y"] = 2, ["param1"] = 170, ["z"] = 9, ["name"] = "bloc4builder:slope_rainbow_inner_cut"}, {["x"] = 7, ["param2"] = 55, ["y"] = 2, ["param1"] = 154, ["z"] = 10, ["name"] = "bloc4builder:slope_rainbow_outer_cut"}, {["x"] = 7, ["param2"] = 195, ["y"] = 3, ["z"] = 0, ["name"] = "bloc4builder:rainbow"}, {["x"] = 7, ["meta"] = {["fields"] = {["channel"] = "No channel"}, ["inventory"] = {}}, ["param2"] = 2, ["y"] = 3, ["param1"] = 106, ["z"] = 2, ["name"] = "bloc4builder:sas1"}, {["x"] = 7, ["param2"] = 2, ["y"] = 3, ["param1"] = 121, ["z"] = 3, ["name"] = "bloc4builder:slab_rainbow_1"}, {["x"] = 7, ["param2"] = 2, ["y"] = 3, ["param1"] = 136, ["z"] = 4, ["name"] = "bloc4builder:slab_rainbow_1"}, {["x"] = 7, ["param2"] = 2, ["y"] = 3, ["param1"] = 153, ["z"] = 5, ["name"] = "bloc4builder:slab_rainbow_1"}, {["x"] = 7, ["param2"] = 2, ["y"] = 3, ["param1"] = 170, ["z"] = 6, ["name"] = "bloc4builder:slab_rainbow_1"}, {["x"] = 7, ["y"] = 3, ["param1"] = 187, ["z"] = 7, ["name"] = "bloc4builder:slab_rainbow_1"}, {["x"] = 7, ["y"] = 3, ["param1"] = 204, ["z"] = 8, ["name"] = "bloc4builder:slab_rainbow_1"}, {["x"] = 7, ["y"] = 3, ["z"] = 9, ["name"] = "bloc4builder:rainbow"}, {["x"] = 7, ["param2"] = 195, ["y"] = 3, ["z"] = 10, ["name"] = "bloc4builder:rainbow"}, {["x"] = 7, ["param2"] = 193, ["y"] = 3, ["z"] = 11, ["name"] = "bloc4builder:rainbow"}, {["x"] = 7, ["param2"] = 193, ["y"] = 3, ["z"] = 12, ["name"] = "bloc4builder:rainbow"}, {["x"] = 7, ["param2"] = 214, ["y"] = 3, ["param1"] = 157, ["z"] = 13, ["name"] = "bloc4builder:slope_rainbow"}, {["x"] = 7, ["param2"] = 227, ["y"] = 4, ["z"] = 0, ["name"] = "bloc4builder:rainbow"}, {["x"] = 7, ["param2"] = 2, ["y"] = 4, ["param1"] = 121, ["z"] = 2, ["name"] = "bloc4builder:hidden"}, {["x"] = 7, ["param2"] = 9, ["y"] = 4, ["param1"] = 221, ["z"] = 8, ["name"] = "bloc4builder:light_on"}, {["x"] = 7, ["y"] = 4, ["z"] = 9, ["name"] = "bloc4builder:rainbow"}, {["x"] = 7, ["param2"] = 227, ["y"] = 4, ["z"] = 11, ["name"] = "bloc4builder:rainbow"}, {["x"] = 7, ["param2"] = 227, ["y"] = 4, ["z"] = 12, ["name"] = "bloc4builder:rainbow"}, {["x"] = 7, ["param2"] = 226, ["y"] = 4, ["z"] = 13, ["name"] = "bloc4builder:rainbow"}, {["x"] = 7, ["param2"] = 246, ["y"] = 4, ["param1"] = 190, ["z"] = 14, ["name"] = "bloc4builder:slope_rainbow"}, {["x"] = 7, ["param2"] = 35, ["y"] = 5, ["z"] = 0, ["name"] = "bloc4builder:rainbow"}, {["x"] = 7, ["param2"] = 23, ["y"] = 5, ["param1"] = 89, ["z"] = 1, ["name"] = "bloc4builder:slab_rainbow_1"}, {["x"] = 7, ["param2"] = 6, ["y"] = 5, ["param1"] = 104, ["z"] = 2, ["name"] = "bloc4builder:slab_rainbow_two_sides"}, {["x"] = 7, ["param2"] = 21, ["y"] = 5, ["param1"] = 119, ["z"] = 3, ["name"] = "bloc4builder:slab_rainbow_1"}, {["x"] = 7, ["param2"] = 21, ["y"] = 5, ["param1"] = 136, ["z"] = 4, ["name"] = "bloc4builder:slab_rainbow_1"}, {["x"] = 7, ["param2"] = 21, ["y"] = 5, ["param1"] = 153, ["z"] = 5, ["name"] = "bloc4builder:slab_rainbow_1"}, {["x"] = 7, ["param2"] = 21, ["y"] = 5, ["param1"] = 170, ["z"] = 6, ["name"] = "bloc4builder:slab_rainbow_1"}, {["x"] = 7, ["param2"] = 21, ["y"] = 5, ["param1"] = 187, ["z"] = 7, ["name"] = "bloc4builder:slab_rainbow_1"}, {["x"] = 7, ["param2"] = 3, ["y"] = 5, ["z"] = 8, ["name"] = "bloc4builder:rainbow"}, {["x"] = 7, ["y"] = 5, ["z"] = 9, ["name"] = "bloc4builder:rainbow"}, {["x"] = 7, ["param2"] = 3, ["y"] = 5, ["z"] = 10, ["name"] = "bloc4builder:rainbow"}, {["x"] = 7, ["param2"] = 3, ["y"] = 5, ["z"] = 11, ["name"] = "bloc4builder:rainbow"}, {["x"] = 7, ["y"] = 5, ["z"] = 12, ["name"] = "bloc4builder:rainbow"}, {["x"] = 7, ["param2"] = 1, ["y"] = 5, ["z"] = 13, ["name"] = "bloc4builder:rainbow"}, {["x"] = 7, ["param2"] = 227, ["y"] = 5, ["param1"] = 206, ["z"] = 14, ["name"] = "bloc4builder:slope_white_inner_cut"}, {["x"] = 7, ["param2"] = 225, ["y"] = 6, ["z"] = 0, ["name"] = "bloc4builder:rainbow"}, {["x"] = 7, ["param2"] = 9, ["y"] = 6, ["param1"] = 153, ["z"] = 5, ["name"] = "bloc4builder:slab_rainbow_1"}, {["x"] = 7, ["param2"] = 2, ["y"] = 6, ["z"] = 7, ["name"] = "bloc4builder:rainbow"}, {["x"] = 7, ["param2"] = 7, ["y"] = 6, ["param1"] = 222, ["z"] = 14, ["name"] = "moreblocks:slope_meselamp"}, {["x"] = 7, ["param2"] = 224, ["y"] = 7, ["z"] = 0, ["name"] = "bloc4builder:rainbow"}, {["x"] = 7, ["param2"] = 10, ["y"] = 7, ["param1"] = 137, ["z"] = 5, ["name"] = "bloc4builder:slab_rainbow_1"}, {["x"] = 7, ["param2"] = 2, ["y"] = 7, ["z"] = 7, ["name"] = "bloc4builder:rainbow"}, {["x"] = 7, ["meta"] = {["fields"] = {["infotext"] = "ENGINE PUISSANCE", ["channel"] = "linxx:singleplayer", ["spacengine"] = "^a¨0¨0¨^aA0¨1¨^", ["pos_cont"] = "(-2,0,6)"}, ["inventory"] = {}}, ["y"] = 7, ["param1"] = 205, ["z"] = 13, ["name"] = "spacengine:analog00"}, {["x"] = 7, ["param2"] = 7, ["y"] = 7, ["param1"] = 222, ["z"] = 14, ["name"] = "moreblocks:slope_meselamp"}, {["x"] = 7, ["param2"] = 32, ["y"] = 8, ["z"] = 0, ["name"] = "bloc4builder:rainbow"}, {["x"] = 7, ["param2"] = 21, ["y"] = 8, ["param1"] = 154, ["z"] = 2, ["name"] = "bloc4builder:slab_rainbow_1"}, {["x"] = 7, ["param2"] = 20, ["y"] = 8, ["param1"] = 170, ["z"] = 3, ["name"] = "bloc4builder:slab_rainbow_1"}, {["x"] = 7, ["param2"] = 20, ["y"] = 8, ["param1"] = 170, ["z"] = 4, ["name"] = "bloc4builder:slab_rainbow_1"}, {["x"] = 7, ["param2"] = 8, ["y"] = 8, ["param1"] = 154, ["z"] = 5, ["name"] = "bloc4builder:slab_rainbow_two_sides"}, {["x"] = 7, ["param2"] = 23, ["y"] = 8, ["param1"] = 138, ["z"] = 6, ["name"] = "bloc4builder:slab_rainbow_1"}, {["x"] = 7, ["param2"] = 2, ["y"] = 8, ["z"] = 7, ["name"] = "bloc4builder:rainbow"}, {["x"] = 7, ["meta"] = {["fields"] = {["infotext"] = "ENGINE PUISSANCE", ["channel"] = "linxx:singleplayer", ["spacengine"] = "^a¨0¨0¨^aA0¨1¨^", ["pos_cont"] = "(-2,1,1)"}, ["inventory"] = {}}, ["param2"] = 3, ["y"] = 8, ["param1"] = 140, ["z"] = 8, ["name"] = "spacengine:analog00"}, {["x"] = 7, ["param2"] = 245, ["y"] = 8, ["param1"] = 125, ["z"] = 9, ["name"] = "bloc4builder:slab_rainbow_1"}, {["x"] = 7, ["meta"] = {["fields"] = {["infotext"] = "ENGINE PUISSANCE", ["channel"] = "linxx:singleplayer", ["spacengine"] = "^a¨0¨0¨^aA0¨1¨^", ["pos_cont"] = "(-2,1,3)"}, ["inventory"] = {}}, ["param2"] = 3, ["y"] = 8, ["param1"] = 141, ["z"] = 10, ["name"] = "spacengine:analog00"}, {["x"] = 7, ["meta"] = {["fields"] = {["infotext"] = "CONTROLER on/off", ["channel"] = "linxx:singleplayer", ["spacengine"] = "^b¨0¨0¨^bC0¨1¨^", ["pos_cont"] = "(-2,1,4)"}, ["inventory"] = {}}, ["param2"] = 3, ["y"] = 8, ["param1"] = 158, ["z"] = 11, ["name"] = "spacengine:switch_bp"}, {["x"] = 7, ["meta"] = {["fields"] = {["infotext"] = "ENGINE PUISSANCE", ["channel"] = "linxx:singleplayer", ["spacengine"] = "^a¨0¨0¨^aA0¨1¨^", ["pos_cont"] = "(-2,1,5)"}, ["inventory"] = {}}, ["param2"] = 3, ["y"] = 8, ["param1"] = 174, ["z"] = 12, ["name"] = "spacengine:analog00"}, {["x"] = 7, ["param2"] = 20, ["y"] = 8, ["param1"] = 189, ["z"] = 13, ["name"] = "bloc4builder:slope_white"}, {["x"] = 7, ["param2"] = 246, ["y"] = 8, ["param1"] = 206, ["z"] = 14, ["name"] = "bloc4builder:slope_white_inner_cut"}, {["x"] = 7, ["param2"] = 34, ["y"] = 9, ["z"] = 0, ["name"] = "bloc4builder:rainbow"}, {["x"] = 7, ["param2"] = 12, ["y"] = 9, ["param1"] = 155, ["z"] = 1, ["name"] = "bloc4builder:slab_rainbow_two_sides"}, {["x"] = 7, ["y"] = 9, ["z"] = 2, ["name"] = "default:dirt"}, {["x"] = 7, ["y"] = 9, ["z"] = 3, ["name"] = "default:dirt"}, {["x"] = 7, ["y"] = 9, ["z"] = 4, ["name"] = "default:dirt"}, {["x"] = 7, ["param2"] = 3, ["y"] = 9, ["z"] = 7, ["name"] = "bloc4builder:rainbow"}, {["x"] = 7, ["param2"] = 227, ["y"] = 9, ["z"] = 8, ["name"] = "bloc4builder:rainbow"}, {["x"] = 7, ["y"] = 9, ["param1"] = 110, ["z"] = 9, ["name"] = "default:obsidian_glass"}, {["x"] = 7, ["param2"] = 225, ["y"] = 9, ["z"] = 10, ["name"] = "bloc4builder:rainbow"}, {["x"] = 7, ["param2"] = 227, ["y"] = 9, ["z"] = 11, ["name"] = "bloc4builder:rainbow"}, {["x"] = 7, ["param2"] = 224, ["y"] = 9, ["z"] = 12, ["name"] = "bloc4builder:rainbow"}, {["x"] = 7, ["param2"] = 226, ["y"] = 9, ["param1"] = 174, ["z"] = 13, ["name"] = "bloc4builder:slope_rainbow_half_raised"}, {["x"] = 7, ["param2"] = 226, ["y"] = 9, ["param1"] = 190, ["z"] = 14, ["name"] = "bloc4builder:slope_rainbow_half"}, {["x"] = 7, ["param2"] = 226, ["y"] = 10, ["z"] = 0, ["name"] = "bloc4builder:rainbow"}, {["x"] = 7, ["param2"] = 3, ["y"] = 10, ["z"] = 7, ["name"] = "bloc4builder:rainbow"}, {["x"] = 7, ["param2"] = 224, ["y"] = 10, ["z"] = 8, ["name"] = "bloc4builder:rainbow"}, {["x"] = 7, ["y"] = 10, ["param1"] = 110, ["z"] = 9, ["name"] = "default:obsidian_glass"}, {["x"] = 7, ["param2"] = 227, ["y"] = 10, ["z"] = 10, ["name"] = "bloc4builder:rainbow"}, {["x"] = 7, ["param2"] = 226, ["y"] = 10, ["param1"] = 126, ["z"] = 11, ["name"] = "bloc4builder:slope_rainbow_half_raised"}, {["x"] = 7, ["param2"] = 226, ["y"] = 10, ["param1"] = 142, ["z"] = 12, ["name"] = "bloc4builder:slope_rainbow_half"}, {["x"] = 7, ["param2"] = 226, ["y"] = 11, ["z"] = 0, ["name"] = "bloc4builder:rainbow"}, {["x"] = 7, ["param2"] = 227, ["y"] = 11, ["z"] = 7, ["name"] = "bloc4builder:rainbow"}, {["x"] = 7, ["param2"] = 227, ["y"] = 11, ["z"] = 8, ["name"] = "bloc4builder:rainbow"}, {["x"] = 7, ["param2"] = 226, ["y"] = 11, ["param1"] = 126, ["z"] = 9, ["name"] = "bloc4builder:slope_rainbow_half_raised"}, {["x"] = 7, ["param2"] = 226, ["y"] = 11, ["param1"] = 110, ["z"] = 10, ["name"] = "bloc4builder:slope_rainbow_half"}, {["x"] = 7, ["param2"] = 33, ["y"] = 12, ["param1"] = 174, ["z"] = 0, ["name"] = "bloc4builder:slope_rainbow_half_raised"}, {["x"] = 7, ["param2"] = 33, ["y"] = 12, ["param1"] = 174, ["z"] = 1, ["name"] = "bloc4builder:slope_rainbow_half_raised"}, {["x"] = 7, ["param2"] = 33, ["y"] = 12, ["param1"] = 189, ["z"] = 2, ["name"] = "bloc4builder:slope_rainbow_half_raised"}, {["x"] = 7, ["param2"] = 33, ["y"] = 12, ["param1"] = 190, ["z"] = 3, ["name"] = "bloc4builder:slope_rainbow_half_raised"}, {["x"] = 7, ["param2"] = 33, ["y"] = 12, ["param1"] = 189, ["z"] = 4, ["name"] = "bloc4builder:slope_rainbow_half_raised"}, {["x"] = 7, ["param2"] = 33, ["y"] = 12, ["param1"] = 174, ["z"] = 5, ["name"] = "bloc4builder:slope_rainbow_half_raised"}, {["x"] = 7, ["param2"] = 33, ["y"] = 12, ["param1"] = 157, ["z"] = 6, ["name"] = "bloc4builder:slope_rainbow_half_raised"}, {["x"] = 7, ["param2"] = 34, ["y"] = 12, ["param1"] = 142, ["z"] = 7, ["name"] = "bloc4builder:slope_rainbow_outer_cut"}, {["x"] = 7, ["meta"] = {["fields"] = {["infotext"] = "Stone", ["channel"] = "linxx:singleplayer", ["spacengine"] = "^A¨50¨0¨300¨30¨^group:stone", ["pos_cont"] = "(-2,5,1)"}, ["inventory"] = {}}, ["param2"] = 2, ["y"] = 12, ["param1"] = 126, ["z"] = 8, ["name"] = "spacengine:radar"}, {["x"] = 8, ["param2"] = 32, ["y"] = 0, ["z"] = 0, ["name"] = "bloc4builder:rainbow"}, {["x"] = 8, ["param2"] = 32, ["y"] = 0, ["z"] = 1, ["name"] = "bloc4builder:rainbow"}, {["x"] = 8, ["param2"] = 32, ["y"] = 0, ["z"] = 2, ["name"] = "bloc4builder:rainbow"}, {["x"] = 8, ["param2"] = 32, ["y"] = 0, ["z"] = 3, ["name"] = "bloc4builder:rainbow"}, {["x"] = 8, ["param2"] = 32, ["y"] = 0, ["z"] = 4, ["name"] = "bloc4builder:rainbow"}, {["x"] = 8, ["param2"] = 32, ["y"] = 0, ["z"] = 5, ["name"] = "bloc4builder:rainbow"}, {["x"] = 8, ["param2"] = 32, ["y"] = 0, ["z"] = 6, ["name"] = "bloc4builder:rainbow"}, {["x"] = 8, ["param2"] = 32, ["y"] = 0, ["z"] = 7, ["name"] = "bloc4builder:rainbow"}, {["x"] = 8, ["param2"] = 32, ["y"] = 0, ["z"] = 8, ["name"] = "bloc4builder:rainbow"}, {["x"] = 8, ["param2"] = 33, ["y"] = 0, ["z"] = 9, ["name"] = "bloc4builder:rainbow"}, {["x"] = 8, ["param2"] = 38, ["y"] = 0, ["param1"] = 138, ["z"] = 10, ["name"] = "bloc4builder:slope_rainbow"}, {["x"] = 8, ["param2"] = 35, ["y"] = 1, ["z"] = 0, ["name"] = "bloc4builder:rainbow"}, {["x"] = 8, ["param2"] = 227, ["y"] = 1, ["param1"] = 108, ["z"] = 1, ["name"] = "bloc4builder:stair_rainbow_alt_1"}, {["x"] = 8, ["param2"] = 39, ["y"] = 1, ["param1"] = 123, ["z"] = 2, ["name"] = "bloc4builder:slab_rainbow_1"}, {["x"] = 8, ["param2"] = 9, ["y"] = 1, ["param1"] = 221, ["z"] = 8, ["name"] = "bloc4builder:light_on"}, {["x"] = 8, ["param2"] = 32, ["y"] = 1, ["z"] = 9, ["name"] = "bloc4builder:rainbow"}, {["x"] = 8, ["param2"] = 33, ["y"] = 1, ["z"] = 10, ["name"] = "bloc4builder:rainbow"}, {["x"] = 8, ["param2"] = 54, ["y"] = 1, ["param1"] = 139, ["z"] = 11, ["name"] = "bloc4builder:slope_rainbow"}, {["x"] = 8, ["param2"] = 35, ["y"] = 2, ["z"] = 0, ["name"] = "bloc4builder:rainbow"}, {["x"] = 8, ["param2"] = 39, ["y"] = 2, ["param1"] = 106, ["z"] = 2, ["name"] = "bloc4builder:slab_rainbow_1"}, {["x"] = 8, ["param2"] = 35, ["y"] = 2, ["z"] = 9, ["name"] = "bloc4builder:rainbow"}, {["x"] = 8, ["param2"] = 32, ["y"] = 2, ["z"] = 10, ["name"] = "bloc4builder:rainbow"}, {["x"] = 8, ["param2"] = 33, ["y"] = 2, ["z"] = 11, ["name"] = "bloc4builder:rainbow"}, {["x"] = 8, ["param2"] = 54, ["y"] = 2, ["param1"] = 108, ["z"] = 12, ["name"] = "bloc4builder:slope_rainbow"}, {["x"] = 8, ["param2"] = 195, ["y"] = 3, ["z"] = 0, ["name"] = "bloc4builder:rainbow"}, {["x"] = 8, ["param2"] = 4, ["y"] = 3, ["param1"] = 89, ["z"] = 2, ["name"] = "bloc4builder:slab_rainbow_two_sides"}, {["x"] = 8, ["param2"] = 2, ["y"] = 3, ["param1"] = 104, ["z"] = 3, ["name"] = "bloc4builder:slab_rainbow_1"}, {["x"] = 8, ["param2"] = 2, ["y"] = 3, ["param1"] = 119, ["z"] = 4, ["name"] = "bloc4builder:slab_rainbow_1"}, {["x"] = 8, ["param2"] = 2, ["y"] = 3, ["param1"] = 136, ["z"] = 5, ["name"] = "bloc4builder:slab_rainbow_1"}, {["x"] = 8, ["param2"] = 2, ["y"] = 3, ["param1"] = 153, ["z"] = 6, ["name"] = "bloc4builder:slab_rainbow_1"}, {["x"] = 8, ["y"] = 3, ["param1"] = 170, ["z"] = 7, ["name"] = "bloc4builder:slab_rainbow_1"}, {["x"] = 8, ["y"] = 3, ["param1"] = 187, ["z"] = 8, ["name"] = "bloc4builder:slab_rainbow_1"}, {["x"] = 8, ["param2"] = 3, ["y"] = 3, ["z"] = 9, ["name"] = "bloc4builder:rainbow"}, {["x"] = 8, ["meta"] = {["fields"] = {["infotext"] = "Shield+", ["channel"] = "linxx:singleplayer", ["spacengine"] = "^D¨125¨0¨1250¨3", ["pos_cont"] = "(-1,-4,5)"}, ["inventory"] = {}}, ["y"] = 3, ["z"] = 12, ["name"] = "spacengine:shield"}, {["x"] = 8, ["param2"] = 214, ["y"] = 3, ["param1"] = 141, ["z"] = 13, ["name"] = "bloc4builder:slope_rainbow"}, {["x"] = 8, ["param2"] = 227, ["y"] = 4, ["z"] = 0, ["name"] = "bloc4builder:rainbow"}, {["x"] = 8, ["param2"] = 7, ["y"] = 4, ["param1"] = 104, ["z"] = 2, ["name"] = "bloc4builder:slab_rainbow_1"}, {["x"] = 8, ["param2"] = 3, ["y"] = 4, ["z"] = 9, ["name"] = "bloc4builder:rainbow"}, {["x"] = 8, ["meta"] = {["fields"] = {["infotext"] = "Shield+", ["channel"] = "linxx:singleplayer", ["spacengine"] = "^D¨125¨0¨1250¨3", ["pos_cont"] = "(-1,-3,5)"}, ["inventory"] = {}}, ["y"] = 4, ["z"] = 12, ["name"] = "spacengine:shield"}, {["x"] = 8, ["param2"] = 2, ["y"] = 4, ["z"] = 13, ["name"] = "bloc4builder:rainbow"}, {["x"] = 8, ["param2"] = 246, ["y"] = 4, ["param1"] = 174, ["z"] = 14, ["name"] = "bloc4builder:slope_rainbow"}, {["x"] = 8, ["param2"] = 32, ["y"] = 5, ["z"] = 0, ["name"] = "bloc4builder:rainbow"}, {["x"] = 8, ["param2"] = 21, ["y"] = 5, ["param1"] = 104, ["z"] = 1, ["name"] = "bloc4builder:slab_rainbow_1"}, {["x"] = 8, ["param2"] = 22, ["y"] = 5, ["param1"] = 103, ["z"] = 2, ["name"] = "bloc4builder:slab_rainbow_two_sides"}, {["x"] = 8, ["param2"] = 21, ["y"] = 5, ["param1"] = 119, ["z"] = 3, ["name"] = "bloc4builder:slab_rainbow_1"}, {["x"] = 8, ["param2"] = 21, ["y"] = 5, ["param1"] = 136, ["z"] = 4, ["name"] = "bloc4builder:slab_rainbow_1"}, {["x"] = 8, ["param2"] = 21, ["y"] = 5, ["param1"] = 153, ["z"] = 5, ["name"] = "bloc4builder:slab_rainbow_1"}, {["x"] = 8, ["param2"] = 21, ["y"] = 5, ["param1"] = 170, ["z"] = 6, ["name"] = "bloc4builder:slab_rainbow_1"}, {["x"] = 8, ["param2"] = 22, ["y"] = 5, ["param1"] = 187, ["z"] = 7, ["name"] = "bloc4builder:slab_rainbow_1"}, {["x"] = 8, ["param2"] = 3, ["y"] = 5, ["z"] = 8, ["name"] = "bloc4builder:rainbow"}, {["x"] = 8, ["param2"] = 3, ["y"] = 5, ["z"] = 9, ["name"] = "bloc4builder:rainbow"}, {["x"] = 8, ["param2"] = 3, ["y"] = 5, ["z"] = 10, ["name"] = "bloc4builder:rainbow"}, {["x"] = 8, ["y"] = 5, ["z"] = 11, ["name"] = "bloc4builder:rainbow"}, {["x"] = 8, ["y"] = 5, ["z"] = 12, ["name"] = "bloc4builder:rainbow"}, {["x"] = 8, ["y"] = 5, ["z"] = 13, ["name"] = "bloc4builder:rainbow"}, {["x"] = 8, ["param2"] = 226, ["y"] = 5, ["param1"] = 190, ["z"] = 14, ["name"] = "bloc4builder:slope_white"}, {["x"] = 8, ["param2"] = 225, ["y"] = 6, ["z"] = 0, ["name"] = "bloc4builder:rainbow"}, {["x"] = 8, ["param2"] = 1, ["y"] = 6, ["param1"] = 120, ["z"] = 1, ["name"] = "bloc4builder:stair_rainbow_alt"}, {["x"] = 8, ["param2"] = 7, ["y"] = 6, ["param1"] = 119, ["z"] = 2, ["name"] = "bloc4builder:slab_rainbow_1"}, {["x"] = 8, ["param2"] = 2, ["y"] = 6, ["param1"] = 187, ["z"] = 6, ["name"] = "bloc4builder:slab_rainbow_three_sides_u"}, {["x"] = 8, ["meta"] = {["fields"] = {["infotext"] = "Crew", ["channel"] = "linxx:singleplayer", ["spacengine"] = "^A¨50¨0¨^c", ["pos_cont"] = "(-1,-1,0)"}, ["inventory"] = {}}, ["y"] = 6, ["param1"] = 204, ["z"] = 7, ["name"] = "spacengine:passenger"}, {["x"] = 8, ["y"] = 6, ["param1"] = 158, ["z"] = 10, ["name"] = "moreblocks:box_obsidian_glass_midslim"}, {["x"] = 8, ["param2"] = 7, ["y"] = 6, ["param1"] = 206, ["z"] = 14, ["name"] = "moreblocks:slab_obsidian_glass_1"}, {["x"] = 8, ["param2"] = 225, ["y"] = 7, ["z"] = 0, ["name"] = "bloc4builder:rainbow"}, {["x"] = 8, ["param2"] = 7, ["y"] = 7, ["param1"] = 120, ["z"] = 2, ["name"] = "bloc4builder:slab_rainbow_1"}, {["x"] = 8, ["param2"] = 20, ["y"] = 7, ["param1"] = 170, ["z"] = 6, ["name"] = "bloc4builder:slab_rainbow_three_sides_u"}, {["x"] = 8, ["meta"] = {["fields"] = {["spacengine"] = "^S¨64¨0¨^aB0bM0¨1", ["channel"] = "linxx:singleplayer", ["text"] = "(2(b(c1(b2_______)(cPUISSAN | (p(3?SHIELD@)(h (3?OFF@) | (n(1A)(f000% | (d(1`)05000 / (c05000 | (2(eRQ)003", ["pos_cont"] = "(-1,0,3)"}, ["inventory"] = {}}, ["y"] = 7, ["param1"] = 142, ["z"] = 10, ["name"] = "monitor:screen_transparent"}, {["x"] = 8, ["param2"] = 7, ["y"] = 7, ["param1"] = 206, ["z"] = 14, ["name"] = "moreblocks:slab_obsidian_glass_1"}, {["x"] = 8, ["param2"] = 33, ["y"] = 8, ["z"] = 0, ["name"] = "bloc4builder:rainbow"}, {["x"] = 8, ["param2"] = 6, ["y"] = 8, ["param1"] = 137, ["z"] = 2, ["name"] = "bloc4builder:slab_rainbow_two_sides"}, {["x"] = 8, ["param2"] = 22, ["y"] = 8, ["param1"] = 153, ["z"] = 3, ["name"] = "bloc4builder:slab_rainbow_1"}, {["x"] = 8, ["param2"] = 21, ["y"] = 8, ["param1"] = 153, ["z"] = 4, ["name"] = "bloc4builder:slab_rainbow_1"}, {["x"] = 8, ["param2"] = 8, ["y"] = 8, ["param1"] = 154, ["z"] = 5, ["name"] = "bloc4builder:slab_rainbow_two_sides"}, {["x"] = 8, ["param2"] = 1, ["y"] = 8, ["z"] = 6, ["name"] = "bloc4builder:rainbow"}, {["x"] = 8, ["param2"] = 22, ["y"] = 8, ["param1"] = 172, ["z"] = 7, ["name"] = "bloc4builder:slab_rainbow_1"}, {["x"] = 8, ["param2"] = 86, ["y"] = 8, ["param1"] = 157, ["z"] = 8, ["name"] = "bloc4builder:slab_rainbow_1"}, {["x"] = 8, ["param2"] = 85, ["y"] = 8, ["param1"] = 142, ["z"] = 9, ["name"] = "bloc4builder:slab_rainbow_1"}, {["x"] = 8, ["param2"] = 76, ["y"] = 8, ["param1"] = 126, ["z"] = 10, ["name"] = "bloc4builder:box_rainbow_tslim"}, {["x"] = 8, ["meta"] = {["fields"] = {["spacengine"] = "^C¨64¨0¨^bC0bJ0bM0aa0bi0¨1", ["channel"] = "linxx:singleplayer", ["text"] = "(2(b(c1(b2345____)(c(1;)ON(1:)OFF | (P(3?CONTROLER@)(1(kq)(q029% | (2(df(to(df(h(1_'a_)(h(1%a_)(h(1`a_)(f (2:(1g) | (r(1x)(f000%(c(1_v)X19Y15Z15 | (1(kV)(h(2`)OVER(l(14$)0004381", ["pos_cont"] = "(-1,1,6)"}, ["inventory"] = {}}, ["y"] = 8, ["param1"] = 174, ["z"] = 13, ["name"] = "monitor:screen_up"}, {["x"] = 8, ["param2"] = 246, ["y"] = 8, ["param1"] = 190, ["z"] = 14, ["name"] = "bloc4builder:slope_white"}, {["x"] = 8, ["param2"] = 34, ["y"] = 9, ["z"] = 0, ["name"] = "bloc4builder:rainbow"}, {["x"] = 8, ["param2"] = 9, ["y"] = 9, ["param1"] = 171, ["z"] = 1, ["name"] = "bloc4builder:slab_rainbow_1"}, {["x"] = 8, ["y"] = 9, ["z"] = 2, ["name"] = "default:dirt"}, {["x"] = 8, ["y"] = 9, ["z"] = 3, ["name"] = "default:dirt"}, {["x"] = 8, ["y"] = 9, ["z"] = 4, ["name"] = "default:dirt"}, {["x"] = 8, ["param2"] = 9, ["y"] = 9, ["param1"] = 156, ["z"] = 6, ["name"] = "bloc4builder:slab_rainbow_1"}, {["x"] = 8, ["meta"] = {["fields"] = {["spacengine"] = "^C¨64¨0¨^bC0bJ0bM0aa0bi0¨1", ["channel"] = "linxx:singleplayer", ["text"] = "(2(b(c1(b2345____)(c(1;)ON(1:)OFF | (P(3?CONTROLER@)(1(kq)(q029% | (2(df(to(df(h(1_'a_)(h(1%a_)(h(1`a_)(f (2:(1g) | (r(1x)(f000%(c(1_v)X19Y15Z15 | (1(kV)(h(2`)OVER(l(14$)0004381", ["pos_cont"] = "(-1,2,3)"}, ["inventory"] = {}}, ["y"] = 9, ["param1"] = 111, ["z"] = 10, ["name"] = "monitor:screen_down"}, {["x"] = 8, ["param2"] = 226, ["y"] = 9, ["param1"] = 158, ["z"] = 13, ["name"] = "bloc4builder:slope_rainbow_half_raised"}, {["x"] = 8, ["param2"] = 226, ["y"] = 9, ["param1"] = 174, ["z"] = 14, ["name"] = "bloc4builder:slope_rainbow_half"}, {["x"] = 8, ["param2"] = 226, ["y"] = 10, ["z"] = 0, ["name"] = "bloc4builder:rainbow"}, {["x"] = 8, ["param2"] = 9, ["y"] = 10, ["param1"] = 172, ["z"] = 6, ["name"] = "bloc4builder:slab_rainbow_1"}, {["x"] = 8, ["meta"] = {["fields"] = {["infotext"] = "CONTROLER on/off -- 1 --\
CONTROLER on/off -- 2 --\
CONTROLER on/off -- 3 --\
CONTROLER on/off -- 4 --", ["channel"] = "linxx:singleplayer", ["spacengine"] = "^t¨0¨0¨^bC0bC0bC0bC0¨1¨^", ["pos_cont"] = "(-1,3,1)"}, ["inventory"] = {}}, ["param2"] = 3, ["y"] = 10, ["param1"] = 142, ["z"] = 8, ["name"] = "spacengine:switch_4bp3"}, {["x"] = 8, ["meta"] = {["fields"] = {["infotext"] = "ENGINE PUISSANCE", ["channel"] = "linxx:singleplayer", ["spacengine"] = "^a¨0¨0¨^aA0¨1¨^", ["pos_cont"] = "(-1,3,3)"}, ["inventory"] = {}}, ["param2"] = 3, ["y"] = 10, ["param1"] = 111, ["z"] = 10, ["name"] = "spacengine:analog00"}, {["x"] = 8, ["param2"] = 2, ["y"] = 10, ["param1"] = 111, ["z"] = 11, ["name"] = "moreblocks:slope_obsidian_glass_half_raised"}, {["x"] = 8, ["param2"] = 2, ["y"] = 10, ["param1"] = 127, ["z"] = 12, ["name"] = "moreblocks:slope_obsidian_glass_half"}, {["x"] = 8, ["param2"] = 226, ["y"] = 11, ["z"] = 0, ["name"] = "bloc4builder:rainbow"}, {["x"] = 8, ["param2"] = 22, ["y"] = 11, ["param1"] = 221, ["z"] = 2, ["name"] = "bloc4builder:light_on"}, {["x"] = 8, ["param2"] = 22, ["y"] = 11, ["param1"] = 221, ["z"] = 3, ["name"] = "bloc4builder:light_on"}, {["x"] = 8, ["param2"] = 22, ["y"] = 11, ["param1"] = 221, ["z"] = 4, ["name"] = "bloc4builder:light_on"}, {["x"] = 8, ["param2"] = 9, ["y"] = 11, ["param1"] = 188, ["z"] = 6, ["name"] = "bloc4builder:slab_rainbow_1"}, {["x"] = 8, ["param2"] = 2, ["y"] = 11, ["param1"] = 143, ["z"] = 9, ["name"] = "moreblocks:slope_obsidian_glass_half_raised"}, {["x"] = 8, ["param2"] = 2, ["y"] = 11, ["param1"] = 127, ["z"] = 10, ["name"] = "moreblocks:slope_obsidian_glass_half"}, {["x"] = 8, ["param2"] = 34, ["y"] = 12, ["z"] = 0, ["name"] = "bloc4builder:rainbow"}, {["x"] = 8, ["meta"] = {["fields"] = {["infotext"] = "Generateur Hydrogene", ["channel"] = "linxx:singleplayer", ["spacengine"] = "2¨150¨0¨500¨^spacengine:hydrogene_tank¨^battery¨15¨1¨9¨500", ["pos_cont"] = "(-1,5,-6)"}, ["inventory"] = {}}, ["y"] = 12, ["param1"] = 190, ["z"] = 1, ["name"] = "spacengine:power"}, {["x"] = 8, ["param2"] = 34, ["y"] = 12, ["z"] = 2, ["name"] = "bloc4builder:rainbow"}, {["x"] = 8, ["param2"] = 34, ["y"] = 12, ["z"] = 3, ["name"] = "bloc4builder:rainbow"}, {["x"] = 8, ["param2"] = 33, ["y"] = 12, ["z"] = 4, ["name"] = "bloc4builder:rainbow"}, {["x"] = 8, ["param2"] = 33, ["y"] = 12, ["z"] = 5, ["name"] = "bloc4builder:rainbow"}, {["x"] = 8, ["param2"] = 33, ["y"] = 12, ["z"] = 6, ["name"] = "bloc4builder:rainbow"}, {["x"] = 8, ["param2"] = 34, ["y"] = 12, ["param1"] = 157, ["z"] = 7, ["name"] = "bloc4builder:slope_rainbow_half_raised"}, {["x"] = 8, ["param2"] = 34, ["y"] = 12, ["param1"] = 142, ["z"] = 8, ["name"] = "bloc4builder:slope_rainbow_half"}, {["x"] = 9, ["param2"] = 35, ["y"] = 0, ["z"] = 0, ["name"] = "bloc4builder:rainbow"}, {["x"] = 9, ["param2"] = 34, ["y"] = 0, ["z"] = 1, ["name"] = "bloc4builder:rainbow"}, {["x"] = 9, ["param2"] = 35, ["y"] = 0, ["z"] = 2, ["name"] = "bloc4builder:rainbow"}, {["x"] = 9, ["param2"] = 32, ["y"] = 0, ["z"] = 3, ["name"] = "bloc4builder:rainbow"}, {["x"] = 9, ["param2"] = 32, ["y"] = 0, ["z"] = 4, ["name"] = "bloc4builder:rainbow"}, {["x"] = 9, ["param2"] = 32, ["y"] = 0, ["z"] = 5, ["name"] = "bloc4builder:rainbow"}, {["x"] = 9, ["param2"] = 32, ["y"] = 0, ["z"] = 6, ["name"] = "bloc4builder:rainbow"}, {["x"] = 9, ["param2"] = 32, ["y"] = 0, ["z"] = 7, ["name"] = "bloc4builder:rainbow"}, {["x"] = 9, ["param2"] = 32, ["y"] = 0, ["z"] = 8, ["name"] = "bloc4builder:rainbow"}, {["x"] = 9, ["param2"] = 34, ["y"] = 0, ["z"] = 9, ["name"] = "bloc4builder:rainbow"}, {["x"] = 9, ["param2"] = 38, ["y"] = 0, ["param1"] = 154, ["z"] = 10, ["name"] = "bloc4builder:slope_rainbow"}, {["x"] = 9, ["param2"] = 34, ["y"] = 1, ["z"] = 0, ["name"] = "bloc4builder:rainbow"}, {["x"] = 9, ["meta"] = {["fields"] = {["owner"] = "singleplayer", ["channel"] = "linxx"}, ["inventory"] = {}}, ["y"] = 1, ["param1"] = 170, ["z"] = 10, ["name"] = "bloc4builder:sas2"}, {["x"] = 9, ["param2"] = 34, ["y"] = 2, ["z"] = 0, ["name"] = "bloc4builder:rainbow"}, {["x"] = 9, ["y"] = 2, ["param1"] = 154, ["z"] = 10, ["name"] = "bloc4builder:hidden"}, {["x"] = 9, ["param2"] = 195, ["y"] = 3, ["z"] = 0, ["name"] = "bloc4builder:rainbow"}, {["x"] = 9, ["param2"] = 2, ["y"] = 3, ["param1"] = 88, ["z"] = 2, ["name"] = "bloc4builder:slab_rainbow_two_sides"}, {["x"] = 9, ["param2"] = 2, ["y"] = 3, ["param1"] = 103, ["z"] = 3, ["name"] = "bloc4builder:slab_rainbow_1"}, {["x"] = 9, ["param2"] = 3, ["y"] = 3, ["param1"] = 119, ["z"] = 4, ["name"] = "bloc4builder:slab_rainbow_1"}, {["x"] = 9, ["param2"] = 3, ["y"] = 3, ["param1"] = 136, ["z"] = 5, ["name"] = "bloc4builder:slab_rainbow_1"}, {["x"] = 9, ["param2"] = 3, ["y"] = 3, ["param1"] = 153, ["z"] = 6, ["name"] = "bloc4builder:slab_rainbow_1"}, {["x"] = 9, ["param2"] = 3, ["y"] = 3, ["param1"] = 170, ["z"] = 7, ["name"] = "bloc4builder:slab_rainbow_1"}, {["x"] = 9, ["param2"] = 3, ["y"] = 3, ["param1"] = 170, ["z"] = 8, ["name"] = "bloc4builder:slab_rainbow_1"}, {["x"] = 9, ["y"] = 3, ["z"] = 9, ["name"] = "bloc4builder:rainbow"}, {["x"] = 9, ["param2"] = 35, ["y"] = 3, ["param1"] = 138, ["z"] = 10, ["name"] = "bloc4builder:slab_rainbow_1"}, {["x"] = 9, ["param2"] = 35, ["y"] = 3, ["param1"] = 123, ["z"] = 11, ["name"] = "bloc4builder:slab_rainbow_1"}, {["x"] = 9, ["param2"] = 35, ["y"] = 3, ["param1"] = 108, ["z"] = 12, ["name"] = "bloc4builder:slab_rainbow_1"}, {["x"] = 9, ["param2"] = 214, ["y"] = 3, ["param1"] = 125, ["z"] = 13, ["name"] = "bloc4builder:slope_rainbow"}, {["x"] = 9, ["param2"] = 227, ["y"] = 4, ["z"] = 0, ["name"] = "bloc4builder:rainbow"}, {["x"] = 9, ["param2"] = 7, ["y"] = 4, ["param1"] = 103, ["z"] = 2, ["name"] = "bloc4builder:slab_rainbow_1"}, {["x"] = 9, ["y"] = 4, ["z"] = 9, ["name"] = "bloc4builder:rainbow"}, {["x"] = 9, ["y"] = 4, ["param1"] = 123, ["z"] = 12, ["name"] = "spacengine:command2"}, {["x"] = 9, ["param2"] = 2, ["y"] = 4, ["z"] = 13, ["name"] = "bloc4builder:rainbow"}, {["x"] = 9, ["param2"] = 246, ["y"] = 4, ["param1"] = 158, ["z"] = 14, ["name"] = "bloc4builder:slope_rainbow"}, {["x"] = 9, ["param2"] = 35, ["y"] = 5, ["z"] = 0, ["name"] = "bloc4builder:rainbow"}, {["x"] = 9, ["param2"] = 21, ["y"] = 5, ["param1"] = 103, ["z"] = 1, ["name"] = "bloc4builder:slab_rainbow_1"}, {["x"] = 9, ["param2"] = 22, ["y"] = 5, ["param1"] = 119, ["z"] = 2, ["name"] = "bloc4builder:slab_rainbow_two_sides"}, {["x"] = 9, ["param2"] = 21, ["y"] = 5, ["param1"] = 136, ["z"] = 3, ["name"] = "bloc4builder:slab_rainbow_1"}, {["x"] = 9, ["param2"] = 21, ["y"] = 5, ["param1"] = 153, ["z"] = 4, ["name"] = "bloc4builder:slab_rainbow_1"}, {["x"] = 9, ["param2"] = 21, ["y"] = 5, ["param1"] = 170, ["z"] = 5, ["name"] = "bloc4builder:slab_rainbow_1"}, {["x"] = 9, ["param2"] = 21, ["y"] = 5, ["param1"] = 187, ["z"] = 6, ["name"] = "bloc4builder:slab_rainbow_1"}, {["x"] = 9, ["param2"] = 21, ["y"] = 5, ["param1"] = 204, ["z"] = 7, ["name"] = "bloc4builder:slab_rainbow_1"}, {["x"] = 9, ["param2"] = 3, ["y"] = 5, ["z"] = 8, ["name"] = "bloc4builder:rainbow"}, {["x"] = 9, ["param2"] = 3, ["y"] = 5, ["z"] = 9, ["name"] = "bloc4builder:rainbow"}, {["x"] = 9, ["y"] = 5, ["z"] = 10, ["name"] = "bloc4builder:rainbow"}, {["x"] = 9, ["y"] = 5, ["z"] = 11, ["name"] = "bloc4builder:rainbow"}, {["x"] = 9, ["y"] = 5, ["z"] = 12, ["name"] = "bloc4builder:rainbow"}, {["x"] = 9, ["y"] = 5, ["z"] = 13, ["name"] = "bloc4builder:rainbow"}, {["x"] = 9, ["param2"] = 226, ["y"] = 5, ["param1"] = 174, ["z"] = 14, ["name"] = "bloc4builder:slope_white"}, {["x"] = 9, ["param2"] = 226, ["y"] = 6, ["z"] = 0, ["name"] = "bloc4builder:rainbow"}, {["x"] = 9, ["param2"] = 7, ["y"] = 6, ["param1"] = 136, ["z"] = 2, ["name"] = "bloc4builder:slab_rainbow_1"}, {["x"] = 9, ["param2"] = 2, ["y"] = 6, ["param1"] = 204, ["z"] = 6, ["name"] = "bloc4builder:slab_rainbow_three_sides_u"}, {["x"] = 9, ["y"] = 6, ["z"] = 7, ["name"] = "jumpdrive:engine"}, {["x"] = 9, ["y"] = 6, ["param1"] = 174, ["z"] = 10, ["name"] = "moreblocks:box_obsidian_glass_midslim"}, {["x"] = 9, ["param2"] = 7, ["y"] = 6, ["param1"] = 190, ["z"] = 14, ["name"] = "moreblocks:slab_obsidian_glass_1"}, {["x"] = 9, ["param2"] = 226, ["y"] = 7, ["z"] = 0, ["name"] = "bloc4builder:rainbow"}, {["x"] = 9, ["param2"] = 1, ["y"] = 7, ["param1"] = 120, ["z"] = 1, ["name"] = "bloc4builder:stair_rainbow_alt"}, {["x"] = 9, ["param2"] = 7, ["y"] = 7, ["param1"] = 136, ["z"] = 2, ["name"] = "bloc4builder:slab_rainbow_1"}, {["x"] = 9, ["param2"] = 22, ["y"] = 7, ["param1"] = 187, ["z"] = 6, ["name"] = "bloc4builder:slab_rainbow_two_sides"}, {["x"] = 9, ["meta"] = {["fields"] = {["spacengine"] = "^K¨250¨0¨^x09y07z07v04275¨6", ["channel"] = "linxx:singleplayer", ["captain"] = "singleplayer", ["infotext"] = "CONTROLER beta5", ["pos_cont"] = "(-20853,1982,-25030)", ["stock_pos"] = "33333#0#0¨-2#-5#-1¨-1#0#3¨-1#1#6¨-1#2#3¨-1#5#-6¨0#0#3¨0#2#5¨1#0#3¨1#1#6¨1#2#3¨1#5#-6¨3#0#3¨3#0#5"}, ["inventory"] = {["stock"] = {"spacengine:oxygene_tank 98", "spacengine:hydrogene_tank 93", "", "", "", ""}}}, ["y"] = 7, ["z"] = 7, ["name"] = "spacengine:controler"}, {["x"] = 9, ["meta"] = {["fields"] = {["spacengine"] = "^W¨64¨0¨^bF0aC0aD0aI0bM0¨1", ["channel"] = "linxx:singleplayer", ["text"] = "(2(b(c1(b2345____)(c(h(1!)FIRE (1!) | (p (3?WEAPONS@) (fREADY! | (1(hq)(q025%(l(1_%)004 (d(1v)002 | (1(g*A)00000U(1_(mwA)000 | (e(2_Q)0000/0005", ["pos_cont"] = "(0,0,3)"}, ["inventory"] = {}}, ["y"] = 7, ["param1"] = 158, ["z"] = 10, ["name"] = "monitor:screen_transparent"}, {["x"] = 9, ["param2"] = 7, ["y"] = 7, ["param1"] = 190, ["z"] = 14, ["name"] = "moreblocks:slab_obsidian_glass_1"}, {["x"] = 9, ["param2"] = 34, ["y"] = 8, ["z"] = 0, ["name"] = "bloc4builder:rainbow"}, {["x"] = 9, ["param2"] = 6, ["y"] = 8, ["param1"] = 153, ["z"] = 2, ["name"] = "bloc4builder:slab_rainbow_two_sides"}, {["x"] = 9, ["param2"] = 22, ["y"] = 8, ["param1"] = 136, ["z"] = 3, ["name"] = "bloc4builder:slab_rainbow_1"}, {["x"] = 9, ["param2"] = 22, ["y"] = 8, ["param1"] = 137, ["z"] = 4, ["name"] = "bloc4builder:slab_rainbow_1"}, {["x"] = 9, ["param2"] = 8, ["y"] = 8, ["param1"] = 154, ["z"] = 5, ["name"] = "bloc4builder:slab_rainbow_two_sides"}, {["x"] = 9, ["param2"] = 3, ["y"] = 8, ["z"] = 6, ["name"] = "bloc4builder:rainbow"}, {["x"] = 9, ["param2"] = 2, ["y"] = 8, ["z"] = 7, ["name"] = "bloc4builder:rainbow"}, {["x"] = 9, ["param2"] = 86, ["y"] = 8, ["param1"] = 173, ["z"] = 8, ["name"] = "bloc4builder:slab_rainbow_1"}, {["x"] = 9, ["param2"] = 86, ["y"] = 8, ["param1"] = 158, ["z"] = 9, ["name"] = "bloc4builder:slab_rainbow_1"}, {["x"] = 9, ["param2"] = 76, ["y"] = 8, ["param1"] = 142, ["z"] = 10, ["name"] = "bloc4builder:box_rainbow_tslim"}, {["x"] = 9, ["meta"] = {["fields"] = {["infotext"] = "ENGINE PUISSANCE", ["channel"] = "linxx:singleplayer", ["spacengine"] = "^a¨0¨0¨^aA0¨1¨^", ["pos_cont"] = "(0,1,6)"}, ["inventory"] = {}}, ["param2"] = 8, ["y"] = 8, ["param1"] = 157, ["z"] = 13, ["name"] = "spacengine:analog10"}, {["x"] = 9, ["param2"] = 246, ["y"] = 8, ["param1"] = 174, ["z"] = 14, ["name"] = "bloc4builder:slope_white"}, {["x"] = 9, ["param2"] = 34, ["y"] = 9, ["z"] = 0, ["name"] = "bloc4builder:rainbow"}, {["x"] = 9, ["param2"] = 9, ["y"] = 9, ["param1"] = 154, ["z"] = 1, ["name"] = "bloc4builder:slab_rainbow_1"}, {["x"] = 9, ["y"] = 9, ["param1"] = 170, ["z"] = 2, ["name"] = "default:water_source"}, {["x"] = 9, ["y"] = 9, ["z"] = 3, ["name"] = "default:dirt"}, {["x"] = 9, ["y"] = 9, ["z"] = 4, ["name"] = "default:dirt"}, {["x"] = 9, ["param2"] = 32, ["y"] = 9, ["param1"] = 140, ["z"] = 6, ["name"] = "bloc4builder:ladder"}, {["x"] = 9, ["param2"] = 7, ["y"] = 9, ["param1"] = 141, ["z"] = 7, ["name"] = "bloc4builder:slab_rainbow"}, {["x"] = 9, ["meta"] = {["fields"] = {["spacengine"] = "^m¨64¨0¨^aa0¨25¨^m", ["channel"] = "linxx:singleplayer", ["text"] = " |  | (h-21:42 LOW BAT.--", ["pos_cont"] = "(0,2,5)"}, ["inventory"] = {}}, ["y"] = 9, ["param1"] = 142, ["z"] = 12, ["name"] = "monitor:screen_led"}, {["x"] = 9, ["param2"] = 226, ["y"] = 9, ["param1"] = 142, ["z"] = 13, ["name"] = "bloc4builder:slope_rainbow_half_raised"}, {["x"] = 9, ["param2"] = 226, ["y"] = 9, ["param1"] = 158, ["z"] = 14, ["name"] = "bloc4builder:slope_rainbow_half"}, {["x"] = 9, ["param2"] = 226, ["y"] = 10, ["z"] = 0, ["name"] = "bloc4builder:rainbow"}, {["x"] = 9, ["param2"] = 192, ["y"] = 10, ["param1"] = 156, ["z"] = 6, ["name"] = "bloc4builder:ladder"}, {["x"] = 9, ["param2"] = 7, ["y"] = 10, ["param1"] = 141, ["z"] = 7, ["name"] = "bloc4builder:slab_rainbow"}, {["x"] = 9, ["meta"] = {["fields"] = {["infotext"] = "CONTROLER on/off", ["channel"] = "linxx:singleplayer", ["spacengine"] = "^b¨0¨0¨^bC0¨1¨^", ["pos_cont"] = "(0,3,3)"}, ["inventory"] = {}}, ["y"] = 10, ["param1"] = 111, ["z"] = 10, ["name"] = "spacengine:switch_emergency"}, {["x"] = 9, ["param2"] = 2, ["y"] = 10, ["param1"] = 111, ["z"] = 11, ["name"] = "bloc4builder:slope_building_glass_half_raised"}, {["x"] = 9, ["param2"] = 226, ["y"] = 10, ["param1"] = 126, ["z"] = 12, ["name"] = "bloc4builder:slope_rainbow_half"}, {["x"] = 9, ["param2"] = 226, ["y"] = 11, ["z"] = 0, ["name"] = "bloc4builder:rainbow"}, {["x"] = 9, ["param2"] = 32, ["y"] = 11, ["param1"] = 172, ["z"] = 6, ["name"] = "bloc4builder:ladder"}, {["x"] = 9, ["param2"] = 7, ["y"] = 11, ["param1"] = 157, ["z"] = 7, ["name"] = "bloc4builder:slab_rainbow"}, {["x"] = 9, ["param2"] = 2, ["y"] = 11, ["param1"] = 127, ["z"] = 9, ["name"] = "bloc4builder:slope_building_glass_half_raised"}, {["x"] = 9, ["param2"] = 2, ["y"] = 11, ["param1"] = 111, ["z"] = 10, ["name"] = "bloc4builder:slope_building_glass_half"}, {["x"] = 9, ["param2"] = 34, ["y"] = 12, ["z"] = 0, ["name"] = "bloc4builder:rainbow"}, {["x"] = 9, ["param2"] = 3, ["y"] = 12, ["z"] = 1, ["name"] = "bloc4builder:rainbow"}, {["x"] = 9, ["param2"] = 2, ["y"] = 12, ["z"] = 2, ["name"] = "bloc4builder:rainbow"}, {["x"] = 9, ["param2"] = 2, ["y"] = 12, ["z"] = 3, ["name"] = "bloc4builder:rainbow"}, {["x"] = 9, ["param2"] = 34, ["y"] = 12, ["z"] = 4, ["name"] = "bloc4builder:rainbow"}, {["x"] = 9, ["param2"] = 34, ["y"] = 12, ["z"] = 5, ["name"] = "bloc4builder:rainbow"}, {["x"] = 9, ["param2"] = 192, ["y"] = 12, ["param1"] = 157, ["z"] = 6, ["name"] = "bloc4builder:ladder"}, {["x"] = 9, ["param2"] = 34, ["y"] = 12, ["param1"] = 142, ["z"] = 7, ["name"] = "bloc4builder:slope_rainbow_half_raised"}, {["x"] = 9, ["param2"] = 34, ["y"] = 12, ["param1"] = 126, ["z"] = 8, ["name"] = "bloc4builder:slope_rainbow_half"}, {["x"] = 9, ["param2"] = 227, ["y"] = 13, ["z"] = 0, ["name"] = "bloc4builder:rainbow"}, {["x"] = 9, ["param2"] = 227, ["y"] = 13, ["z"] = 1, ["name"] = "bloc4builder:rainbow"}, {["x"] = 9, ["param2"] = 226, ["y"] = 13, ["z"] = 2, ["name"] = "bloc4builder:rainbow"}, {["x"] = 9, ["param2"] = 226, ["y"] = 13, ["param1"] = 190, ["z"] = 3, ["name"] = "bloc4builder:slope_rainbow"}, {["x"] = 9, ["y"] = 13, ["param1"] = 142, ["z"] = 6, ["name"] = "bloc4builder:trapdoor_metal"}, {["x"] = 9, ["y"] = 14, ["param1"] = 239, ["z"] = 0, ["name"] = "default:meselamp"}, {["x"] = 9, ["y"] = 14, ["param1"] = 239, ["z"] = 1, ["name"] = "default:meselamp"}, {["x"] = 9, ["param2"] = 2, ["y"] = 14, ["param1"] = 223, ["z"] = 2, ["name"] = "moreblocks:slope_meselamp"}, {["x"] = 10, ["param2"] = 32, ["y"] = 0, ["z"] = 0, ["name"] = "bloc4builder:rainbow"}, {["x"] = 10, ["param2"] = 35, ["y"] = 0, ["z"] = 1, ["name"] = "bloc4builder:rainbow"}, {["x"] = 10, ["param2"] = 34, ["y"] = 0, ["z"] = 2, ["name"] = "bloc4builder:rainbow"}, {["x"] = 10, ["param2"] = 34, ["y"] = 0, ["z"] = 3, ["name"] = "bloc4builder:rainbow"}, {["x"] = 10, ["param2"] = 34, ["y"] = 0, ["z"] = 4, ["name"] = "bloc4builder:rainbow"}, {["x"] = 10, ["param2"] = 35, ["y"] = 0, ["z"] = 5, ["name"] = "bloc4builder:rainbow"}, {["x"] = 10, ["param2"] = 35, ["y"] = 0, ["z"] = 6, ["name"] = "bloc4builder:rainbow"}, {["x"] = 10, ["param2"] = 35, ["y"] = 0, ["z"] = 7, ["name"] = "bloc4builder:rainbow"}, {["x"] = 10, ["param2"] = 35, ["y"] = 0, ["z"] = 8, ["name"] = "bloc4builder:rainbow"}, {["x"] = 10, ["param2"] = 35, ["y"] = 0, ["z"] = 9, ["name"] = "bloc4builder:rainbow"}, {["x"] = 10, ["param2"] = 38, ["y"] = 0, ["param1"] = 138, ["z"] = 10, ["name"] = "bloc4builder:slope_rainbow"}, {["x"] = 10, ["param2"] = 32, ["y"] = 1, ["z"] = 0, ["name"] = "bloc4builder:rainbow"}, {["x"] = 10, ["param2"] = 225, ["y"] = 1, ["param1"] = 108, ["z"] = 1, ["name"] = "bloc4builder:stair_rainbow_alt_1"}, {["x"] = 10, ["param2"] = 39, ["y"] = 1, ["param1"] = 123, ["z"] = 2, ["name"] = "bloc4builder:slab_rainbow_1"}, {["x"] = 10, ["param2"] = 9, ["y"] = 1, ["param1"] = 221, ["z"] = 8, ["name"] = "bloc4builder:light_on"}, {["x"] = 10, ["param2"] = 32, ["y"] = 1, ["z"] = 9, ["name"] = "bloc4builder:rainbow"}, {["x"] = 10, ["param2"] = 35, ["y"] = 1, ["z"] = 10, ["name"] = "bloc4builder:rainbow"}, {["x"] = 10, ["param2"] = 54, ["y"] = 1, ["param1"] = 139, ["z"] = 11, ["name"] = "bloc4builder:slope_rainbow"}, {["x"] = 10, ["param2"] = 32, ["y"] = 2, ["z"] = 0, ["name"] = "bloc4builder:rainbow"}, {["x"] = 10, ["param2"] = 39, ["y"] = 2, ["param1"] = 106, ["z"] = 2, ["name"] = "bloc4builder:slab_rainbow_1"}, {["x"] = 10, ["param2"] = 35, ["y"] = 2, ["z"] = 9, ["name"] = "bloc4builder:rainbow"}, {["x"] = 10, ["param2"] = 35, ["y"] = 2, ["z"] = 10, ["name"] = "bloc4builder:rainbow"}, {["x"] = 10, ["param2"] = 33, ["y"] = 2, ["z"] = 11, ["name"] = "bloc4builder:rainbow"}, {["x"] = 10, ["param2"] = 54, ["y"] = 2, ["param1"] = 108, ["z"] = 12, ["name"] = "bloc4builder:slope_rainbow"}, {["x"] = 10, ["param2"] = 192, ["y"] = 3, ["z"] = 0, ["name"] = "bloc4builder:rainbow"}, {["x"] = 10, ["param2"] = 2, ["y"] = 3, ["param1"] = 89, ["z"] = 2, ["name"] = "bloc4builder:slab_rainbow_two_sides"}, {["x"] = 10, ["param2"] = 2, ["y"] = 3, ["param1"] = 104, ["z"] = 3, ["name"] = "bloc4builder:slab_rainbow_1"}, {["x"] = 10, ["param2"] = 2, ["y"] = 3, ["param1"] = 119, ["z"] = 4, ["name"] = "bloc4builder:slab_rainbow_1"}, {["x"] = 10, ["param2"] = 2, ["y"] = 3, ["param1"] = 136, ["z"] = 5, ["name"] = "bloc4builder:slab_rainbow_1"}, {["x"] = 10, ["param2"] = 2, ["y"] = 3, ["param1"] = 153, ["z"] = 6, ["name"] = "bloc4builder:slab_rainbow_1"}, {["x"] = 10, ["param2"] = 1, ["y"] = 3, ["param1"] = 170, ["z"] = 7, ["name"] = "bloc4builder:slab_rainbow_1"}, {["x"] = 10, ["param2"] = 1, ["y"] = 3, ["param1"] = 187, ["z"] = 8, ["name"] = "bloc4builder:slab_rainbow_1"}, {["x"] = 10, ["meta"] = {["fields"] = {["channel"] = "No channel"}, ["inventory"] = {}}, ["y"] = 3, ["param1"] = 170, ["z"] = 9, ["name"] = "bloc4builder:door_shop"}, {["x"] = 10, ["meta"] = {["fields"] = {["infotext"] = "Shield+", ["channel"] = "linxx:singleplayer", ["spacengine"] = "^D¨125¨0¨1250¨3", ["pos_cont"] = "(1,-4,5)"}, ["inventory"] = {}}, ["y"] = 3, ["z"] = 12, ["name"] = "spacengine:shield"}, {["x"] = 10, ["param2"] = 214, ["y"] = 3, ["param1"] = 141, ["z"] = 13, ["name"] = "bloc4builder:slope_rainbow"}, {["x"] = 10, ["param2"] = 224, ["y"] = 4, ["z"] = 0, ["name"] = "bloc4builder:rainbow"}, {["x"] = 10, ["param2"] = 7, ["y"] = 4, ["param1"] = 104, ["z"] = 2, ["name"] = "bloc4builder:slab_rainbow_1"}, {["x"] = 10, ["y"] = 4, ["param1"] = 187, ["z"] = 9, ["name"] = "bloc4builder:hidden"}, {["x"] = 10, ["meta"] = {["fields"] = {["infotext"] = "Shield+", ["channel"] = "linxx:singleplayer", ["spacengine"] = "^D¨125¨0¨1250¨3", ["pos_cont"] = "(1,-3,5)"}, ["inventory"] = {}}, ["y"] = 4, ["z"] = 12, ["name"] = "spacengine:shield"}, {["x"] = 10, ["param2"] = 2, ["y"] = 4, ["z"] = 13, ["name"] = "bloc4builder:rainbow"}, {["x"] = 10, ["param2"] = 246, ["y"] = 4, ["param1"] = 174, ["z"] = 14, ["name"] = "bloc4builder:slope_rainbow"}, {["x"] = 10, ["param2"] = 32, ["y"] = 5, ["z"] = 0, ["name"] = "bloc4builder:rainbow"}, {["x"] = 10, ["param2"] = 21, ["y"] = 5, ["param1"] = 104, ["z"] = 1, ["name"] = "bloc4builder:slab_rainbow_1"}, {["x"] = 10, ["param2"] = 22, ["y"] = 5, ["param1"] = 103, ["z"] = 2, ["name"] = "bloc4builder:slab_rainbow_two_sides"}, {["x"] = 10, ["param2"] = 23, ["y"] = 5, ["param1"] = 119, ["z"] = 3, ["name"] = "bloc4builder:slab_rainbow_1"}, {["x"] = 10, ["param2"] = 23, ["y"] = 5, ["param1"] = 136, ["z"] = 4, ["name"] = "bloc4builder:slab_rainbow_1"}, {["x"] = 10, ["param2"] = 23, ["y"] = 5, ["param1"] = 153, ["z"] = 5, ["name"] = "bloc4builder:slab_rainbow_1"}, {["x"] = 10, ["param2"] = 23, ["y"] = 5, ["param1"] = 170, ["z"] = 6, ["name"] = "bloc4builder:slab_rainbow_1"}, {["x"] = 10, ["param2"] = 20, ["y"] = 5, ["param1"] = 187, ["z"] = 7, ["name"] = "bloc4builder:slab_rainbow_1"}, {["x"] = 10, ["param2"] = 3, ["y"] = 5, ["z"] = 8, ["name"] = "bloc4builder:rainbow"}, {["x"] = 10, ["param2"] = 3, ["y"] = 5, ["z"] = 9, ["name"] = "bloc4builder:rainbow"}, {["x"] = 10, ["y"] = 5, ["z"] = 10, ["name"] = "bloc4builder:rainbow"}, {["x"] = 10, ["y"] = 5, ["z"] = 11, ["name"] = "bloc4builder:rainbow"}, {["x"] = 10, ["y"] = 5, ["z"] = 12, ["name"] = "bloc4builder:rainbow"}, {["x"] = 10, ["y"] = 5, ["z"] = 13, ["name"] = "bloc4builder:rainbow"}, {["x"] = 10, ["param2"] = 226, ["y"] = 5, ["param1"] = 190, ["z"] = 14, ["name"] = "bloc4builder:slope_white"}, {["x"] = 10, ["param2"] = 224, ["y"] = 6, ["z"] = 0, ["name"] = "bloc4builder:rainbow"}, {["x"] = 10, ["param2"] = 3, ["y"] = 6, ["param1"] = 119, ["z"] = 2, ["name"] = "bloc4builder:box_rainbow_tslim"}, {["x"] = 10, ["param2"] = 3, ["y"] = 6, ["param1"] = 136, ["z"] = 3, ["name"] = "bloc4builder:box_rainbow_midslim"}, {["x"] = 10, ["param2"] = 3, ["y"] = 6, ["param1"] = 153, ["z"] = 4, ["name"] = "bloc4builder:box_rainbow_midslim"}, {["x"] = 10, ["param2"] = 3, ["y"] = 6, ["param1"] = 170, ["z"] = 5, ["name"] = "bloc4builder:box_rainbow_midslim"}, {["x"] = 10, ["y"] = 6, ["param1"] = 187, ["z"] = 6, ["name"] = "bloc4builder:slab_rainbow_three_sides_u"}, {["x"] = 10, ["param2"] = 2, ["y"] = 6, ["param1"] = 204, ["z"] = 7, ["name"] = "bloc4builder:ladder"}, {["x"] = 10, ["y"] = 6, ["param1"] = 158, ["z"] = 10, ["name"] = "moreblocks:box_obsidian_glass_midslim"}, {["x"] = 10, ["param2"] = 7, ["y"] = 6, ["param1"] = 206, ["z"] = 14, ["name"] = "moreblocks:slab_obsidian_glass_1"}, {["x"] = 10, ["param2"] = 224, ["y"] = 7, ["z"] = 0, ["name"] = "bloc4builder:rainbow"}, {["x"] = 10, ["param2"] = 3, ["y"] = 7, ["param1"] = 120, ["z"] = 2, ["name"] = "bloc4builder:box_rainbow_tslim"}, {["x"] = 10, ["param2"] = 3, ["y"] = 7, ["param1"] = 136, ["z"] = 3, ["name"] = "bloc4builder:box_rainbow_midslim"}, {["x"] = 10, ["param2"] = 3, ["y"] = 7, ["param1"] = 136, ["z"] = 4, ["name"] = "bloc4builder:box_rainbow_midslim"}, {["x"] = 10, ["param2"] = 3, ["y"] = 7, ["param1"] = 153, ["z"] = 5, ["name"] = "bloc4builder:box_rainbow_midslim"}, {["x"] = 10, ["param2"] = 22, ["y"] = 7, ["param1"] = 170, ["z"] = 6, ["name"] = "bloc4builder:slab_rainbow_three_sides_u"}, {["x"] = 10, ["param2"] = 2, ["y"] = 7, ["param1"] = 187, ["z"] = 7, ["name"] = "bloc4builder:ladder"}, {["x"] = 10, ["meta"] = {["fields"] = {["spacengine"] = "^O¨64¨0¨^aG0bf0bM0¨1¨^A", ["channel"] = "linxx:singleplayer", ["text"] = "(2(b(c1(b23______)(cPUISSAN | (p(3?OXYGENE@(1_(iG(f(3?ON=@) | (2(fR(1(KRRPPP(2_(c:(1(fPP(kP(kP(hP | (1(j&(fPP(kP(kP(hP)(d1 | (oNb 1/(fS 50", ["pos_cont"] = "(1,0,3)"}, ["inventory"] = {}}, ["y"] = 7, ["param1"] = 142, ["z"] = 10, ["name"] = "monitor:screen_transparent"}, {["x"] = 10, ["param2"] = 7, ["y"] = 7, ["param1"] = 206, ["z"] = 14, ["name"] = "moreblocks:slab_obsidian_glass_1"}, {["x"] = 10, ["param2"] = 32, ["y"] = 8, ["z"] = 0, ["name"] = "bloc4builder:rainbow"}, {["x"] = 10, ["param2"] = 1, ["y"] = 8, ["param1"] = 154, ["z"] = 1, ["name"] = "bloc4builder:stair_rainbow_alt"}, {["x"] = 10, ["param2"] = 1, ["y"] = 8, ["z"] = 2, ["name"] = "bloc4builder:rainbow"}, {["x"] = 10, ["param2"] = 7, ["y"] = 8, ["param1"] = 153, ["z"] = 3, ["name"] = "bloc4builder:box_rainbow_tslim"}, {["x"] = 10, ["param2"] = 7, ["y"] = 8, ["param1"] = 153, ["z"] = 4, ["name"] = "bloc4builder:box_rainbow_tslim"}, {["x"] = 10, ["param2"] = 3, ["y"] = 8, ["z"] = 5, ["name"] = "bloc4builder:rainbow"}, {["x"] = 10, ["param2"] = 2, ["y"] = 8, ["z"] = 6, ["name"] = "bloc4builder:rainbow"}, {["x"] = 10, ["param2"] = 2, ["y"] = 8, ["param1"] = 172, ["z"] = 7, ["name"] = "bloc4builder:ladder"}, {["x"] = 10, ["param2"] = 86, ["y"] = 8, ["param1"] = 157, ["z"] = 8, ["name"] = "bloc4builder:slab_rainbow_1"}, {["x"] = 10, ["param2"] = 86, ["y"] = 8, ["param1"] = 142, ["z"] = 9, ["name"] = "bloc4builder:slab_rainbow_1"}, {["x"] = 10, ["param2"] = 76, ["y"] = 8, ["param1"] = 126, ["z"] = 10, ["name"] = "bloc4builder:box_rainbow_tslim"}, {["x"] = 10, ["meta"] = {["fields"] = {["spacengine"] = "^C¨64¨0¨^bC0bJ0bM0aa0bi0¨1", ["channel"] = "linxx:singleplayer", ["text"] = "(2(b(c1(b2345____)(c(1;)ON(1:)OFF | (P(3?CONTROLER@)(1(kq)(q030% | (2(df(to(df(h(1_'a_)(h(1%a_)(h(1`a_)(f (2:(1g) | (r(1x)(f000%(c(1_v)X19Y15Z15 | (1(kV)(h(2`)OVER(l(14$)0004381", ["pos_cont"] = "(1,1,6)"}, ["inventory"] = {}}, ["y"] = 8, ["param1"] = 174, ["z"] = 13, ["name"] = "monitor:screen_up"}, {["x"] = 10, ["param2"] = 246, ["y"] = 8, ["param1"] = 190, ["z"] = 14, ["name"] = "bloc4builder:slope_white"}, {["x"] = 10, ["param2"] = 32, ["y"] = 9, ["z"] = 0, ["name"] = "bloc4builder:rainbow"}, {["x"] = 10, ["param2"] = 9, ["y"] = 9, ["param1"] = 171, ["z"] = 1, ["name"] = "bloc4builder:slab_rainbow_1"}, {["x"] = 10, ["y"] = 9, ["z"] = 2, ["name"] = "default:dirt"}, {["x"] = 10, ["y"] = 9, ["z"] = 3, ["name"] = "default:dirt"}, {["x"] = 10, ["y"] = 9, ["z"] = 4, ["name"] = "default:dirt"}, {["x"] = 10, ["param2"] = 9, ["y"] = 9, ["param1"] = 156, ["z"] = 6, ["name"] = "bloc4builder:slab_rainbow_1"}, {["x"] = 10, ["param2"] = 2, ["y"] = 9, ["param1"] = 157, ["z"] = 7, ["name"] = "bloc4builder:ladder"}, {["x"] = 10, ["meta"] = {["fields"] = {["spacengine"] = "^C¨64¨0¨^bC0bJ0bM0aa0bi0¨1", ["channel"] = "linxx:singleplayer", ["text"] = "(2(b(c1(b2345____)(c(1;)ON(1:)OFF | (P(3?CONTROLER@)(1(kq)(q030% | (2(df(to(df(h(1_'a_)(h(1%a_)(h(1`a_)(f (2:(1g) | (r(1x)(f000%(c(1_v)X19Y15Z15 | (1(kV)(h(2`)OVER(l(14$)0004381", ["pos_cont"] = "(1,2,3)"}, ["inventory"] = {}}, ["y"] = 9, ["param1"] = 111, ["z"] = 10, ["name"] = "monitor:screen_down"}, {["x"] = 10, ["param2"] = 226, ["y"] = 9, ["param1"] = 158, ["z"] = 13, ["name"] = "bloc4builder:slope_rainbow_half_raised"}, {["x"] = 10, ["param2"] = 226, ["y"] = 9, ["param1"] = 174, ["z"] = 14, ["name"] = "bloc4builder:slope_rainbow_half"}, {["x"] = 10, ["param2"] = 224, ["y"] = 10, ["z"] = 0, ["name"] = "bloc4builder:rainbow"}, {["x"] = 10, ["param2"] = 9, ["y"] = 10, ["param1"] = 172, ["z"] = 6, ["name"] = "bloc4builder:slab_rainbow_1"}, {["x"] = 10, ["meta"] = {["fields"] = {["infotext"] = "CONTROLER on/off -- 1 --\
CONTROLER on/off -- 2 --\
CONTROLER on/off -- 3 --\
