5:return {{["x"] = 0, ["param2"] = 23, ["y"] = 1, ["param1"] = 142, ["z"] = 1, ["name"] = "bloc4builder:slope_army"}, {["x"] = 0, ["param2"] = 23, ["y"] = 1, ["param1"] = 126, ["z"] = 2, ["name"] = "bloc4builder:slope_army"}, {["x"] = 0, ["param2"] = 23, ["y"] = 1, ["param1"] = 142, ["z"] = 3, ["name"] = "bloc4builder:slope_army"}, {["x"] = 0, ["param2"] = 23, ["y"] = 1, ["param1"] = 158, ["z"] = 4, ["name"] = "bloc4builder:slope_army"}, {["x"] = 0, ["param2"] = 23, ["y"] = 1, ["param1"] = 174, ["z"] = 5, ["name"] = "bloc4builder:slope_army"}, {["x"] = 0, ["param2"] = 6, ["y"] = 1, ["param1"] = 190, ["z"] = 6, ["name"] = "bloc4builder:mesh_road_neutre_fuse5"}, {["x"] = 0, ["param2"] = 6, ["y"] = 1, ["param1"] = 206, ["z"] = 7, ["name"] = "bloc4builder:mesh_road_neutre_fuse6"}, {["x"] = 0, ["y"] = 2, ["z"] = 1, ["name"] = "bloc4builder:army"}, {["x"] = 0, ["y"] = 2, ["param1"] = 142, ["z"] = 2, ["name"] = "bloc4builder:building_glass"}, {["x"] = 0, ["y"] = 2, ["z"] = 3, ["name"] = "bloc4builder:army"}, {["x"] = 0, ["y"] = 2, ["param1"] = 174, ["z"] = 4, ["name"] = "bloc4builder:building_glass"}, {["x"] = 0, ["y"] = 2, ["z"] = 5, ["name"] = "bloc4builder:army"}, {["x"] = 0, ["param2"] = 18, ["y"] = 2, ["param1"] = 206, ["z"] = 6, ["name"] = "bloc4builder:slope_road_neutre_half_raised"}, {["x"] = 0, ["param2"] = 18, ["y"] = 2, ["param1"] = 222, ["z"] = 7, ["name"] = "bloc4builder:slope_road_neutre_half"}, {["x"] = 0, ["y"] = 3, ["z"] = 1, ["name"] = "bloc4builder:army"}, {["x"] = 0, ["y"] = 3, ["z"] = 2, ["name"] = "bloc4builder:army"}, {["x"] = 0, ["y"] = 3, ["z"] = 3, ["name"] = "bloc4builder:army"}, {["x"] = 0, ["y"] = 3, ["z"] = 4, ["name"] = "bloc4builder:army"}, {["x"] = 0, ["y"] = 3, ["z"] = 5, ["name"] = "bloc4builder:army"}, {["x"] = 0, ["param2"] = 18, ["y"] = 3, ["param1"] = 206, ["z"] = 6, ["name"] = "bloc4builder:slope_road_neutre_half_raised"}, {["x"] = 0, ["param2"] = 18, ["y"] = 3, ["param1"] = 222, ["z"] = 7, ["name"] = "bloc4builder:slope_road_neutre_half"}, {["x"] = 0, ["param2"] = 1, ["y"] = 4, ["param1"] = 142, ["z"] = 1, ["name"] = "bloc4builder:slope_army"}, {["x"] = 0, ["param2"] = 1, ["y"] = 4, ["param1"] = 158, ["z"] = 2, ["name"] = "bloc4builder:slope_army"}, {["x"] = 0, ["param2"] = 1, ["y"] = 4, ["param1"] = 142, ["z"] = 3, ["name"] = "bloc4builder:slope_army"}, {["x"] = 0, ["param2"] = 1, ["y"] = 4, ["param1"] = 158, ["z"] = 4, ["name"] = "bloc4builder:slope_army"}, {["x"] = 0, ["param2"] = 1, ["y"] = 4, ["param1"] = 174, ["z"] = 5, ["name"] = "bloc4builder:slope_army"}, {["x"] = 0, ["param2"] = 5, ["y"] = 4, ["param1"] = 190, ["z"] = 6, ["name"] = "bloc4builder:mesh_road_neutre_fuse5"}, {["x"] = 0, ["param2"] = 5, ["y"] = 4, ["param1"] = 206, ["z"] = 7, ["name"] = "bloc4builder:mesh_road_neutre_fuse6"}, {["x"] = 1, ["param2"] = 23, ["y"] = 0, ["param1"] = 141, ["z"] = 1, ["name"] = "bloc4builder:slope_army_half"}, {["x"] = 1, ["param2"] = 23, ["y"] = 0, ["param1"] = 125, ["z"] = 2, ["name"] = "bloc4builder:slope_army_half"}, {["x"] = 1, ["param2"] = 23, ["y"] = 0, ["param1"] = 141, ["z"] = 3, ["name"] = "bloc4builder:slope_army_half"}, {["x"] = 1, ["param2"] = 23, ["y"] = 0, ["param1"] = 157, ["z"] = 4, ["name"] = "bloc4builder:slope_army_half"}, {["x"] = 1, ["param2"] = 23, ["y"] = 0, ["param1"] = 173, ["z"] = 5, ["name"] = "bloc4builder:slope_army_half"}, {["x"] = 1, ["param2"] = 9, ["y"] = 1, ["param1"] = 142, ["z"] = 0, ["name"] = "bloc4builder:slab_army_1"}, {["x"] = 1, ["meta"] = {["fields"] = {["spacengine"] = "^C¨200¨0¨5000", ["channel"] = "pirate:singleplayer", ["formspec"] = "size [9,10]bgcolor[#080808BB;true]list[current_name;storage;3,1.5;2,2;]list[current_player;main;0.5,6.5;8,4;]", ["infotext"] = "Container 5000Kg", ["pos_cont"] = "(-4,-4,-4)"}, ["inventory"] = {["main"] = {"", "", "", "", "", "", "", "", "", "", "", "", "", "", "", "", "", "", "", "", "", "", "", "", "", "", "", "", "", "", "", ""}, ["storage"] = {"", "", "", ""}}}, ["param2"] = 2, ["y"] = 1, ["z"] = 1, ["name"] = "spacengine:container3"}, {["x"] = 1, ["param2"] = 9, ["y"] = 1, ["param1"] = 189, ["z"] = 5, ["name"] = "bloc4builder:slab_army_1"}, {["x"] = 1, ["param2"] = 22, ["y"] = 1, ["param1"] = 205, ["z"] = 6, ["name"] = "bloc4builder:slope_road_neutre_half_raised"}, {["x"] = 1, ["param2"] = 22, ["y"] = 1, ["param1"] = 221, ["z"] = 7, ["name"] = "bloc4builder:slope_road_neutre_half"}, {["x"] = 1, ["param2"] = 13, ["y"] = 2, ["param1"] = 142, ["z"] = 1, ["name"] = "bloc4builder:slope_black_inner_cut"}, {["x"] = 1, ["param2"] = 22, ["y"] = 2, ["param1"] = 157, ["z"] = 2, ["name"] = "bloc4builder:slab_black_1"}, {["x"] = 1, ["param2"] = 21, ["y"] = 2, ["param1"] = 172, ["z"] = 3, ["name"] = "bloc4builder:slab_black_1"}, {["x"] = 1, ["y"] = 2, ["param1"] = 238, ["z"] = 7, ["name"] = "default:meselamp"}, {["x"] = 1, ["param2"] = 7, ["y"] = 2, ["param1"] = 222, ["z"] = 8, ["name"] = "bloc4builder:box_grille_colroundtop"}, {["x"] = 1, ["param2"] = 7, ["y"] = 2, ["param1"] = 206, ["z"] = 9, ["name"] = "bloc4builder:box_grille_colroundtop"}, {["x"] = 1, ["param2"] = 12, ["y"] = 3, ["param1"] = 142, ["z"] = 1, ["name"] = "bloc4builder:slope_black"}, {["x"] = 1, ["param2"] = 7, ["y"] = 3, ["param1"] = 188, ["z"] = 4, ["name"] = "moreblocks:slab_obsidian_glass_1"}, {["x"] = 1, ["y"] = 3, ["param1"] = 238, ["z"] = 7, ["name"] = "default:meselamp"}, {["x"] = 1, ["param2"] = 7, ["y"] = 3, ["param1"] = 222, ["z"] = 8, ["name"] = "bloc4builder:box_grille_colroundtop"}, {["x"] = 1, ["param2"] = 7, ["y"] = 3, ["param1"] = 206, ["z"] = 9, ["name"] = "bloc4builder:box_grille_colroundtop"}, {["x"] = 1, ["param2"] = 12, ["y"] = 4, ["param1"] = 158, ["z"] = 1, ["name"] = "bloc4builder:slope_black_inner_cut"}, {["x"] = 1, ["param2"] = 9, ["y"] = 4, ["param1"] = 189, ["z"] = 5, ["name"] = "bloc4builder:slab_army_1"}, {["x"] = 1, ["param2"] = 2, ["y"] = 4, ["param1"] = 206, ["z"] = 6, ["name"] = "bloc4builder:slope_road_neutre_half_raised"}, {["x"] = 1, ["param2"] = 2, ["y"] = 4, ["param1"] = 222, ["z"] = 7, ["name"] = "bloc4builder:slope_road_neutre_half"}, {["x"] = 1, ["param2"] = 1, ["y"] = 5, ["param1"] = 174, ["z"] = 1, ["name"] = "bloc4builder:slope_army_half"}, {["x"] = 1, ["param2"] = 1, ["y"] = 5, ["param1"] = 190, ["z"] = 2, ["name"] = "bloc4builder:slope_army_half"}, {["x"] = 1, ["param2"] = 1, ["y"] = 5, ["param1"] = 174, ["z"] = 3, ["name"] = "bloc4builder:slope_army_half"}, {["x"] = 1, ["param2"] = 1, ["y"] = 5, ["param1"] = 158, ["z"] = 4, ["name"] = "bloc4builder:slope_army_half"}, {["x"] = 1, ["param2"] = 1, ["y"] = 5, ["param1"] = 174, ["z"] = 5, ["name"] = "bloc4builder:slope_army_half"}, {["x"] = 2, ["param2"] = 23, ["y"] = 0, ["param1"] = 125, ["z"] = 1, ["name"] = "bloc4builder:slope_army_half_raised"}, {["x"] = 2, ["param2"] = 23, ["y"] = 0, ["param1"] = 124, ["z"] = 2, ["name"] = "bloc4builder:slope_army_half_raised"}, {["x"] = 2, ["param2"] = 23, ["y"] = 0, ["param1"] = 124, ["z"] = 3, ["name"] = "bloc4builder:slope_army_half_raised"}, {["x"] = 2, ["param2"] = 23, ["y"] = 0, ["param1"] = 140, ["z"] = 4, ["name"] = "bloc4builder:slope_army_half_raised"}, {["x"] = 2, ["param2"] = 23, ["y"] = 0, ["param1"] = 156, ["z"] = 5, ["name"] = "bloc4builder:slope_army_half_raised"}, {["x"] = 2, ["param2"] = 9, ["y"] = 1, ["param1"] = 126, ["z"] = 0, ["name"] = "bloc4builder:slab_army_1"}, {["x"] = 2, ["meta"] = {["fields"] = {["infotext"] = "BATTERY Mega5", ["channel"] = "pirate:singleplayer", ["spacengine"] = "^C¨150¨0¨50000", ["pos_cont"] = "(-3,-4,-4)"}, ["inventory"] = {}}, ["param2"] = 2, ["y"] = 1, ["z"] = 1, ["name"] = "spacengine:battery"}, {["x"] = 2, ["param2"] = 9, ["y"] = 1, ["param1"] = 172, ["z"] = 5, ["name"] = "bloc4builder:slab_army_1"}, {["x"] = 2, ["param2"] = 7, ["y"] = 1, ["param1"] = 188, ["z"] = 6, ["name"] = "bloc4builder:mesh_road_neutre_fuse5"}, {["x"] = 2, ["param2"] = 7, ["y"] = 1, ["param1"] = 205, ["z"] = 7, ["name"] = "bloc4builder:mesh_road_neutre_fuse6"}, {["x"] = 2, ["y"] = 2, ["param1"] = 141, ["z"] = 1, ["name"] = "bloc4builder:slope_black"}, {["x"] = 2, ["param2"] = 22, ["y"] = 2, ["param1"] = 156, ["z"] = 2, ["name"] = "bloc4builder:slab_black_1"}, {["x"] = 2, ["param2"] = 21, ["y"] = 2, ["param1"] = 155, ["z"] = 3, ["name"] = "bloc4builder:slab_black_1"}, {["x"] = 2, ["param2"] = 9, ["y"] = 2, ["param1"] = 187, ["z"] = 5, ["name"] = "bloc4builder:slab_army_1"}, {["x"] = 2, ["param2"] = 14, ["y"] = 2, ["param1"] = 204, ["z"] = 6, ["name"] = "bloc4builder:slope_road_neutre_half_raised"}, {["x"] = 2, ["param2"] = 14, ["y"] = 2, ["param1"] = 221, ["z"] = 7, ["name"] = "bloc4builder:slope_road_neutre_half"}, {["x"] = 2, ["meta"] = {["fields"] = {["infotext"] = "Rocket", ["channel"] = "pirate:singleplayer", ["spacengine"] = "^A¨75¨0¨10¨50¨50¨500", ["pos_cont"] = "(-3,-2,-3)"}, ["inventory"] = {}}, ["param2"] = 2, ["y"] = 3, ["z"] = 2, ["name"] = "spacengine:engine"}, {["x"] = 2, ["param2"] = 7, ["y"] = 3, ["param1"] = 171, ["z"] = 4, ["name"] = "moreblocks:slab_obsidian_glass_1"}, {["x"] = 2, ["param2"] = 9, ["y"] = 3, ["param1"] = 187, ["z"] = 5, ["name"] = "bloc4builder:slab_army_1"}, {["x"] = 2, ["param2"] = 14, ["y"] = 3, ["param1"] = 204, ["z"] = 6, ["name"] = "bloc4builder:slope_road_neutre_half_raised"}, {["x"] = 2, ["param2"] = 14, ["y"] = 3, ["param1"] = 221, ["z"] = 7, ["name"] = "bloc4builder:slope_road_neutre_half"}, {["x"] = 2, ["param2"] = 20, ["y"] = 4, ["param1"] = 173, ["z"] = 1, ["name"] = "bloc4builder:slope_black"}, {["x"] = 2, ["meta"] = {["fields"] = {["infotext"] = "Generateur Hydrogene", ["channel"] = "pirate:singleplayer", ["spacengine"] = "2¨150¨0¨500¨^spacengine:hydrogene_tank¨^battery¨15¨1¨9¨500", ["pos_cont"] = "(-3,-1,-3)"}, ["inventory"] = {}}, ["param2"] = 2, ["y"] = 4, ["param1"] = 188, ["z"] = 2, ["name"] = "spacengine:power"}, {["x"] = 2, ["param2"] = 9, ["y"] = 4, ["param1"] = 172, ["z"] = 5, ["name"] = "bloc4builder:slab_army_1"}, {["x"] = 2, ["param2"] = 4, ["y"] = 4, ["param1"] = 189, ["z"] = 6, ["name"] = "bloc4builder:mesh_road_neutre_fuse5"}, {["x"] = 2, ["param2"] = 4, ["y"] = 4, ["param1"] = 206, ["z"] = 7, ["name"] = "bloc4builder:mesh_road_neutre_fuse6"}, {["x"] = 2, ["param2"] = 1, ["y"] = 5, ["param1"] = 189, ["z"] = 1, ["name"] = "bloc4builder:slope_army_half_raised"}, {["x"] = 2, ["param2"] = 1, ["y"] = 5, ["param1"] = 205, ["z"] = 2, ["name"] = "bloc4builder:slope_army_half_raised"}, {["x"] = 2, ["param2"] = 1, ["y"] = 5, ["param1"] = 189, ["z"] = 3, ["name"] = "bloc4builder:slope_army_half_raised"}, {["x"] = 2, ["param2"] = 1, ["y"] = 5, ["param1"] = 173, ["z"] = 4, ["name"] = "bloc4builder:slope_army_half_raised"}, {["x"] = 2, ["param2"] = 1, ["y"] = 5, ["param1"] = 157, ["z"] = 5, ["name"] = "bloc4builder:slope_army_half_raised"}, {["x"] = 2, ["param2"] = 18, ["y"] = 6, ["param1"] = 173, ["z"] = 1, ["name"] = "bloc4builder:slab_army_1"}, {["x"] = 2, ["param2"] = 18, ["y"] = 6, ["param1"] = 190, ["z"] = 2, ["name"] = "bloc4builder:slab_army_1"}, {["x"] = 2, ["param2"] = 18, ["y"] = 6, ["param1"] = 174, ["z"] = 3, ["name"] = "bloc4builder:slab_army_1"}, {["x"] = 2, ["param2"] = 18, ["y"] = 6, ["param1"] = 158, ["z"] = 4, ["name"] = "bloc4builder:slab_army_1"}, {["x"] = 2, ["param2"] = 18, ["y"] = 7, ["param1"] = 158, ["z"] = 1, ["name"] = "bloc4builder:slab_army_1"}, {["x"] = 2, ["param2"] = 18, ["y"] = 7, ["param1"] = 174, ["z"] = 2, ["name"] = "bloc4builder:slab_army_1"}, {["x"] = 2, ["param2"] = 18, ["y"] = 7, ["param1"] = 158, ["z"] = 3, ["name"] = "bloc4builder:slab_army_1"}, {["x"] = 2, ["param2"] = 18, ["y"] = 7, ["param1"] = 142, ["z"] = 4, ["name"] = "bloc4builder:slab_army_1"}, {["x"] = 2, ["meta"] = {["fields"] = {["infotext"] = "LASER", ["channel"] = "pirate:singleplayer", ["spacengine"] = "^A¨100¨0¨750¨20¨5¨2", ["pos_cont"] = "(-3,2,0)"}, ["inventory"] = {}}, ["param2"] = 18, ["y"] = 7, ["param1"] = 126, ["z"] = 5, ["name"] = "spacengine:weapons"}, {["x"] = 3, ["y"] = 0, ["z"] = 1, ["name"] = "bloc4builder:army"}, {["x"] = 3, ["y"] = 0, ["z"] = 2, ["name"] = "bloc4builder:army"}, {["x"] = 3, ["y"] = 0, ["z"] = 3, ["name"] = "bloc4builder:army"}, {["x"] = 3, ["y"] = 0, ["z"] = 4, ["name"] = "bloc4builder:army"}, {["x"] = 3, ["y"] = 0, ["z"] = 5, ["name"] = "bloc4builder:army"}, {["x"] = 3, ["param2"] = 22, ["y"] = 0, ["param1"] = 155, ["z"] = 6, ["name"] = "bloc4builder:slope_army_half_raised"}, {["x"] = 3, ["param2"] = 22, ["y"] = 0, ["param1"] = 172, ["z"] = 7, ["name"] = "bloc4builder:slope_army_half"}, {["x"] = 3, ["meta"] = {["fields"] = {["infotext"] = "LASER", ["channel"] = "pirate:singleplayer", ["spacengine"] = "^A¨100¨0¨750¨20¨5¨2", ["pos_cont"] = "(-2,-5,3)"}, ["inventory"] = {}}, ["param2"] = 23, ["y"] = 0, ["param1"] = 157, ["z"] = 8, ["name"] = "spacengine:weapons"}, {["x"] = 3, ["param2"] = 9, ["y"] = 1, ["param1"] = 126, ["z"] = 0, ["name"] = "bloc4builder:slab_army_1"}, {["x"] = 3, ["meta"] = {["fields"] = {["infotext"] = "Gforce MOON", ["channel"] = "pirate:singleplayer", ["spacengine"] = "^A¨100¨0¨4", ["pos_cont"] = "(-2,-4,-4)"}, ["inventory"] = {}}, ["param2"] = 2, ["y"] = 1, ["z"] = 1, ["name"] = "spacengine:gravitation"}, {["x"] = 3, ["y"] = 1, ["z"] = 6, ["name"] = "bloc4builder:army"}, {["x"] = 3, ["y"] = 1, ["z"] = 7, ["name"] = "bloc4builder:army"}, {["x"] = 3, ["y"] = 1, ["z"] = 8, ["name"] = "bloc4builder:army"}, {["x"] = 3, ["param2"] = 22, ["y"] = 1, ["param1"] = 158, ["z"] = 9, ["name"] = "bloc4builder:slope_army_half_raised"}, {["x"] = 3, ["param2"] = 22, ["y"] = 1, ["param1"] = 142, ["z"] = 10, ["name"] = "bloc4builder:slope_army_half"}, {["x"] = 3, ["param2"] = 16, ["y"] = 2, ["param1"] = 158, ["z"] = 1, ["name"] = "bloc4builder:slope_black_inner_cut"}, {["x"] = 3, ["param2"] = 22, ["y"] = 2, ["param1"] = 173, ["z"] = 2, ["name"] = "bloc4builder:slab_black_1"}, {["x"] = 3, ["param2"] = 21, ["y"] = 2, ["param1"] = 156, ["z"] = 3, ["name"] = "bloc4builder:slab_black_1"}, {["x"] = 3, ["param2"] = 9, ["y"] = 2, ["param1"] = 172, ["z"] = 5, ["name"] = "bloc4builder:slab_army_1"}, {["x"] = 3, ["y"] = 2, ["z"] = 6, ["name"] = "bloc4builder:army"}, {["x"] = 3, ["y"] = 2, ["z"] = 7, ["name"] = "bloc4builder:army"}, {["x"] = 3, ["param2"] = 13, ["y"] = 2, ["param1"] = 189, ["z"] = 8, ["name"] = "bloc4builder:slope_white_half_raised"}, {["x"] = 3, ["param2"] = 13, ["y"] = 2, ["param1"] = 174, ["z"] = 9, ["name"] = "bloc4builder:slope_white_half_raised"}, {["x"] = 3, ["param2"] = 2, ["y"] = 2, ["param1"] = 158, ["z"] = 10, ["name"] = "bloc4builder:slope_white_inner_cut"}, {["x"] = 3, ["param2"] = 16, ["y"] = 3, ["param1"] = 174, ["z"] = 1, ["name"] = "bloc4builder:slope_black"}, {["x"] = 3, ["param2"] = 7, ["y"] = 3, ["param1"] = 155, ["z"] = 4, ["name"] = "moreblocks:slab_obsidian_glass_1"}, {["x"] = 3, ["param2"] = 9, ["y"] = 3, ["param1"] = 172, ["z"] = 5, ["name"] = "bloc4builder:slab_army_1"}, {["x"] = 3, ["param2"] = 18, ["y"] = 3, ["param1"] = 189, ["z"] = 6, ["name"] = "bloc4builder:slab_army"}, {["x"] = 3, ["param2"] = 18, ["y"] = 3, ["param1"] = 206, ["z"] = 7, ["name"] = "bloc4builder:slab_army"}, {["x"] = 3, ["meta"] = {["fields"] = {["spacengine"] = "^S¨64¨0¨^aB0bM0¨1", ["channel"] = "pirate:singleplayer", ["text"] = "(2(b(c1(b2_______)(cPUISSAN | (p(3?SHIELD@)(h (3?OFF@) | (n(1A)(f000% | (d(1`)01250 / (c01250 | (2(eRQ)003", ["pos_cont"] = "(-2,-2,3)"}, ["inventory"] = {}}, ["param2"] = 3, ["y"] = 3, ["param1"] = 190, ["z"] = 8, ["name"] = "monitor:screen_transparent"}, {["x"] = 3, ["param2"] = 1, ["y"] = 3, ["param1"] = 174, ["z"] = 9, ["name"] = "moreblocks:box_obsidian_glass_midslim"}, {["x"] = 3, ["param2"] = 2, ["y"] = 3, ["param1"] = 158, ["z"] = 10, ["name"] = "moreblocks:mesh_obsidian_glass_fuse3"}, {["x"] = 3, ["param2"] = 17, ["y"] = 4, ["param1"] = 190, ["z"] = 1, ["name"] = "bloc4builder:slope_black_inner_cut"}, {["x"] = 3, ["param2"] = 9, ["y"] = 4, ["param1"] = 156, ["z"] = 5, ["name"] = "bloc4builder:slab_army_1"}, {["x"] = 3, ["param2"] = 18, ["y"] = 4, ["param1"] = 173, ["z"] = 6, ["name"] = "bloc4builder:slab_army"}, {["x"] = 3, ["param2"] = 18, ["y"] = 4, ["param1"] = 190, ["z"] = 7, ["name"] = "bloc4builder:slab_army"}, {["x"] = 3, ["param2"] = 21, ["y"] = 4, ["param1"] = 174, ["z"] = 8, ["name"] = "bloc4builder:mesh_black_fuse4"}, {["x"] = 3, ["param2"] = 21, ["y"] = 4, ["param1"] = 158, ["z"] = 9, ["name"] = "bloc4builder:mesh_black_fuse4"}, {["x"] = 3, ["param2"] = 2, ["y"] = 4, ["param1"] = 142, ["z"] = 10, ["name"] = "bloc4builder:mesh_black_fuse6"}, {["x"] = 3, ["y"] = 5, ["z"] = 1, ["name"] = "bloc4builder:army"}, {["x"] = 3, ["param2"] = 7, ["y"] = 5, ["param1"] = 221, ["z"] = 2, ["name"] = "bloc4builder:light_on"}, {["x"] = 3, ["param2"] = 21, ["y"] = 5, ["param1"] = 204, ["z"] = 3, ["name"] = "bloc4builder:slab_black_1"}, {["x"] = 3, ["param2"] = 21, ["y"] = 5, ["param1"] = 188, ["z"] = 4, ["name"] = "bloc4builder:slab_black_1"}, {["x"] = 3, ["param2"] = 9, ["y"] = 5, ["param1"] = 172, ["z"] = 5, ["name"] = "bloc4builder:slab_army_1"}, {["x"] = 3, ["param2"] = 18, ["y"] = 5, ["param1"] = 157, ["z"] = 6, ["name"] = "bloc4builder:slab_army"}, {["x"] = 3, ["param2"] = 18, ["y"] = 5, ["param1"] = 174, ["z"] = 7, ["name"] = "bloc4builder:slab_army"}, {["x"] = 3, ["param2"] = 18, ["y"] = 5, ["param1"] = 159, ["z"] = 8, ["name"] = "moreblocks:slab_obsidian_glass_1"}, {["x"] = 3, ["y"] = 6, ["z"] = 1, ["name"] = "bloc4builder:army"}, {["x"] = 3, ["y"] = 6, ["z"] = 2, ["name"] = "bloc4builder:army"}, {["x"] = 3, ["y"] = 6, ["z"] = 5, ["name"] = "bloc4builder:army"}, {["x"] = 3, ["param2"] = 18, ["y"] = 6, ["param1"] = 142, ["z"] = 6, ["name"] = "bloc4builder:slab_army"}, {["x"] = 3, ["param2"] = 18, ["y"] = 6, ["param1"] = 158, ["z"] = 7, ["name"] = "bloc4builder:slab_army"}, {["x"] = 3, ["y"] = 7, ["z"] = 1, ["name"] = "bloc4builder:army"}, {["x"] = 3, ["y"] = 7, ["z"] = 5, ["name"] = "bloc4builder:army"}, {["x"] = 3, ["param2"] = 18, ["y"] = 7, ["param1"] = 127, ["z"] = 6, ["name"] = "moreblocks:slab_obsidian_glass_1"}, {["x"] = 3, ["param2"] = 1, ["y"] = 8, ["param1"] = 174, ["z"] = 1, ["name"] = "bloc4builder:slope_army"}, {["x"] = 3, ["param2"] = 1, ["y"] = 8, ["param1"] = 190, ["z"] = 2, ["name"] = "bloc4builder:slope_army"}, {["x"] = 3, ["param2"] = 1, ["y"] = 8, ["param1"] = 174, ["z"] = 3, ["name"] = "bloc4builder:slope_army"}, {["x"] = 3, ["param2"] = 1, ["y"] = 8, ["param1"] = 158, ["z"] = 4, ["name"] = "bloc4builder:slope_army"}, {["x"] = 3, ["param2"] = 1, ["y"] = 8, ["param1"] = 142, ["z"] = 5, ["name"] = "bloc4builder:slope_army"}, {["x"] = 4, ["y"] = 0, ["z"] = 1, ["name"] = "bloc4builder:army"}, {["x"] = 4, ["y"] = 0, ["z"] = 2, ["name"] = "bloc4builder:army"}, {["x"] = 4, ["y"] = 0, ["z"] = 3, ["name"] = "bloc4builder:army"}, {["x"] = 4, ["y"] = 0, ["z"] = 4, ["name"] = "bloc4builder:army"}, {["x"] = 4, ["y"] = 0, ["z"] = 5, ["name"] = "bloc4builder:army"}, {["x"] = 4, ["param2"] = 22, ["y"] = 0, ["param1"] = 140, ["z"] = 6, ["name"] = "bloc4builder:slope_army_half_raised"}, {["x"] = 4, ["param2"] = 22, ["y"] = 0, ["param1"] = 157, ["z"] = 7, ["name"] = "bloc4builder:slope_army_half"}, {["x"] = 4, ["param2"] = 9, ["y"] = 1, ["param1"] = 126, ["z"] = 0, ["name"] = "bloc4builder:slab_army_1"}, {["x"] = 4, ["y"] = 1, ["z"] = 1, ["name"] = "bloc4builder:army"}, {["x"] = 4, ["meta"] = {["fields"] = {["owner"] = "singleplayer", ["channel"] = "pirate"}, ["inventory"] = {}}, ["param2"] = 2, ["y"] = 1, ["param1"] = 139, ["z"] = 2, ["name"] = "bloc4builder:keypad"}, {["x"] = 4, ["y"] = 1, ["param1"] = 158, ["z"] = 7, ["name"] = "bloc4builder:stair_army"}, {["x"] = 4, ["y"] = 1, ["z"] = 8, ["name"] = "bloc4builder:army"}, {["x"] = 4, ["param2"] = 22, ["y"] = 1, ["param1"] = 141, ["z"] = 9, ["name"] = "bloc4builder:slope_army_half_raised"}, {["x"] = 4, ["param2"] = 22, ["y"] = 1, ["param1"] = 126, ["z"] = 10, ["name"] = "bloc4builder:slope_army_half"}, {["x"] = 4, ["param2"] = 9, ["y"] = 2, ["param1"] = 126, ["z"] = 0, ["name"] = "bloc4builder:slab_army_1"}, {["x"] = 4, ["y"] = 2, ["z"] = 1, ["name"] = "bloc4builder:army"}, {["x"] = 4, ["param2"] = 22, ["y"] = 2, ["param1"] = 156, ["z"] = 2, ["name"] = "bloc4builder:slab_black_1"}, {["x"] = 4, ["param2"] = 23, ["y"] = 2, ["param1"] = 139, ["z"] = 3, ["name"] = "bloc4builder:slab_black_1"}, {["x"] = 4, ["param2"] = 3, ["y"] = 2, ["param1"] = 174, ["z"] = 8, ["name"] = "bloc4builder:slab_army_1"}, {["x"] = 4, ["y"] = 2, ["param1"] = 158, ["z"] = 9, ["name"] = "bloc4builder:slab_army_1"}, {["x"] = 4, ["param2"] = 10, ["y"] = 2, ["param1"] = 142, ["z"] = 10, ["name"] = "bloc4builder:slope_white_half_raised"}, {["x"] = 4, ["param2"] = 9, ["y"] = 3, ["param1"] = 142, ["z"] = 0, ["name"] = "bloc4builder:slab_army_1"}, {["x"] = 4, ["y"] = 3, ["z"] = 1, ["name"] = "bloc4builder:army"}, {["x"] = 4, ["param2"] = 7, ["y"] = 3, ["param1"] = 140, ["z"] = 4, ["name"] = "moreblocks:slab_obsidian_glass_1"}, {["x"] = 4, ["meta"] = {["fields"] = {["infotext"] = "CONTROLER on/off", ["channel"] = "pirate:singleplayer", ["spacengine"] = "^b¨0¨0¨^bC0¨1¨^", ["pos_cont"] = "(-1,-2,2)"}, ["inventory"] = {}}, ["param2"] = 3, ["y"] = 3, ["param1"] = 191, ["z"] = 7, ["name"] = "spacengine:switch_emergency"}, {["x"] = 4, ["meta"] = {["fields"] = {["spacengine"] = "^W¨64¨0¨^bF0aC0aD1aI0bM0¨2", ["channel"] = "pirate:singleplayer", ["text"] = "(2(b1(c2(b345____)(cPUISSAN | (p (3?WEAPONS@) (fREADY! | (1(hp)(q008%(l(1_%)005 (d(1v)002 | (1(g*G)05208U(1_(mwA)000 | (e(2_Q)0000/0005", ["pos_cont"] = "(-1,-2,5)"}, ["inventory"] = {}}, ["y"] = 3, ["param1"] = 143, ["z"] = 10, ["name"] = "monitor:screen_transparent"}, {["x"] = 4, ["param2"] = 9, ["y"] = 4, ["param1"] = 158, ["z"] = 0, ["name"] = "bloc4builder:slab_army_1"}, {["x"] = 4, ["y"] = 4, ["z"] = 1, ["name"] = "bloc4builder:army"}, {["x"] = 4, ["meta"] = {["fields"] = {["infotext"] = "ENGINE PUISSANCE", ["channel"] = "pirate:singleplayer", ["spacengine"] = "^a¨0¨0¨^aA0¨1¨^", ["pos_cont"] = "(-1,-1,2)"}, ["inventory"] = {}}, ["param2"] = 3, ["y"] = 4, ["param1"] = 175, ["z"] = 7, ["name"] = "spacengine:analog00"}, {["x"] = 4, ["param2"] = 20, ["y"] = 4, ["param1"] = 127, ["z"] = 10, ["name"] = "moreblocks:mesh_obsidian_glass_fuse4"}, {["x"] = 4, ["param2"] = 9, ["y"] = 5, ["param1"] = 142, ["z"] = 0, ["name"] = "bloc4builder:slab_army_1"}, {["x"] = 4, ["y"] = 5, ["z"] = 1, ["name"] = "bloc4builder:army"}, {["x"] = 4, ["param2"] = 21, ["y"] = 5, ["param1"] = 204, ["z"] = 2, ["name"] = "bloc4builder:slab_black_1"}, {["x"] = 4, ["param2"] = 20, ["y"] = 5, ["param1"] = 187, ["z"] = 3, ["name"] = "bloc4builder:slab_black_1"}, {["x"] = 4, ["param2"] = 20, ["y"] = 5, ["param1"] = 172, ["z"] = 4, ["name"] = "bloc4builder:slab_black_1"}, {["x"] = 4, ["param2"] = 20, ["y"] = 5, ["param1"] = 157, ["z"] = 5, ["name"] = "bloc4builder:slab_black_1"}, {["x"] = 4, ["param2"] = 20, ["y"] = 5, ["param1"] = 142, ["z"] = 6, ["name"] = "bloc4builder:slab_black_1"}, {["x"] = 4, ["meta"] = {["fields"] = {["infotext"] = "ENGINE PUISSANCE", ["channel"] = "pirate:singleplayer", ["spacengine"] = "^a¨0¨0¨^aA0¨1¨^", ["pos_cont"] = "(-1,0,3)"}, ["inventory"] = {}}, ["param2"] = 8, ["y"] = 5, ["param1"] = 143, ["z"] = 8, ["name"] = "spacengine:analog10"}, {["x"] = 4, ["param2"] = 2, ["y"] = 5, ["param1"] = 127, ["z"] = 9, ["name"] = "moreblocks:slope_obsidian_glass"}, {["x"] = 4, ["param2"] = 9, ["y"] = 6, ["param1"] = 158, ["z"] = 0, ["name"] = "bloc4builder:slab_army_1"}, {["x"] = 4, ["meta"] = {["fields"] = {["infotext"] = "ENGINE PUISSANCE", ["channel"] = "pirate:singleplayer", ["spacengine"] = "^a¨0¨0¨^aA0¨1¨^", ["pos_cont"] = "(-1,1,0)"}, ["inventory"] = {}}, ["param2"] = 3, ["y"] = 6, ["param1"] = 141, ["z"] = 5, ["name"] = "spacengine:rotator00"}, {["x"] = 4, ["meta"] = {["fields"] = {["infotext"] = "POWER ON/OFF", ["channel"] = "pirate:singleplayer", ["spacengine"] = "^i¨0¨0¨^iA0¨1¨^", ["pos_cont"] = "(-1,1,1)"}, ["inventory"] = {}}, ["param2"] = 3, ["y"] = 6, ["param1"] = 126, ["z"] = 6, ["name"] = "spacengine:inter_0"}, {["x"] = 4, ["param2"] = 20, ["y"] = 6, ["param1"] = 143, ["z"] = 7, ["name"] = "moreblocks:slope_obsidian_glass"}, {["x"] = 4, ["param2"] = 2, ["y"] = 6, ["param1"] = 127, ["z"] = 8, ["name"] = "moreblocks:slope_obsidian_glass"}, {["x"] = 4, ["param2"] = 9, ["y"] = 7, ["param1"] = 158, ["z"] = 0, ["name"] = "bloc4builder:slab_army_1"}, {["x"] = 4, ["param2"] = 2, ["y"] = 7, ["param1"] = 127, ["z"] = 7, ["name"] = "moreblocks:slope_obsidian_glass"}, {["x"] = 4, ["param2"] = 9, ["y"] = 8, ["param1"] = 174, ["z"] = 0, ["name"] = "bloc4builder:slab_army_1"}, {["x"] = 4, ["meta"] = {["fields"] = {["spacengine"] = "^P¨64¨0¨^bD0bP0bM0¨1", ["channel"] = "pirate:singleplayer", ["text"] = "(2(b(c1(b23______)(c ON/OFF | (p(3?POWER@)(f(3?ON=@) | (gGenerateur Hydro | (2(df(to(df)(f0000995 | (1(qt)00035(o/(e00100KU", ["pos_cont"] = "(-1,3,0)"}, ["inventory"] = {}}, ["y"] = 8, ["param1"] = 157, ["z"] = 5, ["name"] = "monitor:screen_up"}, {["x"] = 4, ["param2"] = 2, ["y"] = 8, ["param1"] = 142, ["z"] = 6, ["name"] = "bloc4builder:slope_black"}, {["x"] = 4, ["param2"] = 1, ["y"] = 9, ["param1"] = 174, ["z"] = 1, ["name"] = "bloc4builder:slope_army_half"}, {["x"] = 4, ["param2"] = 1, ["y"] = 9, ["param1"] = 190, ["z"] = 2, ["name"] = "bloc4builder:slope_army_half"}, {["x"] = 4, ["param2"] = 1, ["y"] = 9, ["param1"] = 173, ["z"] = 3, ["name"] = "bloc4builder:slope_army_half"}, {["x"] = 4, ["param2"] = 1, ["y"] = 9, ["param1"] = 158, ["z"] = 4, ["name"] = "bloc4builder:slope_army_half"}, {["x"] = 4, ["param2"] = 1, ["y"] = 9, ["param1"] = 141, ["z"] = 5, ["name"] = "bloc4builder:slope_army_half"}, {["x"] = 5, ["param2"] = 2, ["y"] = 0, ["param1"] = 141, ["z"] = 1, ["name"] = "bloc4builder:hub"}, {["x"] = 5, ["y"] = 0, ["z"] = 2, ["name"] = "bloc4builder:army"}, {["x"] = 5, ["y"] = 0, ["z"] = 3, ["name"] = "bloc4builder:army"}, {["x"] = 5, ["y"] = 0, ["z"] = 4, ["name"] = "bloc4builder:army"}, {["x"] = 5, ["y"] = 0, ["z"] = 5, ["name"] = "bloc4builder:army"}, {["x"] = 5, ["param2"] = 22, ["y"] = 0, ["param1"] = 155, ["z"] = 6, ["name"] = "bloc4builder:slope_army_half_raised"}, {["x"] = 5, ["param2"] = 22, ["y"] = 0, ["param1"] = 140, ["z"] = 7, ["name"] = "bloc4builder:slope_army_half"}, {["x"] = 5, ["meta"] = {["fields"] = {["infotext"] = "LASER", ["channel"] = "pirate:singleplayer", ["spacengine"] = "^A¨100¨0¨750¨20¨5¨2", ["pos_cont"] = "(0,-5,3)"}, ["inventory"] = {}}, ["param2"] = 22, ["y"] = 0, ["param1"] = 124, ["z"] = 8, ["name"] = "spacengine:weapons"}, {["x"] = 5, ["meta"] = {["fields"] = {["owner"] = "singleplayer", ["channel"] = "pirate"}, ["inventory"] = {}}, ["param2"] = 2, ["y"] = 1, ["param1"] = 125, ["z"] = 1, ["name"] = "bloc4builder:sas2"}, {["x"] = 5, ["y"] = 1, ["z"] = 5, ["name"] = "bloc4builder:electro2"}, {["x"] = 5, ["param2"] = 8, ["y"] = 1, ["z"] = 6, ["name"] = "bloc4builder:electro"}, {["x"] = 5, ["param2"] = 5, ["y"] = 1, ["z"] = 7, ["name"] = "bloc4builder:electro"}, {["x"] = 5, ["y"] = 1, ["z"] = 8, ["name"] = "bloc4builder:army"}, {["x"] = 5, ["param2"] = 22, ["y"] = 1, ["param1"] = 125, ["z"] = 9, ["name"] = "bloc4builder:slope_army_half_raised"}, {["x"] = 5, ["param2"] = 22, ["y"] = 1, ["param1"] = 110, ["z"] = 10, ["name"] = "bloc4builder:slope_army_half"}, {["x"] = 5, ["y"] = 2, ["param1"] = 125, ["z"] = 1, ["name"] = "bloc4builder:hidden"}, {["x"] = 5, ["param2"] = 22, ["y"] = 2, ["param1"] = 140, ["z"] = 2, ["name"] = "bloc4builder:slab_black_1"}, {["x"] = 5, ["param2"] = 23, ["y"] = 2, ["param1"] = 123, ["z"] = 3, ["name"] = "bloc4builder:slab_black_1"}, {["x"] = 5, ["param2"] = 2, ["y"] = 2, ["param1"] = 141, ["z"] = 5, ["name"] = "bloc4builder:box_purple_colsqu"}, {["x"] = 5, ["y"] = 2, ["param1"] = 158, ["z"] = 8, ["name"] = "bloc4builder:slab_army_1"}, {["x"] = 5, ["y"] = 2, ["param1"] = 142, ["z"] = 9, ["name"] = "bloc4builder:slab_army_1"}, {["x"] = 5, ["param2"] = 10, ["y"] = 2, ["param1"] = 126, ["z"] = 10, ["name"] = "bloc4builder:slope_white_half_raised"}, {["x"] = 5, ["y"] = 3, ["z"] = 1, ["name"] = "bloc4builder:army"}, {["x"] = 5, ["param2"] = 7, ["y"] = 3, ["param1"] = 124, ["z"] = 4, ["name"] = "moreblocks:slab_obsidian_glass_1"}, {["x"] = 5, ["param2"] = 22, ["y"] = 3, ["param1"] = 141, ["z"] = 5, ["name"] = "bloc4builder:box_purple_colsqu"}, {["x"] = 5, ["param2"] = 2, ["y"] = 3, ["param1"] = 127, ["z"] = 10, ["name"] = "moreblocks:box_obsidian_glass_midslim"}, {["x"] = 5, ["y"] = 4, ["z"] = 1, ["name"] = "bloc4builder:army"}, {["x"] = 5, ["meta"] = {["fields"] = {["infotext"] = "Shield+", ["channel"] = "pirate:singleplayer", ["spacengine"] = "^D¨125¨0¨1250¨3", ["pos_cont"] = "(0,-1,0)"}, ["inventory"] = {}}, ["y"] = 4, ["z"] = 5, ["name"] = "spacengine:shield"}, {["x"] = 5, ["param2"] = 20, ["y"] = 4, ["param1"] = 111, ["z"] = 10, ["name"] = "moreblocks:mesh_obsidian_glass_fuse4"}, {["x"] = 5, ["y"] = 5, ["z"] = 1, ["name"] = "bloc4builder:army"}, {["x"] = 5, ["param2"] = 21, ["y"] = 5, ["param1"] = 187, ["z"] = 2, ["name"] = "bloc4builder:slab_black_1"}, {["x"] = 5, ["param2"] = 20, ["y"] = 5, ["param1"] = 171, ["z"] = 3, ["name"] = "bloc4builder:slab_black_1"}, {["x"] = 5, ["param2"] = 20, ["y"] = 5, ["param1"] = 156, ["z"] = 4, ["name"] = "bloc4builder:slab_black_1"}, {["x"] = 5, ["meta"] = {["fields"] = {["spacengine"] = "^A¨250¨0¨^x05y05z05v01331¨6", ["channel"] = "pirate:singleplayer", ["captain"] = "singleplayer", ["infotext"] = "CONTROLER beta5", ["pos_cont"] = "(-20853,1980,-25050)", ["stock_pos"] = "33333#0#0¨-3#-1#-3¨-2#-2#3¨-1#-2#5¨-1#3#0¨1#-2#2¨1#-2#5¨1#3#0¨2#-2#3¨3#-1#-3"}, ["inventory"] = {["stock"] = {"spacengine:hydrogene_tank 93", "spacengine:oxygene_tank 98", "", "", "", ""}}}, ["y"] = 5, ["z"] = 5, ["name"] = "spacengine:controler"}, {["x"] = 5, ["param2"] = 21, ["y"] = 5, ["param1"] = 126, ["z"] = 6, ["name"] = "bloc4builder:slab_black_1"}, {["x"] = 5, ["param2"] = 2, ["y"] = 5, ["param1"] = 111, ["z"] = 9, ["name"] = "moreblocks:slope_obsidian_glass"}, {["x"] = 5, ["param2"] = 9, ["y"] = 6, ["param1"] = 158, ["z"] = 0, ["name"] = "bloc4builder:slab_army_1"}, {["x"] = 5, ["param2"] = 20, ["y"] = 6, ["param1"] = 127, ["z"] = 7, ["name"] = "moreblocks:slope_obsidian_glass"}, {["x"] = 5, ["param2"] = 2, ["y"] = 6, ["param1"] = 111, ["z"] = 8, ["name"] = "moreblocks:slope_obsidian_glass"}, {["x"] = 5, ["param2"] = 9, ["y"] = 7, ["param1"] = 174, ["z"] = 0, ["name"] = "bloc4builder:slab_army_1"}, {["x"] = 5, ["param2"] = 2, ["y"] = 7, ["param1"] = 127, ["z"] = 7, ["name"] = "moreblocks:slope_obsidian_glass"}, {["x"] = 5, ["param2"] = 9, ["y"] = 8, ["param1"] = 190, ["z"] = 0, ["name"] = "bloc4builder:slab_army_1"}, {["x"] = 5, ["param2"] = 22, ["y"] = 8, ["param1"] = 221, ["z"] = 2, ["name"] = "bloc4builder:light_on"}, {["x"] = 5, ["param2"] = 12, ["y"] = 8, ["param1"] = 159, ["z"] = 6, ["name"] = "moreblocks:mesh_obsidian_glass_mid"}, {["x"] = 5, ["y"] = 9, ["z"] = 1, ["name"] = "bloc4builder:black"}, {["x"] = 5, ["y"] = 9, ["z"] = 2, ["name"] = "bloc4builder:black"}, {["x"] = 5, ["y"] = 9, ["z"] = 3, ["name"] = "bloc4builder:black"}, {["x"] = 5, ["y"] = 9, ["z"] = 4, ["name"] = "bloc4builder:army"}, {["x"] = 5, ["param2"] = 2, ["y"] = 9, ["param1"] = 158, ["z"] = 5, ["name"] = "bloc4builder:slope_army_half_raised"}, {["x"] = 5, ["meta"] = {["fields"] = {["infotext"] = "Stone", ["channel"] = "pirate:singleplayer", ["spacengine"] = "^A¨50¨0¨300¨30¨^group:stone", ["pos_cont"] = "(0,5,-4)"}, ["inventory"] = {}}, ["param2"] = 2, ["y"] = 10, ["param1"] = 142, ["z"] = 1, ["name"] = "spacengine:radar"}, {["x"] = 6, ["y"] = 0, ["z"] = 1, ["name"] = "bloc4builder:army"}, {["x"] = 6, ["y"] = 0, ["z"] = 2, ["name"] = "bloc4builder:army"}, {["x"] = 6, ["y"] = 0, ["z"] = 3, ["name"] = "bloc4builder:army"}, {["x"] = 6, ["y"] = 0, ["z"] = 4, ["name"] = "bloc4builder:army"}, {["x"] = 6, ["y"] = 0, ["z"] = 5, ["name"] = "bloc4builder:army"}, {["x"] = 6, ["param2"] = 22, ["y"] = 0, ["param1"] = 140, ["z"] = 6, ["name"] = "bloc4builder:slope_army_half_raised"}, {["x"] = 6, ["param2"] = 22, ["y"] = 0, ["param1"] = 157, ["z"] = 7, ["name"] = "bloc4builder:slope_army_half"}, {["x"] = 6, ["param2"] = 9, ["y"] = 1, ["param1"] = 158, ["z"] = 0, ["name"] = "bloc4builder:slab_army_1"}, {["x"] = 6, ["y"] = 1, ["z"] = 1, ["name"] = "bloc4builder:army"}, {["x"] = 6, ["param2"] = 5, ["y"] = 1, ["param1"] = 155, ["z"] = 2, ["name"] = "default:ladder_steel"}, {["x"] = 6, ["y"] = 1, ["param1"] = 158, ["z"] = 7, ["name"] = "bloc4builder:stair_army"}, {["x"] = 6, ["y"] = 1, ["z"] = 8, ["name"] = "bloc4builder:army"}, {["x"] = 6, ["param2"] = 22, ["y"] = 1, ["param1"] = 141, ["z"] = 9, ["name"] = "bloc4builder:slope_army_half_raised"}, {["x"] = 6, ["param2"] = 22, ["y"] = 1, ["param1"] = 126, ["z"] = 10, ["name"] = "bloc4builder:slope_army_half"}, {["x"] = 6, ["param2"] = 9, ["y"] = 2, ["param1"] = 142, ["z"] = 0, ["name"] = "bloc4builder:slab_army_1"}, {["x"] = 6, ["y"] = 2, ["z"] = 1, ["name"] = "bloc4builder:army"}, {["x"] = 6, ["param2"] = 5, ["y"] = 2, ["param1"] = 156, ["z"] = 2, ["name"] = "default:ladder_steel"}, {["x"] = 6, ["param2"] = 23, ["y"] = 2, ["param1"] = 139, ["z"] = 3, ["name"] = "bloc4builder:slab_black_1"}, {["x"] = 6, ["y"] = 2, ["param1"] = 174, ["z"] = 8, ["name"] = "bloc4builder:slab_army_1"}, {["x"] = 6, ["y"] = 2, ["param1"] = 158, ["z"] = 9, ["name"] = "bloc4builder:slab_army_1"}, {["x"] = 6, ["param2"] = 10, ["y"] = 2, ["param1"] = 142, ["z"] = 10, ["name"] = "bloc4builder:slope_white_half_raised"}, {["x"] = 6, ["param2"] = 9, ["y"] = 3, ["param1"] = 142, ["z"] = 0, ["name"] = "bloc4builder:slab_army_1"}, {["x"] = 6, ["y"] = 3, ["z"] = 1, ["name"] = "bloc4builder:army"}, {["x"] = 6, ["param2"] = 5, ["y"] = 3, ["param1"] = 172, ["z"] = 2, ["name"] = "default:ladder_steel"}, {["x"] = 6, ["param2"] = 7, ["y"] = 3, ["param1"] = 140, ["z"] = 4, ["name"] = "moreblocks:slab_obsidian_glass_1"}, {["x"] = 6, ["meta"] = {["fields"] = {["spacengine"] = "^c¨64¨0¨^ax0az0ay0aI0bG0bo0bo0bo0¨1", ["channel"] = "pirate:singleplayer", ["text"] = "(h(1%(b,,,,,,,(2(sBBB(1(b,,,,,,, | (h(1h(b,,,,,,,4(mA)X(1(b,,,,,,, | (g(1U(b,,,,,,,_(jA)Z(1(b,,,,,,, | (g(1j(b,,,,,,,_(eA)Y(1(b,,,,,,, | (k(1T(b,,,,,,,_(kGv(b,,,,,,, | (k(1h(b,,,,,,,_(2(v=_(1(b,,,,,,, | (1_(b(k/(b,,,,,,(2(sBBB(1(b(k/(b,,,,,,", ["pos_cont"] = "(1,-2,2)"}, ["inventory"] = {}}, ["param2"] = 1, ["y"] = 3, ["param1"] = 191, ["z"] = 7, ["name"] = "monitor:screen_aim"}, {["x"] = 6, ["meta"] = {["fields"] = {["spacengine"] = "^s¨64¨0¨^aa0aa0aa0bM0¨1", ["channel"] = "pirate:singleplayer", ["text"] = "(2(b(c1(b234_____)(cSTORAGE | (p(3?STORAGE@(2_(w`(1(e_6)0(12) | (o000000/005000 | (pEat 0 | (pOres0", ["pos_cont"] = "(1,-2,5)"}, ["inventory"] = {}}, ["y"] = 3, ["param1"] = 143, ["z"] = 10, ["name"] = "monitor:screen_transparent"}, {["x"] = 6, ["param2"] = 9, ["y"] = 4, ["param1"] = 158, ["z"] = 0, ["name"] = "bloc4builder:slab_army_1"}, {["x"] = 6, ["y"] = 4, ["z"] = 1, ["name"] = "bloc4builder:army"}, {["x"] = 6, ["param2"] = 5, ["y"] = 4, ["param1"] = 188, ["z"] = 2, ["name"] = "default:ladder_steel"}, {["x"] = 6, ["meta"] = {["fields"] = {["infotext"] = "ENGINE PUISSANCE", ["channel"] = "pirate:singleplayer", ["spacengine"] = "^a¨0¨0¨^aA0¨1¨^", ["pos_cont"] = "(1,-1,2)"}, ["inventory"] = {}}, ["param2"] = 1, ["y"] = 4, ["param1"] = 175, ["z"] = 7, ["name"] = "spacengine:analog00"}, {["x"] = 6, ["param2"] = 20, ["y"] = 4, ["param1"] = 127, ["z"] = 10, ["name"] = "moreblocks:mesh_obsidian_glass_fuse4"}, {["x"] = 6, ["param2"] = 9, ["y"] = 5, ["param1"] = 142, ["z"] = 0, ["name"] = "bloc4builder:slab_army_1"}, {["x"] = 6, ["y"] = 5, ["z"] = 1, ["name"] = "bloc4builder:army"}, {["x"] = 6, ["param2"] = 5, ["y"] = 5, ["param1"] = 204, ["z"] = 2, ["name"] = "default:ladder_steel"}, {["x"] = 6, ["param2"] = 20, ["y"] = 5, ["param1"] = 187, ["z"] = 3, ["name"] = "bloc4builder:slab_black_1"}, {["x"] = 6, ["param2"] = 20, ["y"] = 5, ["param1"] = 172, ["z"] = 4, ["name"] = "bloc4builder:slab_black_1"}, {["x"] = 6, ["param2"] = 23, ["y"] = 5, ["param1"] = 157, ["z"] = 5, ["name"] = "bloc4builder:slab_black_1"}, {["x"] = 6, ["param2"] = 20, ["y"] = 5, ["param1"] = 142, ["z"] = 6, ["name"] = "bloc4builder:slab_black_1"}, {["x"] = 6, ["meta"] = {["fields"] = {["infotext"] = "ENGINE PUISSANCE", ["channel"] = "pirate:singleplayer", ["spacengine"] = "^a¨0¨0¨^aA0¨1¨^", ["pos_cont"] = "(1,0,3)"}, ["inventory"] = {}}, ["param2"] = 8, ["y"] = 5, ["param1"] = 143, ["z"] = 8, ["name"] = "spacengine:analog10"}, {["x"] = 6, ["param2"] = 2, ["y"] = 5, ["param1"] = 127, ["z"] = 9, ["name"] = "moreblocks:slope_obsidian_glass"}, {["x"] = 6, ["param2"] = 9, ["y"] = 6, ["param1"] = 142, ["z"] = 0, ["name"] = "bloc4builder:slab_army_1"}, {["x"] = 6, ["y"] = 6, ["z"] = 1, ["name"] = "bloc4builder:army"}, {["x"] = 6, ["meta"] = {["fields"] = {["infotext"] = "ENGINE PUISSANCE", ["channel"] = "pirate:singleplayer", ["spacengine"] = "^a¨0¨0¨^aA0¨1¨^", ["pos_cont"] = "(1,1,0)"}, ["inventory"] = {}}, ["param2"] = 1, ["y"] = 6, ["param1"] = 141, ["z"] = 5, ["name"] = "spacengine:rotator00"}, {["x"] = 6, ["meta"] = {["fields"] = {["infotext"] = "POWER ON/OFF", ["channel"] = "pirate:singleplayer", ["spacengine"] = "^i¨0¨0¨^iA0¨1¨^", ["pos_cont"] = "(1,1,1)"}, ["inventory"] = {}}, ["param2"] = 1, ["y"] = 6, ["param1"] = 126, ["z"] = 6, ["name"] = "spacengine:inter_0"}, {["x"] = 6, ["param2"] = 20, ["y"] = 6, ["param1"] = 143, ["z"] = 7, ["name"] = "moreblocks:slope_obsidian_glass"}, {["x"] = 6, ["param2"] = 2, ["y"] = 6, ["param1"] = 127, ["z"] = 8, ["name"] = "moreblocks:slope_obsidian_glass"}, {["x"] = 6, ["param2"] = 9, ["y"] = 7, ["param1"] = 158, ["z"] = 0, ["name"] = "bloc4builder:slab_army_1"}, {["x"] = 6, ["param2"] = 2, ["y"] = 7, ["param1"] = 127, ["z"] = 7, ["name"] = "moreblocks:slope_obsidian_glass"}, {["x"] = 6, ["param2"] = 9, ["y"] = 8, ["param1"] = 174, ["z"] = 0, ["name"] = "bloc4builder:slab_army_1"}, {["x"] = 6, ["meta"] = {["fields"] = {["spacengine"] = "^G¨64¨0¨^aF0bM0¨1", ["channel"] = "pirate:singleplayer", ["text"] = "(2(b(c1(b2_______)(cPUISSAN | (p(3?GFORCE@)(h(3?OFF@) | (1(lA) | (l0mG/(o Nb 1", ["pos_cont"] = "(1,3,0)"}, ["inventory"] = {}}, ["y"] = 8, ["param1"] = 157, ["z"] = 5, ["name"] = "monitor:screen_up"}, {["x"] = 6, ["param2"] = 2, ["y"] = 8, ["param1"] = 142, ["z"] = 6, ["name"] = "bloc4builder:slope_black"}, {["x"] = 6, ["param2"] = 3, ["y"] = 9, ["param1"] = 174, ["z"] = 1, ["name"] = "bloc4builder:slope_army_half"}, {["x"] = 6, ["param2"] = 3, ["y"] = 9, ["param1"] = 190, ["z"] = 2, ["name"] = "bloc4builder:slope_army_half"}, {["x"] = 6, ["param2"] = 3, ["y"] = 9, ["param1"] = 173, ["z"] = 3, ["name"] = "bloc4builder:slope_army_half"}, {["x"] = 6, ["param2"] = 3, ["y"] = 9, ["param1"] = 158, ["z"] = 4, ["name"] = "bloc4builder:slope_army_half"}, {["x"] = 6, ["param2"] = 3, ["y"] = 9, ["param1"] = 141, ["z"] = 5, ["name"] = "bloc4builder:slope_army_half"}, {["x"] = 7, ["y"] = 0, ["z"] = 1, ["name"] = "bloc4builder:army"}, {["x"] = 7, ["y"] = 0, ["z"] = 2, ["name"] = "bloc4builder:army"}, {["x"] = 7, ["y"] = 0, ["z"] = 3, ["name"] = "bloc4builder:army"}, {["x"] = 7, ["y"] = 0, ["z"] = 4, ["name"] = "bloc4builder:army"}, {["x"] = 7, ["y"] = 0, ["z"] = 5, ["name"] = "bloc4builder:army"}, {["x"] = 7, ["param2"] = 22, ["y"] = 0, ["param1"] = 155, ["z"] = 6, ["name"] = "bloc4builder:slope_army_half_raised"}, {["x"] = 7, ["param2"] = 22, ["y"] = 0, ["param1"] = 172, ["z"] = 7, ["name"] = "bloc4builder:slope_army_half"}, {["x"] = 7, ["meta"] = {["fields"] = {["infotext"] = "LASER", ["channel"] = "pirate:singleplayer", ["spacengine"] = "^A¨100¨0¨750¨20¨5¨2", ["pos_cont"] = "(2,-5,3)"}, ["inventory"] = {}}, ["param2"] = 21, ["y"] = 0, ["param1"] = 157, ["z"] = 8, ["name"] = "spacengine:weapons"}, {["x"] = 7, ["param2"] = 9, ["y"] = 1, ["param1"] = 174, ["z"] = 0, ["name"] = "bloc4builder:slab_army_1"}, {["x"] = 7, ["meta"] = {["fields"] = {["infotext"] = "Oxygene", ["channel"] = "pirate:singleplayer", ["spacengine"] = "^A¨150¨0¨1¨50", ["pos_cont"] = "(2,-4,-4)"}, ["inventory"] = {}}, ["param2"] = 2, ["y"] = 1, ["z"] = 1, ["name"] = "spacengine:oxygene"}, {["x"] = 7, ["y"] = 1, ["z"] = 6, ["name"] = "bloc4builder:army"}, {["x"] = 7, ["y"] = 1, ["z"] = 7, ["name"] = "bloc4builder:army"}, {["x"] = 7, ["y"] = 1, ["z"] = 8, ["name"] = "bloc4builder:army"}, {["x"] = 7, ["param2"] = 22, ["y"] = 1, ["param1"] = 158, ["z"] = 9, ["name"] = "bloc4builder:slope_army_half_raised"}, {["x"] = 7, ["param2"] = 22, ["y"] = 1, ["param1"] = 142, ["z"] = 10, ["name"] = "bloc4builder:slope_army_half"}, {["x"] = 7, ["param2"] = 13, ["y"] = 2, ["param1"] = 174, ["z"] = 1, ["name"] = "bloc4builder:slope_black_inner_cut"}, {["x"] = 7, ["param2"] = 22, ["y"] = 2, ["param1"] = 173, ["z"] = 2, ["name"] = "bloc4builder:slab_black_1"}, {["x"] = 7, ["param2"] = 23, ["y"] = 2, ["param1"] = 156, ["z"] = 3, ["name"] = "bloc4builder:slab_black_1"}, {["x"] = 7, ["param2"] = 9, ["y"] = 2, ["param1"] = 172, ["z"] = 5, ["name"] = "bloc4builder:slab_army_1"}, {["x"] = 7, ["y"] = 2, ["z"] = 6, ["name"] = "bloc4builder:army"}, {["x"] = 7, ["y"] = 2, ["z"] = 7, ["name"] = "bloc4builder:army"}, {["x"] = 7, ["param2"] = 19, ["y"] = 2, ["param1"] = 189, ["z"] = 8, ["name"] = "bloc4builder:slope_white_half_raised"}, {["x"] = 7, ["param2"] = 19, ["y"] = 2, ["param1"] = 174, ["z"] = 9, ["name"] = "bloc4builder:slope_white_half_raised"}, {["x"] = 7, ["param2"] = 3, ["y"] = 2, ["param1"] = 158, ["z"] = 10, ["name"] = "bloc4builder:slope_white_inner_cut"}, {["x"] = 7, ["param2"] = 12, ["y"] = 3, ["param1"] = 174, ["z"] = 1, ["name"] = "bloc4builder:slope_black"}, {["x"] = 7, ["param2"] = 7, ["y"] = 3, ["param1"] = 155, ["z"] = 4, ["name"] = "moreblocks:slab_obsidian_glass_1"}, {["x"] = 7, ["param2"] = 9, ["y"] = 3, ["param1"] = 172, ["z"] = 5, ["name"] = "bloc4builder:slab_army_1"}, {["x"] = 7, ["param2"] = 12, ["y"] = 3, ["param1"] = 189, ["z"] = 6, ["name"] = "bloc4builder:slab_army"}, {["x"] = 7, ["param2"] = 12, ["y"] = 3, ["param1"] = 206, ["z"] = 7, ["name"] = "bloc4builder:slab_army"}, {["x"] = 7, ["meta"] = {["fields"] = {["spacengine"] = "^O¨64¨0¨^aG0bf0bM0¨1¨^A", ["channel"] = "pirate:singleplayer", ["text"] = "(2(b(c1(b23______)(cPUISSAN | (p(3?OXYGENE@(1_(iG(f(3?ON=@) | (2(fR(1(fRRQPP(2_(c:(1(fPP(kP(kP(hP | (1(j&(fPP(kP(kP(hP)(d1 | (oNb 1/(fS 50", ["pos_cont"] = "(2,-2,3)"}, ["inventory"] = {}}, ["param2"] = 1, ["y"] = 3, ["param1"] = 190, ["z"] = 8, ["name"] = "monitor:screen_transparent"}, {["x"] = 7, ["param2"] = 3, ["y"] = 3, ["param1"] = 174, ["z"] = 9, ["name"] = "moreblocks:box_obsidian_glass_midslim"}, {["x"] = 7, ["param2"] = 3, ["y"] = 3, ["param1"] = 158, ["z"] = 10, ["name"] = "moreblocks:mesh_obsidian_glass_fuse3"}, {["x"] = 7, ["param2"] = 21, ["y"] = 4, ["param1"] = 190, ["z"] = 1, ["name"] = "bloc4builder:slope_black_inner_cut"}, {["x"] = 7, ["param2"] = 9, ["y"] = 4, ["param1"] = 156, ["z"] = 5, ["name"] = "bloc4builder:slab_army_1"}, {["x"] = 7, ["param2"] = 12, ["y"] = 4, ["param1"] = 173, ["z"] = 6, ["name"] = "bloc4builder:slab_army"}, {["x"] = 7, ["param2"] = 12, ["y"] = 4, ["param1"] = 190, ["z"] = 7, ["name"] = "bloc4builder:slab_army"}, {["x"] = 7, ["param2"] = 23, ["y"] = 4, ["param1"] = 174, ["z"] = 8, ["name"] = "bloc4builder:mesh_black_fuse4"}, {["x"] = 7, ["param2"] = 23, ["y"] = 4, ["param1"] = 158, ["z"] = 9, ["name"] = "bloc4builder:mesh_black_fuse4"}, {["x"] = 7, ["param2"] = 3, ["y"] = 4, ["param1"] = 142, ["z"] = 10, ["name"] = "bloc4builder:mesh_black_fuse6"}, {["x"] = 7, ["y"] = 5, ["z"] = 1, ["name"] = "bloc4builder:army"}, {["x"] = 7, ["param2"] = 7, ["y"] = 5, ["param1"] = 221, ["z"] = 2, ["name"] = "bloc4builder:light_on"}, {["x"] = 7, ["param2"] = 23, ["y"] = 5, ["param1"] = 204, ["z"] = 3, ["name"] = "bloc4builder:slab_black_1"}, {["x"] = 7, ["param2"] = 23, ["y"] = 5, ["param1"] = 188, ["z"] = 4, ["name"] = "bloc4builder:slab_black_1"}, {["x"] = 7, ["param2"] = 9, ["y"] = 5, ["param1"] = 172, ["z"] = 5, ["name"] = "bloc4builder:slab_army_1"}, {["x"] = 7, ["param2"] = 12, ["y"] = 5, ["param1"] = 157, ["z"] = 6, ["name"] = "bloc4builder:slab_army"}, {["x"] = 7, ["param2"] = 12, ["y"] = 5, ["param1"] = 174, ["z"] = 7, ["name"] = "bloc4builder:slab_army"}, {["x"] = 7, ["param2"] = 12, ["y"] = 5, ["param1"] = 159, ["z"] = 8, ["name"] = "moreblocks:slab_obsidian_glass_1"}, {["x"] = 7, ["y"] = 6, ["z"] = 1, ["name"] = "bloc4builder:army"}, {["x"] = 7, ["y"] = 6, ["z"] = 2, ["name"] = "bloc4builder:army"}, {["x"] = 7, ["y"] = 6, ["z"] = 5, ["name"] = "bloc4builder:army"}, {["x"] = 7, ["param2"] = 12, ["y"] = 6, ["param1"] = 142, ["z"] = 6, ["name"] = "bloc4builder:slab_army"}, {["x"] = 7, ["param2"] = 12, ["y"] = 6, ["param1"] = 158, ["z"] = 7, ["name"] = "bloc4builder:slab_army"}, {["x"] = 7, ["y"] = 7, ["z"] = 1, ["name"] = "bloc4builder:army"}, {["x"] = 7, ["y"] = 7, ["z"] = 5, ["name"] = "bloc4builder:army"}, {["x"] = 7, ["param2"] = 12, ["y"] = 7, ["param1"] = 127, ["z"] = 6, ["name"] = "moreblocks:slab_obsidian_glass_1"}, {["x"] = 7, ["param2"] = 3, ["y"] = 8, ["param1"] = 174, ["z"] = 1, ["name"] = "bloc4builder:slope_army"}, {["x"] = 7, ["param2"] = 3, ["y"] = 8, ["param1"] = 190, ["z"] = 2, ["name"] = "bloc4builder:slope_army"}, {["x"] = 7, ["param2"] = 3, ["y"] = 8, ["param1"] = 174, ["z"] = 3, ["name"] = "bloc4builder:slope_army"}, {["x"] = 7, ["param2"] = 3, ["y"] = 8, ["param1"] = 158, ["z"] = 4, ["name"] = "bloc4builder:slope_army"}, {["x"] = 7, ["param2"] = 3, ["y"] = 8, ["param1"] = 142, ["z"] = 5, ["name"] = "bloc4builder:slope_army"}, {["x"] = 8, ["param2"] = 21, ["y"] = 0, ["param1"] = 189, ["z"] = 1, ["name"] = "bloc4builder:slope_army_half_raised"}, {["x"] = 8, ["param2"] = 21, ["y"] = 0, ["param1"] = 172, ["z"] = 2, ["name"] = "bloc4builder:slope_army_half_raised"}, {["x"] = 8, ["param2"] = 21, ["y"] = 0, ["param1"] = 156, ["z"] = 3, ["name"] = "bloc4builder:slope_army_half_raised"}, {["x"] = 8, ["param2"] = 21, ["y"] = 0, ["param1"] = 140, ["z"] = 4, ["name"] = "bloc4builder:slope_army_half_raised"}, {["x"] = 8, ["param2"] = 21, ["y"] = 0, ["param1"] = 156, ["z"] = 5, ["name"] = "bloc4builder:slope_army_half_raised"}, {["x"] = 8, ["param2"] = 9, ["y"] = 1, ["param1"] = 190, ["z"] = 0, ["name"] = "bloc4builder:slab_army_1"}, {["x"] = 8, ["meta"] = {["fields"] = {["infotext"] = "BATTERY Mega5", ["channel"] = "pirate:singleplayer", ["spacengine"] = "^C¨150¨0¨50000", ["pos_cont"] = "(3,-4,-4)"}, ["inventory"] = {}}, ["param2"] = 2, ["y"] = 1, ["z"] = 1, ["name"] = "spacengine:battery"}, {["x"] = 8, ["param2"] = 9, ["y"] = 1, ["param1"] = 172, ["z"] = 5, ["name"] = "bloc4builder:slab_army_1"}, {["x"] = 8, ["param2"] = 6, ["y"] = 1, ["param1"] = 188, ["z"] = 6, ["name"] = "bloc4builder:mesh_road_neutre_fuse5"}, {["x"] = 8, ["param2"] = 6, ["y"] = 1, ["param1"] = 205, ["z"] = 7, ["name"] = "bloc4builder:mesh_road_neutre_fuse6"}, {["x"] = 8, ["y"] = 2, ["param1"] = 189, ["z"] = 1, ["name"] = "bloc4builder:slope_black"}, {["x"] = 8, ["param2"] = 23, ["y"] = 2, ["param1"] = 172, ["z"] = 2, ["name"] = "bloc4builder:slab_black_1"}, {["x"] = 8, ["param2"] = 23, ["y"] = 2, ["param1"] = 155, ["z"] = 3, ["name"] = "bloc4builder:slab_black_1"}, {["x"] = 8, ["param2"] = 9, ["y"] = 2, ["param1"] = 187, ["z"] = 5, ["name"] = "bloc4builder:slab_army_1"}, {["x"] = 8, ["param2"] = 18, ["y"] = 2, ["param1"] = 204, ["z"] = 6, ["name"] = "bloc4builder:slope_road_neutre_half_raised"}, {["x"] = 8, ["param2"] = 18, ["y"] = 2, ["param1"] = 221, ["z"] = 7, ["name"] = "bloc4builder:slope_road_neutre_half"}, {["x"] = 8, ["meta"] = {["fields"] = {["infotext"] = "Rocket", ["channel"] = "pirate:singleplayer", ["spacengine"] = "^A¨75¨0¨10¨50¨50¨500", ["pos_cont"] = "(3,-2,-3)"}, ["inventory"] = {}}, ["param2"] = 2, ["y"] = 3, ["z"] = 2, ["name"] = "spacengine:engine"}, {["x"] = 8, ["param2"] = 7, ["y"] = 3, ["param1"] = 171, ["z"] = 4, ["name"] = "moreblocks:slab_obsidian_glass_1"}, {["x"] = 8, ["param2"] = 9, ["y"] = 3, ["param1"] = 187, ["z"] = 5, ["name"] = "bloc4builder:slab_army_1"}, {["x"] = 8, ["param2"] = 18, ["y"] = 3, ["param1"] = 204, ["z"] = 6, ["name"] = "bloc4builder:slope_road_neutre_half_raised"}, {["x"] = 8, ["param2"] = 18, ["y"] = 3, ["param1"] = 221, ["z"] = 7, ["name"] = "bloc4builder:slope_road_neutre_half"}, {["x"] = 8, ["param2"] = 20, ["y"] = 4, ["param1"] = 173, ["z"] = 1, ["name"] = "bloc4builder:slope_black"}, {["x"] = 8, ["meta"] = {["fields"] = {["infotext"] = "Generateur Hydrogene", ["channel"] = "pirate:singleplayer", ["spacengine"] = "2¨150¨0¨500¨^spacengine:hydrogene_tank¨^battery¨15¨1¨9¨500", ["pos_cont"] = "(3,-1,-3)"}, ["inventory"] = {}}, ["param2"] = 2, ["y"] = 4, ["param1"] = 188, ["z"] = 2, ["name"] = "spacengine:power"}, {["x"] = 8, ["param2"] = 9, ["y"] = 4, ["param1"] = 172, ["z"] = 5, ["name"] = "bloc4builder:slab_army_1"}, {["x"] = 8, ["param2"] = 5, ["y"] = 4, ["param1"] = 189, ["z"] = 6, ["name"] = "bloc4builder:mesh_road_neutre_fuse5"}, {["x"] = 8, ["param2"] = 5, ["y"] = 4, ["param1"] = 206, ["z"] = 7, ["name"] = "bloc4builder:mesh_road_neutre_fuse6"}, {["x"] = 8, ["param2"] = 3, ["y"] = 5, ["param1"] = 189, ["z"] = 1, ["name"] = "bloc4builder:slope_army_half_raised"}, {["x"] = 8, ["param2"] = 3, ["y"] = 5, ["param1"] = 205, ["z"] = 2, ["name"] = "bloc4builder:slope_army_half_raised"}, {["x"] = 8, ["param2"] = 3, ["y"] = 5, ["param1"] = 189, ["z"] = 3, ["name"] = "bloc4builder:slope_army_half_raised"}, {["x"] = 8, ["param2"] = 3, ["y"] = 5, ["param1"] = 173, ["z"] = 4, ["name"] = "bloc4builder:slope_army_half_raised"}, {["x"] = 8, ["param2"] = 3, ["y"] = 5, ["param1"] = 157, ["z"] = 5, ["name"] = "bloc4builder:slope_army_half_raised"}, {["x"] = 8, ["param2"] = 12, ["y"] = 6, ["param1"] = 173, ["z"] = 1, ["name"] = "bloc4builder:slab_army_1"}, {["x"] = 8, ["param2"] = 12, ["y"] = 6, ["param1"] = 190, ["z"] = 2, ["name"] = "bloc4builder:slab_army_1"}, {["x"] = 8, ["param2"] = 12, ["y"] = 6, ["param1"] = 174, ["z"] = 3, ["name"] = "bloc4builder:slab_army_1"}, {["x"] = 8, ["param2"] = 12, ["y"] = 6, ["param1"] = 158, ["z"] = 4, ["name"] = "bloc4builder:slab_army_1"}, {["x"] = 8, ["param2"] = 12, ["y"] = 7, ["param1"] = 158, ["z"] = 1, ["name"] = "bloc4builder:slab_army_1"}, {["x"] = 8, ["param2"] = 12, ["y"] = 7, ["param1"] = 174, ["z"] = 2, ["name"] = "bloc4builder:slab_army_1"}, {["x"] = 8, ["param2"] = 12, ["y"] = 7, ["param1"] = 158, ["z"] = 3, ["name"] = "bloc4builder:slab_army_1"}, {["x"] = 8, ["param2"] = 12, ["y"] = 7, ["param1"] = 142, ["z"] = 4, ["name"] = "bloc4builder:slab_army_1"}, {["x"] = 8, ["meta"] = {["fields"] = {["infotext"] = "LASER", ["channel"] = "pirate:singleplayer", ["spacengine"] = "^A¨100¨0¨750¨20¨5¨2", ["pos_cont"] = "(3,2,0)"}, ["inventory"] = {}}, ["param2"] = 14, ["y"] = 7, ["param1"] = 126, ["z"] = 5, ["name"] = "spacengine:weapons"}, {["x"] = 9, ["param2"] = 21, ["y"] = 0, ["param1"] = 205, ["z"] = 1, ["name"] = "bloc4builder:slope_army_half"}, {["x"] = 9, ["param2"] = 21, ["y"] = 0, ["param1"] = 189, ["z"] = 2, ["name"] = "bloc4builder:slope_army_half"}, {["x"] = 9, ["param2"] = 21, ["y"] = 0, ["param1"] = 173, ["z"] = 3, ["name"] = "bloc4builder:slope_army_half"}, {["x"] = 9, ["param2"] = 21, ["y"] = 0, ["param1"] = 157, ["z"] = 4, ["name"] = "bloc4builder:slope_army_half"}, {["x"] = 9, ["param2"] = 21, ["y"] = 0, ["param1"] = 173, ["z"] = 5, ["name"] = "bloc4builder:slope_army_half"}, {["x"] = 9, ["param2"] = 9, ["y"] = 1, ["param1"] = 206, ["z"] = 0, ["name"] = "bloc4builder:slab_army_1"}, {["x"] = 9, ["y"] = 1, ["z"] = 1, ["name"] = "jumpdrive:engine"}, {["x"] = 9, ["param2"] = 9, ["y"] = 1, ["param1"] = 189, ["z"] = 5, ["name"] = "bloc4builder:slab_army_1"}, {["x"] = 9, ["param2"] = 22, ["y"] = 1, ["param1"] = 205, ["z"] = 6, ["name"] = "bloc4builder:slope_road_neutre_half_raised"}, {["x"] = 9, ["param2"] = 22, ["y"] = 1, ["param1"] = 221, ["z"] = 7, ["name"] = "bloc4builder:slope_road_neutre_half"}, {["x"] = 9, ["param2"] = 1, ["y"] = 2, ["param1"] = 206, ["z"] = 1, ["name"] = "bloc4builder:slope_black_inner_cut"}, {["x"] = 9, ["param2"] = 22, ["y"] = 2, ["param1"] = 189, ["z"] = 2, ["name"] = "bloc4builder:slab_black_1"}, {["x"] = 9, ["param2"] = 23, ["y"] = 2, ["param1"] = 172, ["z"] = 3, ["name"] = "bloc4builder:slab_black_1"}, {["x"] = 9, ["y"] = 2, ["param1"] = 238, ["z"] = 7, ["name"] = "default:meselamp"}, {["x"] = 9, ["param2"] = 7, ["y"] = 2, ["param1"] = 222, ["z"] = 8, ["name"] = "bloc4builder:box_grille_colroundtop"}, {["x"] = 9, ["param2"] = 7, ["y"] = 2, ["param1"] = 206, ["z"] = 9, ["name"] = "bloc4builder:box_grille_colroundtop"}, {["x"] = 9, ["param2"] = 16, ["y"] = 3, ["param1"] = 190, ["z"] = 1, ["name"] = "bloc4builder:slope_black"}, {["x"] = 9, ["param2"] = 7, ["y"] = 3, ["param1"] = 188, ["z"] = 4, ["name"] = "moreblocks:slab_obsidian_glass_1"}, {["x"] = 9, ["y"] = 3, ["param1"] = 238, ["z"] = 7, ["name"] = "default:meselamp"}, {["x"] = 9, ["param2"] = 7, ["y"] = 3, ["param1"] = 222, ["z"] = 8, ["name"] = "bloc4builder:box_grille_colroundtop"}, {["x"] = 9, ["param2"] = 7, ["y"] = 3, ["param1"] = 206, ["z"] = 9, ["name"] = "bloc4builder:box_grille_colroundtop"}, {["x"] = 9, ["param2"] = 20, ["y"] = 4, ["param1"] = 174, ["z"] = 1, ["name"] = "bloc4builder:slope_black_inner_cut"}, {["x"] = 9, ["param2"] = 9, ["y"] = 4, ["param1"] = 189, ["z"] = 5, ["name"] = "bloc4builder:slab_army_1"}, {["x"] = 9, ["param2"] = 2, ["y"] = 4, ["param1"] = 206, ["z"] = 6, ["name"] = "bloc4builder:slope_road_neutre_half_raised"}, {["x"] = 9, ["param2"] = 2, ["y"] = 4, ["param1"] = 222, ["z"] = 7, ["name"] = "bloc4builder:slope_road_neutre_half"}, {["x"] = 9, ["param2"] = 3, ["y"] = 5, ["param1"] = 174, ["z"] = 1, ["name"] = "bloc4builder:slope_army_half"}, {["x"] = 9, ["param2"] = 3, ["y"] = 5, ["param1"] = 190, ["z"] = 2, ["name"] = "bloc4builder:slope_army_half"}, {["x"] = 9, ["param2"] = 3, ["y"] = 5, ["param1"] = 174, ["z"] = 3, ["name"] = "bloc4builder:slope_army_half"}, {["x"] = 9, ["param2"] = 3, ["y"] = 5, ["param1"] = 158, ["z"] = 4, ["name"] = "bloc4builder:slope_army_half"}, {["x"] = 9, ["param2"] = 3, ["y"] = 5, ["param1"] = 174, ["z"] = 5, ["name"] = "bloc4builder:slope_army_half"}, {["x"] = 10, ["param2"] = 21, ["y"] = 1, ["param1"] = 206, ["z"] = 1, ["name"] = "bloc4builder:slope_army"}, {["x"] = 10, ["param2"] = 21, ["y"] = 1, ["param1"] = 190, ["z"] = 2, ["name"] = "bloc4builder:slope_army"}, {["x"] = 10, ["param2"] = 21, ["y"] = 1, ["param1"] = 174, ["z"] = 3, ["name"] = "bloc4builder:slope_army"}, {["x"] = 10, ["param2"] = 21, ["y"] = 1, ["param1"] = 158, ["z"] = 4, ["name"] = "bloc4builder:slope_army"}, {["x"] = 10, ["param2"] = 21, ["y"] = 1, ["param1"] = 174, ["z"] = 5, ["name"] = "bloc4builder:slope_army"}, {["x"] = 10, ["param2"] = 7, ["y"] = 1, ["param1"] = 190, ["z"] = 6, ["name"] = "bloc4builder:mesh_road_neutre_fuse5"}, {["x"] = 10, ["param2"] = 7, ["y"] = 1, ["param1"] = 206, ["z"] = 7, ["name"] = "bloc4builder:mesh_road_neutre_fuse6"}, {["x"] = 10, ["y"] = 2, ["z"] = 1, ["name"] = "bloc4builder:army"}, {["x"] = 10, ["y"] = 2, ["param1"] = 174, ["z"] = 2, ["name"] = "bloc4builder:building_glass"}, {["x"] = 10, ["y"] = 2, ["z"] = 3, ["name"] = "bloc4builder:army"}, {["x"] = 10, ["y"] = 2, ["param1"] = 174, ["z"] = 4, ["name"] = "bloc4builder:building_glass"}, {["x"] = 10, ["y"] = 2, ["z"] = 5, ["name"] = "bloc4builder:army"}, {["x"] = 10, ["param2"] = 14, ["y"] = 2, ["param1"] = 206, ["z"] = 6, ["name"] = "bloc4builder:slope_road_neutre_half_raised"}, {["x"] = 10, ["param2"] = 14, ["y"] = 2, ["param1"] = 222, ["z"] = 7, ["name"] = "bloc4builder:slope_road_neutre_half"}, {["x"] = 10, ["y"] = 3, ["z"] = 1, ["name"] = "bloc4builder:army"}, {["x"] = 10, ["y"] = 3, ["z"] = 2, ["name"] = "bloc4builder:army"}, {["x"] = 10, ["y"] = 3, ["z"] = 3, ["name"] = "bloc4builder:army"}, {["x"] = 10, ["y"] = 3, ["z"] = 4, ["name"] = "bloc4builder:army"}, {["x"] = 10, ["y"] = 3, ["z"] = 5, ["name"] = "bloc4builder:army"}, {["x"] = 10, ["param2"] = 14, ["y"] = 3, ["param1"] = 206, ["z"] = 6, ["name"] = "bloc4builder:slope_road_neutre_half_raised"}, {["x"] = 10, ["param2"] = 14, ["y"] = 3, ["param1"] = 222, ["z"] = 7, ["name"] = "bloc4builder:slope_road_neutre_half"}, {["x"] = 10, ["param2"] = 3, ["y"] = 4, ["param1"] = 158, ["z"] = 1, ["name"] = "bloc4builder:slope_army"}, {["x"] = 10, ["param2"] = 3, ["y"] = 4, ["param1"] = 158, ["z"] = 2, ["name"] = "bloc4builder:slope_army"}, {["x"] = 10, ["param2"] = 3, ["y"] = 4, ["param1"] = 142, ["z"] = 3, ["name"] = "bloc4builder:slope_army"}, {["x"] = 10, ["param2"] = 3, ["y"] = 4, ["param1"] = 158, ["z"] = 4, ["name"] = "bloc4builder:slope_army"}, {["x"] = 10, ["param2"] = 3, ["y"] = 4, ["param1"] = 174, ["z"] = 5, ["name"] = "bloc4builder:slope_army"}, {["x"] = 10, ["param2"] = 4, ["y"] = 4, ["param1"] = 190, ["z"] = 6, ["name"] = "bloc4builder:mesh_road_neutre_fuse5"}, {["x"] = 10, ["param2"] = 4, ["y"] = 4, ["param1"] = 206, ["z"] = 7, ["name"] = "bloc4builder:mesh_road_neutre_fuse6"}}